Workbook

Sheet PriorDecember
A1: Monthly Report - Voter Registration by Party Affiliation - Prior December
A2: Data as of 12/31/2017
A3: ACTIVE REGISTERED VOTERS BY PARTY AFFILIATION BY COUNTY
A4: COUNTY | B4: REPUBLICAN PARTY OF FLORIDA | C4: FLORIDA DEMOCRATIC PARTY | D4: MINOR PARTY | E4: NO PARTY AFFILIATION | F4: TOTALS
A5: ALACHUA | B5: 48875 | C5: 82204 | D5: 1198 | E5: 40387 | F5: =SUM(B5:E5) -> 172664
A6: BAKER | B6: 7913 | C6: 5725 | D6: 50 | E6: 1613 | F6: =SUM(B6:E6) -> 15301
A7: BAY | B7: 60493 | C7: 30458 | D7: 804 | E7: 24756 | F7: =SUM(B7:E7) -> 116511
A8: BRADFORD | B8: 7446 | C8: 6185 | D8: 68 | E8: 2381 | F8: =SUM(B8:E8) -> 16080
A9: BREVARD | B9: 171942 | C9: 126602 | D9: 3000 | E9: 106557 | F9: =SUM(B9:E9) -> 408101
A10: BROWARD | B10: 253589 | C10: 593644 | D10: 4399 | E10: 330135 | F10: =SUM(B10:E10) -> 1181767
A11: CALHOUN | B11: 2393 | C11: 5256 | D11: 25 | E11: 948 | F11: =SUM(B11:E11) -> 8622
A12: CHARLOTTE | B12: 57904 | C12: 35773 | D12: 729 | E12: 34763 | F12: =SUM(B12:E12) -> 129169
A13: CITRUS | B13: 49336 | C13: 29187 | D13: 592 | E13: 25854 | F13: =SUM(B13:E13) -> 104969
A14: CLAY | B14: 80561 | C14: 32691 | D14: 881 | E14: 35107 | F14: =SUM(B14:E14) -> 149240
A15: COLLIER | B15: 102913 | C15: 46848 | D15: 789 | E15: 50133 | F15: =SUM(B15:E15) -> 200683
A16: COLUMBIA | B16: 17311 | C16: 14412 | D16: 214 | E16: 6908 | F16: =SUM(B16:E16) -> 38845
... A71: WASHINGTON | B71: 7909 | C71: 5478 | D71: 59 | E71: 2161 | F71: =SUM(B71:E71) -> 15607
A72: TOTALS | B72: =SUM(B5:B71) -> 4544708 | C72: =SUM(C5:C71) -> 4807950 | D72: =SUM(D5:D71) -> 65526 | E72: =SUM(E5:E71) -> 3449005 | F72: =SUM(F5:F71) -> 12867189

Sheet January
A1: Monthly Report - Voter Registration by Party Affiliation - January
A2: Data as of 01/31/2018
A3: ACTIVE REGISTERED VOTERS BY PARTY AFFILIATION BY COUNTY
A4: COUNTY | B4: REPUBLICAN PARTY OF FLORIDA | C4: FLORIDA DEMOCRATIC PARTY | D4: MINOR PARTY | E4: NO PARTY AFFILIATION | F4: TOTALS
A5: ALACHUA | B5: 48871 | C5: 82213 | D5: 1227 | E5: 40455 | F5: =SUM(B5:E5) -> 172766
A6: BAKER | B6: 7959 | C6: 5704 | D6: 42 | E6: 1640 | F6: =SUM(B6:E6) -> 15345
A7: BAY | B7: 60671 | C7: 30470 | D7: 838 | E7: 24901 | F7: =SUM(B7:E7) -> 116880
A8: BRADFORD | B8: 7450 | C8: 6159 | D8: 71 | E8: 2389 | F8: =SUM(B8:E8) -> 16069
A9: BREVARD | B9: 172088 | C9: 126581 | D9: 3123 | E9: 106839 | F9: =SUM(B9:E9) -> 408631
A10: BROWARD | B10: 253718 | C10: 593634 | D10: 4699 | E10: 331118 | F10: =SUM(B10:E10) -> 1183169
A11: CALHOUN | B11: 2401 | C11: 5243 | D11: 26 | E11: 951 | F11: =SUM(B11:E11) -> 8621
A12: CHARLOTTE | B12: 58145 | C12: 35844 | D12: 797 | E12: 34985 | F12: =SUM(B12:E12) -> 129771
A13: CITRUS | B13: 49567 | C13: 29216 | D13: 632 | E13: 25980 | F13: =SUM(B13:E13) -> 105395
A14: CLAY | B14: 80639 | C14: 32672 | D14: 910 | E14: 35154 | F14: =SUM(B14:E14) -> 149375
A15: COLLIER | B15: 103389 | C15: 47127 | D15: 823 | E15: 50460 | F15: =SUM(B15:E15) -> 201799
A16: COLUMBIA | B16: 17357 | C16: 14360 | D16: 219 | E16: 6917 | F16: =SUM(B16:E16) -> 38853
... A71: WASHINGTON | B71: 7946 | C71: 5456 | D71: 63 | E71: 2174 | F71: =SUM(B71:E71) -> 15639
A72: TOTALS | B72: =SUM(B5:B71) -> 4550556 | C72: =SUM(C5:C71) -> 4810909 | D72: =SUM(D5:D71) -> 68884 | E72: =SUM(E5:E71) -> 3462735 | F72: =SUM(F5:F71) -> 12893084

Sheet February
A1: Monthly Report - Voter Registration by Party Affiliation - February
A2: Data as of 02/28/2018
A3: ACTIVE REGISTERED VOTERS BY PARTY AFFILIATION BY COUNTY
A4: COUNTY | B4: REPUBLICAN PARTY OF FLORIDA | C4: FLORIDA DEMOCRATIC PARTY | D4: MINOR PARTY | E4: NO PARTY AFFILIATION | F4: TOTALS
A5: ALACHUA | B5: 48903 | C5: 82372 | D5: 1242 | E5: 40597 | F5: =SUM(B5:E5) -> 173114
A6: BAKER | B6: 7888 | C6: 5653 | D6: 43 | E6: 1614 | F6: =SUM(B6:E6) -> 15198
A7: BAY | B7: 60856 | C7: 30532 | D7: 869 | E7: 25083 | F7: =SUM(B7:E7) -> 117340
A8: BRADFORD | B8: 7485 | C8: 6151 | D8: 72 | E8: 2408 | F8: =SUM(B8:E8) -> 16116
A9: BREVARD | B9: 172319 | C9: 126739 | D9: 3238 | E9: 107201 | F9: =SUM(B9:E9) -> 409497
A10: BROWARD | B10: 253644 | C10: 593591 | D10: 4966 | E10: 331835 | F10: =SUM(B10:E10) -> 1184036
A11: CALHOUN | B11: 2398 | C11: 5233 | D11: 27 | E11: 951 | F11: =SUM(B11:E11) -> 8609
A12: CHARLOTTE | B12: 58363 | C12: 35923 | D12: 826 | E12: 35156 | F12: =SUM(B12:E12) -> 130268
A13: CITRUS | B13: 49836 | C13: 29301 | D13: 670 | E13: 26131 | F13: =SUM(B13:E13) -> 105938
A14: CLAY | B14: 80673 | C14: 32757 | D14: 953 | E14: 35223 | F14: =SUM(B14:E14) -> 149606
A15: COLLIER | B15: 103859 | C15: 47435 | D15: 853 | E15: 50838 | F15: =SUM(B15:E15) -> 202985
A16: COLUMBIA | B16: 17421 | C16: 14351 | D16: 225 | E16: 6932 | F16: =SUM(B16:E16) -> 38929
... A71: WASHINGTON | B71: 7977 | C71: 5455 | D71: 65 | E71: 2194 | F71: =SUM(B71:E71) -> 15691
A72: TOTALS | B72: =SUM(B5:B71) -> 4556401 | C72: =SUM(C5:C71) -> 4815369 | D72: =SUM(D5:D71) -> 72166 | E72: =SUM(E5:E71) -> 3474166 | F72: =SUM(F5:F71) -> 12918102

Sheet March
A1: Monthly Report - Voter Registration by Party Affiliation - March
A2: Data as of 03/31/2018
A3: ACTIVE REGISTERED VOTERS BY PARTY AFFILIATION BY COUNTY
A4: COUNTY | B4: REPUBLICAN PARTY OF FLORIDA | C4: FLORIDA DEMOCRATIC PARTY | D4: MINOR PARTY | E4: NO PARTY AFFILIATION | F4: TOTALS
A5: ALACHUA | B5: 48938 | C5: 82501 | D5: 1278 | E5: 40779 | F5: =SUM(B5:E5) -> 173496
A6: BAKER | B6: 7878 | C6: 5635 | D6: 43 | E6: 1619 | F6: =SUM(B6:E6) -> 15175
A7: BAY | B7: 61058 | C7: 30532 | D7: 909 | E7: 25240 | F7: =SUM(B7:E7) -> 117739
A8: BRADFORD | B8: 7500 | C8: 6143 | D8: 71 | E8: 2423 | F8: =SUM(B8:E8) -> 16137
A9: BREVARD | B9: 171626 | C9: 126444 | D9: 3232 | E9: 106873 | F9: =SUM(B9:E9) -> 408175
A10: BROWARD | B10: 248914 | C10: 580487 | D10: 5123 | E10: 324711 | F10: =SUM(B10:E10) -> 1159235
A11: CALHOUN | B11: 2408 | C11: 5210 | D11: 29 | E11: 954 | F11: =SUM(B11:E11) -> 8601
A12: CHARLOTTE | B12: 58632 | C12: 35998 | D12: 868 | E12: 35408 | F12: =SUM(B12:E12) -> 130906
A13: CITRUS | B13: 49989 | C13: 29328 | D13: 684 | E13: 26250 | F13: =SUM(B13:E13) -> 106251
A14: CLAY | B14: 80847 | C14: 32919 | D14: 997 | E14: 35412 | F14: =SUM(B14:E14) -> 150175
A15: COLLIER | B15: 104372 | C15: 47829 | D15: 903 | E15: 51265 | F15: =SUM(B15:E15) -> 204369
A16: COLUMBIA | B16: 17505 | C16: 14354 | D16: 231 | E16: 6976 | F16: =SUM(B16:E16) -> 39066
... A71: WASHINGTON | B71: 8004 | C71: 5454 | D71: 69 | E71: 2194 | F71: =SUM(B71:E71) -> 15721
A72: TOTALS | B72: =SUM(B5:B71) -> 4554831 | C72: =SUM(C5:C71) -> 4805735 | D72: =SUM(D5:D71) -> 74443 | E72: =SUM(E5:E71) -> 3477921 | F72: =SUM(F5:F71) -> 12912930

Sheet April
A1: Monthly Report - Voter Registration by Party Affiliation - April
A2: Data as of 04/30/2018
A3: ACTIVE REGISTERED VOTERS BY PARTY AFFILIATION BY COUNTY
A4: COUNTY | B4: REPUBLICAN PARTY OF FLORIDA | C4: FLORIDA DEMOCRATIC PARTY | D4: MINOR PARTY | E4: NO PARTY AFFILIATION | F4: TOTALS
A5: ALACHUA | B5: 48978 | C5: 82568 | D5: 1304 | E5: 40923 | F5: =SUM(B5:E5) -> 173773
A6: BAKER | B6: 7871 | C6: 5604 | D6: 45 | E6: 1623 | F6: =SUM(B6:E6) -> 15143
A7: BAY | B7: 61170 | C7: 30549 | D7: 940 | E7: 25337 | F7: =SUM(B7:E7) -> 117996
A8: BRADFORD | B8: 7517 | C8: 6147 | D8: 75 | E8: 2433 | F8: =SUM(B8:E8) -> 16172
A9: BREVARD | B9: 172127 | C9: 126907 | D9: 3365 | E9: 107364 | F9: =SUM(B9:E9) -> 409763
A10: BROWARD | B10: 244810 | C10: 569462 | D10: 5244 | E10: 318755 | F10: =SUM(B10:E10) -> 1138271
A11: CALHOUN | B11: 2417 | C11: 5202 | D11: 29 | E11: 953 | F11: =SUM(B11:E11) -> 8601
A12: CHARLOTTE | B12: 58866 | C12: 36012 | D12: 893 | E12: 35505 | F12: =SUM(B12:E12) -> 131276
A13: CITRUS | B13: 50234 | C13: 29358 | D13: 704 | E13: 26311 | F13: =SUM(B13:E13) -> 106607
A14: CLAY | B14: 80814 | C14: 32921 | D14: 1012 | E14: 35511 | F14: =SUM(B14:E14) -> 150258
A15: COLLIER | B15: 104795 | C15: 48112 | D15: 925 | E15: 51588 | F15: =SUM(B15:E15) -> 205420
A16: COLUMBIA | B16: 17606 | C16: 14365 | D16: 238 | E16: 7034 | F16: =SUM(B16:E16) -> 39243
... A71: WASHINGTON | B71: 8035 | C71: 5443 | D71: 67 | E71: 2208 | F71: =SUM(B71:E71) -> 15753
A72: TOTALS | B72: =SUM(B5:B71) -> 4555773 | C72: =SUM(C5:C71) -> 4798973 | D72: =SUM(D5:D71) -> 76953 | E72: =SUM(E5:E71) -> 3482707 | F72: =SUM(F5:F71) -> 12914406

Sheet May
A1: Monthly Report - Voter Registration by Party Affiliation - May
A2: Data as of 05/31/2018
A3: ACTIVE REGISTERED VOTERS BY PARTY AFFILIATION BY COUNTY
A4: COUNTY | B4: REPUBLICAN PARTY OF FLORIDA | C4: FLORIDA DEMOCRATIC PARTY | D4: MINOR PARTY | E4: NO PARTY AFFILIATION | F4: TOTALS
A5: ALACHUA | B5: 48956 | C5: 82658 | D5: 1336 | E5: 41043 | F5: =SUM(B5:E5) -> 173993
A6: BAKER | B6: 7868 | C6: 5563 | D6: 47 | E6: 1614 | F6: =SUM(B6:E6) -> 15092
A7: BAY | B7: 61345 | C7: 30535 | D7: 973 | E7: 25491 | F7: =SUM(B7:E7) -> 118344
A8: BRADFORD | B8: 7523 | C8: 6128 | D8: 75 | E8: 2440 | F8: =SUM(B8:E8) -> 16166
A9: BREVARD | B9: 172700 | C9: 127141 | D9: 3484 | E9: 107866 | F9: =SUM(B9:E9) -> 411191
A10: BROWARD | B10: 245171 | C10: 570479 | D10: 5490 | E10: 320220 | F10: =SUM(B10:E10) -> 1141360
A11: CALHOUN | B11: 2432 | C11: 5191 | D11: 27 | E11: 970 | F11: =SUM(B11:E11) -> 8620
A12: CHARLOTTE | B12: 59086 | C12: 36073 | D12: 944 | E12: 35631 | F12: =SUM(B12:E12) -> 131734
A13: CITRUS | B13: 50442 | C13: 29378 | D13: 734 | E13: 26418 | F13: =SUM(B13:E13) -> 106972
A14: CLAY | B14: 80781 | C14: 32932 | D14: 1040 | E14: 35481 | F14: =SUM(B14:E14) -> 150234
A15: COLLIER | B15: 105214 | C15: 48421 | D15: 965 | E15: 51838 | F15: =SUM(B15:E15) -> 206438
A16: COLUMBIA | B16: 17666 | C16: 14390 | D16: 240 | E16: 7063 | F16: =SUM(B16:E16) -> 39359
... A71: WASHINGTON | B71: 7982 | C71: 5367 | D71: 70 | E71: 2185 | F71: =SUM(B71:E71) -> 15604
A72: TOTALS | B72: =SUM(B5:B71) -> 4547635 | C72: =SUM(C5:C71) -> 4776092 | D72: =SUM(D5:D71) -> 79587 | E72: =SUM(E5:E71) -> 3472684 | F72: =SUM(F5:F71) -> 12875998

Sheet June
A1: Monthly Report - Voter Registration by Party Affiliation - June
A2: Data as of 06/30/2018
A3: ACTIVE REGISTERED VOTERS BY PARTY AFFILIATION BY COUNTY
A4: COUNTY | B4: REPUBLICAN PARTY OF FLORIDA | C4: FLORIDA DEMOCRATIC PARTY | D4: MINOR PARTY | E4: NO PARTY AFFILIATION | F4: TOTALS
A5: ALACHUA | B5: 48955 | C5: 82777 | D5: 1364 | E5: 41223 | F5: =SUM(B5:E5) -> 174319
A6: BAKER | B6: 7750 | C6: 5358 | D6: 47 | E6: 1570 | F6: =SUM(B6:E6) -> 14725
A7: BAY | B7: 61564 | C7: 30553 | D7: 1002 | E7: 25620 | F7: =SUM(B7:E7) -> 118739
A8: BRADFORD | B8: 7552 | C8: 6091 | D8: 75 | E8: 2459 | F8: =SUM(B8:E8) -> 16177
A9: BREVARD | B9: 173484 | C9: 127552 | D9: 3630 | E9: 108227 | F9: =SUM(B9:E9) -> 412893
A10: BROWARD | B10: 245785 | C10: 572654 | D10: 5743 | E10: 322122 | F10: =SUM(B10:E10) -> 1146304
A11: CALHOUN | B11: 2454 | C11: 5164 | D11: 29 | E11: 977 | F11: =SUM(B11:E11) -> 8624
A12: CHARLOTTE | B12: 59300 | C12: 36234 | D12: 994 | E12: 35697 | F12: =SUM(B12:E12) -> 132225
A13: CITRUS | B13: 50674 | C13: 29406 | D13: 762 | E13: 26480 | F13: =SUM(B13:E13) -> 107322
A14: CLAY | B14: 80928 | C14: 33034 | D14: 1066 | E14: 35590 | F14: =SUM(B14:E14) -> 150618
A15: COLLIER | B15: 105615 | C15: 48696 | D15: 1018 | E15: 52076 | F15: =SUM(B15:E15) -> 207405
A16: COLUMBIA | B16: 17744 | C16: 14394 | D16: 248 | E16: 7098 | F16: =SUM(B16:E16) -> 39484
... A71: WASHINGTON | B71: 8029 | C71: 5362 | D71: 73 | E71: 2197 | F71: =SUM(B71:E71) -> 15661
A72: TOTALS | B72: =SUM(B5:B71) -> 4562533 | C72: =SUM(C5:C71) -> 4792599 | D72: =SUM(D5:D71) -> 82737 | E72: =SUM(E5:E71) -> 3489449 | F72: =SUM(F5:F71) -> 12927318

Sheet July
A1: Monthly Report - Voter Registration by Party Affiliation - July
A2: Data as of 07/31/2018
A3: ACTIVE REGISTERED VOTERS BY PARTY AFFILIATION BY COUNTY
A4: COUNTY | B4: REPUBLICAN PARTY OF FLORIDA | C4: FLORIDA DEMOCRATIC PARTY | D4: MINOR PARTY | E4: NO PARTY AFFILIATION | F4: TOTALS
A5: ALACHUA | B5: 49081 | C5: 83309 | D5: 1397 | E5: 40965 | F5: =SUM(B5:E5) -> 174752
A6: BAKER | B6: 7892 | C6: 5301 | D6: 47 | E6: 1578 | F6: =SUM(B6:E6) -> 14818
A7: BAY | B7: 61959 | C7: 30758 | D7: 1036 | E7: 25666 | F7: =SUM(B7:E7) -> 119419
A8: BRADFORD | B8: 7619 | C8: 6028 | D8: 77 | E8: 2463 | F8: =SUM(B8:E8) -> 16187
A9: BREVARD | B9: 174724 | C9: 128925 | D9: 3813 | E9: 108140 | F9: =SUM(B9:E9) -> 415602
A10: BROWARD | B10: 247129 | C10: 577395 | D10: 6088 | E10: 322657 | F10: =SUM(B10:E10) -> 1153269
A11: CALHOUN | B11: 2520 | C11: 5112 | D11: 29 | E11: 978 | F11: =SUM(B11:E11) -> 8639
A12: CHARLOTTE | B12: 59784 | C12: 36470 | D12: 1059 | E12: 35661 | F12: =SUM(B12:E12) -> 132974
A13: CITRUS | B13: 51178 | C13: 29548 | D13: 790 | E13: 26385 | F13: =SUM(B13:E13) -> 107901
A14: CLAY | B14: 81303 | C14: 33420 | D14: 1112 | E14: 35583 | F14: =SUM(B14:E14) -> 151418
A15: COLLIER | B15: 106244 | C15: 49392 | D15: 1074 | E15: 52265 | F15: =SUM(B15:E15) -> 208975
A16: COLUMBIA | B16: 18019 | C16: 14370 | D16: 261 | E16: 7132 | F16: =SUM(B16:E16) -> 39782
... A71: WASHINGTON | B71: 8079 | C71: 5339 | D71: 80 | E71: 2211 | F71: =SUM(B71:E71) -> 15709
A72: TOTALS | B72: =SUM(B5:B71) -> 4594373 | C72: =SUM(C5:C71) -> 4840119 | D72: =SUM(D5:D71) -> 86739 | E72: =SUM(E5:E71) -> 3494676 | F72: =SUM(F5:F71) -> 13015907

Sheet August
A1: Monthly Report - Voter Registration by Party Affiliation - August
A2: Data as of 08/31/2018
A3: ACTIVE REGISTERED VOTERS BY PARTY AFFILIATION BY COUNTY
A4: COUNTY | B4: REPUBLICAN PARTY OF FLORIDA | C4: FLORIDA DEMOCRATIC PARTY | D4: MINOR PARTY | E4: NO PARTY AFFILIATION | F4: TOTALS
A5: ALACHUA | B5: 49291 | C5: 84165 | D5: 1444 | E5: 41233 | F5: =SUM(B5:E5) -> 176133
A6: BAKER | B6: 8016 | C6: 5264 | D6: 48 | E6: 1581 | F6: =SUM(B6:E6) -> 14909
A7: BAY | B7: 62358 | C7: 30824 | D7: 1073 | E7: 25687 | F7: =SUM(B7:E7) -> 119942
A8: BRADFORD | B8: 7702 | C8: 5976 | D8: 81 | E8: 2443 | F8: =SUM(B8:E8) -> 16202
A9: BREVARD | B9: 175962 | C9: 129728 | D9: 4056 | E9: 108112 | F9: =SUM(B9:E9) -> 417858
A10: BROWARD | B10: 248084 | C10: 581495 | D10: 6510 | E10: 322549 | F10: =SUM(B10:E10) -> 1158638
A11: CALHOUN | B11: 2590 | C11: 5061 | D11: 29 | E11: 974 | F11: =SUM(B11:E11) -> 8654
A12: CHARLOTTE | B12: 60216 | C12: 36536 | D12: 1113 | E12: 35514 | F12: =SUM(B12:E12) -> 133379
A13: CITRUS | B13: 51772 | C13: 29531 | D13: 847 | E13: 26312 | F13: =SUM(B13:E13) -> 108462
A14: CLAY | B14: 81677 | C14: 33636 | D14: 1166 | E14: 35429 | F14: =SUM(B14:E14) -> 151908
A15: COLLIER | B15: 106967 | C15: 49889 | D15: 1164 | E15: 52411 | F15: =SUM(B15:E15) -> 210431
A16: COLUMBIA | B16: 18294 | C16: 14349 | D16: 266 | E16: 7077 | F16: =SUM(B16:E16) -> 39986
... A71: WASHINGTON | B71: 8135 | C71: 5303 | D71: 82 | E71: 2207 | F71: =SUM(B71:E71) -> 15727
A72: TOTALS | B72: =SUM(B5:B71) -> 4626815 | C72: =SUM(C5:C71) -> 4875282 | D72: =SUM(D5:D71) -> 91742 | E72: =SUM(E5:E71) -> 3500042 | F72: =SUM(F5:F71) -> 13093881

Sheet September
A1: Monthly Report - Voter Registration by Party Affiliation - September
A2: Data as of 09/30/2018
A3: ACTIVE REGISTERED VOTERS BY PARTY AFFILIATION BY COUNTY
A4: COUNTY | B4: REPUBLICAN PARTY OF FLORIDA | C4: FLORIDA DEMOCRATIC PARTY | D4: MINOR PARTY | E4: NO PARTY AFFILIATION | F4: TOTALS
A5: ALACHUA | B5: 49764 | C5: 85837 | D5: 1554 | E5: 42022 | F5: =SUM(B5:E5) -> 179177
A6: BAKER | B6: 8161 | C6: 5214 | D6: 50 | E6: 1590 | F6: =SUM(B6:E6) -> 15015
A7: BAY | B7: 62747 | C7: 30867 | D7: 1116 | E7: 25788 | F7: =SUM(B7:E7) -> 120518
A8: BRADFORD | B8: 7785 | C8: 5936 | D8: 87 | E8: 2446 | F8: =SUM(B8:E8) -> 16254
A9: BREVARD | B9: 177237 | C9: 130415 | D9: 4327 | E9: 108487 | F9: =SUM(B9:E9) -> 420466
A10: BROWARD | B10: 249822 | C10: 586833 | D10: 7094 | E10: 324233 | F10: =SUM(B10:E10) -> 1167982
A11: CALHOUN | B11: 2654 | C11: 5013 | D11: 31 | E11: 982 | F11: =SUM(B11:E11) -> 8680
A12: CHARLOTTE | B12: 60632 | C12: 36616 | D12: 1202 | E12: 35625 | F12: =SUM(B12:E12) -> 134075
A13: CITRUS | B13: 52204 | C13: 29555 | D13: 916 | E13: 26317 | F13: =SUM(B13:E13) -> 108992
A14: CLAY | B14: 82005 | C14: 33846 | D14: 1231 | E14: 35445 | F14: =SUM(B14:E14) -> 152527
A15: COLLIER | B15: 107721 | C15: 50507 | D15: 1298 | E15: 52842 | F15: =SUM(B15:E15) -> 212368
A16: COLUMBIA | B16: 18569 | C16: 14265 | D16: 288 | E16: 7092 | F16: =SUM(B16:E16) -> 40214
... A71: WASHINGTON | B71: 8216 | C71: 5250 | D71: 84 | E71: 2223 | F71: =SUM(B71:E71) -> 15773
A72: TOTALS | B72: =SUM(B5:B71) -> 4661230 | C72: =SUM(C5:C71) -> 4918415 | D72: =SUM(D5:D71) -> 99322 | E72: =SUM(E5:E71) -> 3521905 | F72: =SUM(F5:F71) -> 13200872

Sheet October
A1: Monthly Report - Voter Registration by Party Affiliation - October
A2: Data as of 10/31/2018
A3: ACTIVE REGISTERED VOTERS BY PARTY AFFILIATION BY COUNTY
A4: COUNTY | B4: REPUBLICAN PARTY OF FLORIDA | C4: FLORIDA DEMOCRATIC PARTY | D4: MINOR PARTY | E4: NO PARTY AFFILIATION | F4: TOTALS
A5: ALACHUA | B5: 50436 | C5: 87582 | D5: 1732 | E5: 43207 | F5: =SUM(B5:E5) -> 182957
A6: BAKER | B6: 8395 | C6: 5214 | D6: 54 | E6: 1614 | F6: =SUM(B6:E6) -> 15277
A7: BAY | B7: 63116 | C7: 30918 | D7: 1170 | E7: 25979 | F7: =SUM(B7:E7) -> 121183
A8: BRADFORD | B8: 7897 | C8: 5918 | D8: 89 | E8: 2454 | F8: =SUM(B8:E8) -> 16358
A9: BREVARD | B9: 178560 | C9: 131220 | D9: 4588 | E9: 109599 | F9: =SUM(B9:E9) -> 423967
A10: BROWARD | B10: 252243 | C10: 594604 | D10: 7857 | E10: 328997 | F10: =SUM(B10:E10) -> 1183701
A11: CALHOUN | B11: 2691 | C11: 4976 | D11: 31 | E11: 994 | F11: =SUM(B11:E11) -> 8692
A12: CHARLOTTE | B12: 61035 | C12: 36760 | D12: 1267 | E12: 35875 | F12: =SUM(B12:E12) -> 134937
A13: CITRUS | B13: 52686 | C13: 29574 | D13: 965 | E13: 26464 | F13: =SUM(B13:E13) -> 109689
A14: CLAY | B14: 82611 | C14: 34167 | D14: 1312 | E14: 35712 | F14: =SUM(B14:E14) -> 153802
A15: COLLIER | B15: 109009 | C15: 51227 | D15: 1431 | E15: 53605 | F15: =SUM(B15:E15) -> 215272
A16: COLUMBIA | B16: 18812 | C16: 14296 | D16: 300 | E16: 7162 | F16: =SUM(B16:E16) -> 40570
... A71: WASHINGTON | B71: 8298 | C71: 5220 | D71: 86 | E71: 2238 | F71: =SUM(B71:E71) -> 15842
A72: TOTALS | B72: =SUM(B5:B71) -> 4704835 | C72: =SUM(C5:C71) -> 4969086 | D72: =SUM(D5:D71) -> 107245 | E72: =SUM(E5:E71) -> 3568840 | F72: =SUM(F5:F71) -> 13350006

Sheet November
A1: Monthly Report - Voter Registration by Party Affiliation - November
A2: Data as of 11/30/2018
A3: ACTIVE REGISTERED VOTERS BY PARTY AFFILIATION BY COUNTY
A4: COUNTY | B4: REPUBLICAN PARTY OF FLORIDA | C4: FLORIDA DEMOCRATIC PARTY | D4: MINOR PARTY | E4: NO PARTY AFFILIATION | F4: TOTALS
A5: ALACHUA | B5: 50519 | C5: 87840 | D5: 1759 | E5: 43337 | F5: =SUM(B5:E5) -> 183455
A6: BAKER | B6: 8509 | C6: 5226 | D6: 60 | E6: 1651 | F6: =SUM(B6:E6) -> 15446
A7: BAY | B7: 63334 | C7: 30929 | D7: 1189 | E7: 26126 | F7: =SUM(B7:E7) -> 121578
A8: BRADFORD | B8: 7950 | C8: 5909 | D8: 92 | E8: 2470 | F8: =SUM(B8:E8) -> 16421
A9: BREVARD | B9: 179095 | C9: 131555 | D9: 4741 | E9: 110273 | F9: =SUM(B9:E9) -> 425664
A10: BROWARD | B10: 252804 | C10: 596447 | D10: 8162 | E10: 330604 | F10: =SUM(B10:E10) -> 1188017
A11: CALHOUN | B11: 2701 | C11: 4952 | D11: 30 | E11: 1003 | F11: =SUM(B11:E11) -> 8686
A12: CHARLOTTE | B12: 61295 | C12: 36869 | D12: 1315 | E12: 36080 | F12: =SUM(B12:E12) -> 135559
A13: CITRUS | B13: 52917 | C13: 29599 | D13: 1002 | E13: 26582 | F13: =SUM(B13:E13) -> 110100
A14: CLAY | B14: 82568 | C14: 34270 | D14: 1364 | E14: 35674 | F14: =SUM(B14:E14) -> 153876
A15: COLLIER | B15: 109754 | C15: 51670 | D15: 1495 | E15: 54215 | F15: =SUM(B15:E15) -> 217134
A16: COLUMBIA | B16: 18874 | C16: 14297 | D16: 303 | E16: 7181 | F16: =SUM(B16:E16) -> 40655
... A71: WASHINGTON | B71: 8336 | C71: 5206 | D71: 87 | E71: 2257 | F71: =SUM(B71:E71) -> 15886
A72: TOTALS | B72: =SUM(B5:B71) -> 4718846 | C72: =SUM(C5:C71) -> 4980923 | D72: =SUM(D5:D71) -> 110914 | E72: =SUM(E5:E71) -> 3585429 | F72: =SUM(F5:F71) -> 13396112

Sheet December
A1: Monthly Report - Voter Registration by Party Affiliation - December
A2: Data as of 12/31/2018
A3: ACTIVE REGISTERED VOTERS BY PARTY AFFILIATION BY COUNTY
A4: COUNTY | B4: REPUBLICAN PARTY OF FLORIDA | C4: FLORIDA DEMOCRATIC PARTY | D4: MINOR PARTY | E4: NO PARTY AFFILIATION | F4: TOTALS
A5: ALACHUA | B5: 50473 | C5: 87822 | D5: 1772 | E5: 43381 | F5: 183448
A6: BAKER | B6: 8522 | C6: 5219 | D6: 61 | E6: 1668 | F6: 15470
A7: BAY | B7: 62905 | C7: 30575 | D7: 1194 | E7: 25903 | F7: 120577
A8: BRADFORD | B8: 7967 | C8: 5910 | D8: 96 | E8: 2485 | F8: 16458
A9: BREVARD | B9: 179488 | C9: 131659 | D9: 4889 | E9: 110665 | F9: 426701
A10: BROWARD | B10: 252970 | C10: 597401 | D10: 8385 | E10: 331838 | F10: 1190594
A11: CALHOUN | B11: 2698 | C11: 4925 | D11: 30 | E11: 1004 | F11: 8657
A12: CHARLOTTE | B12: 61570 | C12: 36926 | D12: 1358 | E12: 36256 | F12: 136110
A13: CITRUS | B13: 53134 | C13: 29584 | D13: 1024 | E13: 26703 | F13: 110445
A14: CLAY | B14: 82220 | C14: 34119 | D14: 1377 | E14: 35596 | F14: 153312
A15: COLLIER | B15: 109583 | C15: 51439 | D15: 1502 | E15: 54005 | F15: 216529
A16: COLUMBIA | B16: 18684 | C16: 14128 | D16: 302 | E16: 7075 | F16: 40189
... A71: WASHINGTON | B71: 8292 | C71: 5140 | D71: 90 | E71: 2261 | F71: 15783
A72: TOTALS | B72: =SUM(B5:B71) -> 4718720 | C72: =SUM(C5:C71) -> 4975895 | D72: =SUM(D5:D71) -> 113489 | E72: =SUM(E5:E71) -> 3588518 | F72: =SUM(F5:F71) -> 13396622

Sheet NetPriorDecToJan
A1: Monthly Report - Net Activity by Party Affiliation - January to February
A2: Data comparison between 01/31/2018 - 02/28/2018
A3: ACTIVE REGISTERED VOTERS BY PARTY AFFILIATION BY COUNTY
A4: COUNTY | B4: REPUBLICAN PARTY OF FLORIDA | C4: FLORIDA DEMOCRATIC PARTY | D4: MINOR PARTY | E4: NO PARTY AFFILIATION | F4: TOTALS
A5: ALACHUA | B5: =January!B5-PriorDecember!B5 -> -4 | C5: =January!C5-PriorDecember!C5 -> 9 | D5: =January!D5-PriorDecember!D5 -> 29 | E5: =January!E5-PriorDecember!E5 -> 68 | F5: =SUM(B5:E5) -> 102
A6: BAKER | B6: =January!B6-PriorDecember!B6 -> 46 | C6: =January!C6-PriorDecember!C6 -> -21 | D6: =January!D6-PriorDecember!D6 -> -8 | E6: =January!E6-PriorDecember!E6 -> 27 | F6: =SUM(B6:E6) -> 44
A7: BAY | B7: =January!B7-PriorDecember!B7 -> 178 | C7: =January!C7-PriorDecember!C7 -> 12 | D7: =January!D7-PriorDecember!D7 -> 34 | E7: =January!E7-PriorDecember!E7 -> 145 | F7: =SUM(B7:E7) -> 369
A8: BRADFORD | B8: =January!B8-PriorDecember!B8 -> 4 | C8: =January!C8-PriorDecember!C8 -> -26 | D8: =January!D8-PriorDecember!D8 -> 3 | E8: =January!E8-PriorDecember!E8 -> 8 | F8: =SUM(B8:E8) -> -11
A9: BREVARD | B9: =January!B9-PriorDecember!B9 -> 146 | C9: =January!C9-PriorDecember!C9 -> -21 | D9: =January!D9-PriorDecember!D9 -> 123 | E9: =January!E9-PriorDecember!E9 -> 282 | F9: =SUM(B9:E9) -> 530
A10: BROWARD | B10: =January!B10-PriorDecember!B10 -> 129 | C10: =January!C10-PriorDecember!C10 -> -10 | D10: =January!D10-PriorDecember!D10 -> 300 | E10: =January!E10-PriorDecember!E10 -> 983 | F10: =SUM(B10:E10) -> 1402
A11: CALHOUN | B11: =January!B11-PriorDecember!B11 -> 8 | C11: =January!C11-PriorDecember!C11 -> -13 | D11: =January!D11-PriorDecember!D11 -> 1 | E11: =January!E11-PriorDecember!E11 -> 3 | F11: =SUM(B11:E11) -> -1
A12: CHARLOTTE | B12: =January!B12-PriorDecember!B12 -> 241 | C12: =January!C12-PriorDecember!C12 -> 71 | D12: =January!D12-PriorDecember!D12 -> 68 | E12: =January!E12-PriorDecember!E12 -> 222 | F12: =SUM(B12:E12) -> 602
A13: CITRUS | B13: =January!B13-PriorDecember!B13 -> 231 | C13: =January!C13-PriorDecember!C13 -> 29 | D13: =January!D13-PriorDecember!D13 -> 40 | E13: =January!E13-PriorDecember!E13 -> 126 | F13: =SUM(B13:E13) -> 426
A14: CLAY | B14: =January!B14-PriorDecember!B14 -> 78 | C14: =January!C14-PriorDecember!C14 -> -19 | D14: =January!D14-PriorDecember!D14 -> 29 | E14: =January!E14-PriorDecember!E14 -> 47 | F14: =SUM(B14:E14) -> 135
A15: COLLIER | B15: =January!B15-PriorDecember!B15 -> 476 | C15: =January!C15-PriorDecember!C15 -> 279 | D15: =January!D15-PriorDecember!D15 -> 34 | E15: =January!E15-PriorDecember!E15 -> 327 | F15: =SUM(B15:E15) -> 1116
A16: COLUMBIA | B16: =January!B16-PriorDecember!B16 -> 46 | C16: =January!C16-PriorDecember!C16 -> -52 | D16: =January!D16-PriorDecember!D16 -> 5 | E16: =January!E16-PriorDecember!E16 -> 9 | F16: =SUM(B16:E16) -> 8
... A71: WASHINGTON | B71: =January!B71-PriorDecember!B71 -> 37 | C71: =January!C71-PriorDecember!C71 -> -22 | D71: =January!D71-PriorDecember!D71 -> 4 | E71: =January!E71-PriorDecember!E71 -> 13 | F71: =SUM(B71:E71) -> 32
A72: TOTALS | B72: =SUM(B5:B71) -> 5848 | C72: =SUM(C5:C71) -> 2959 | D72: =SUM(D5:D71) -> 3358 | E72: =SUM(E5:E71) -> 13730 | F72: =SUM(F5:F71) -> 25895

Sheet NetJanToFeb
A1: Monthly Report - Net Activity by Party Affiliation - January to February
A2: Data comparison between 01/31/2018 - 02/28/2018
A3: ACTIVE REGISTERED VOTERS BY PARTY AFFILIATION BY COUNTY
A4: COUNTY | B4: REPUBLICAN PARTY OF FLORIDA | C4: FLORIDA DEMOCRATIC PARTY | D4: MINOR PARTY | E4: NO PARTY AFFILIATION | F4: TOTALS
A5: ALACHUA | B5: =February!B5-January!B5 -> 32 | C5: =February!C5-January!C5 -> 159 | D5: =February!D5-January!D5 -> 15 | E5: =February!E5-January!E5 -> 142 | F5: =SUM(B5:E5) -> 348
A6: BAKER | B6: =February!B6-January!B6 -> -71 | C6: =February!C6-January!C6 -> -51 | D6: =February!D6-January!D6 -> 1 | E6: =February!E6-January!E6 -> -26 | F6: =SUM(B6:E6) -> -147
A7: BAY | B7: =February!B7-January!B7 -> 185 | C7: =February!C7-January!C7 -> 62 | D7: =February!D7-January!D7 -> 31 | E7: =February!E7-January!E7 -> 182 | F7: =SUM(B7:E7) -> 460
A8: BRADFORD | B8: =February!B8-January!B8 -> 35 | C8: =February!C8-January!C8 -> -8 | D8: =February!D8-January!D8 -> 1 | E8: =February!E8-January!E8 -> 19 | F8: =SUM(B8:E8) -> 47
A9: BREVARD | B9: =February!B9-January!B9 -> 231 | C9: =February!C9-January!C9 -> 158 | D9: =February!D9-January!D9 -> 115 | E9: =February!E9-January!E9 -> 362 | F9: =SUM(B9:E9) -> 866
A10: BROWARD | B10: =February!B10-January!B10 -> -74 | C10: =February!C10-January!C10 -> -43 | D10: =February!D10-January!D10 -> 267 | E10: =February!E10-January!E10 -> 717 | F10: =SUM(B10:E10) -> 867
A11: CALHOUN | B11: =February!B11-January!B11 -> -3 | C11: =February!C11-January!C11 -> -10 | D11: =February!D11-January!D11 -> 1 | E11: =February!E11-January!E11 -> 0 | F11: =SUM(B11:E11) -> -12
A12: CHARLOTTE | B12: =February!B12-January!B12 -> 218 | C12: =February!C12-January!C12 -> 79 | D12: =February!D12-January!D12 -> 29 | E12: =February!E12-January!E12 -> 171 | F12: =SUM(B12:E12) -> 497
A13: CITRUS | B13: =February!B13-January!B13 -> 269 | C13: =February!C13-January!C13 -> 85 | D13: =February!D13-January!D13 -> 38 | E13: =February!E13-January!E13 -> 151 | F13: =SUM(B13:E13) -> 543
A14: CLAY | B14: =February!B14-January!B14 -> 34 | C14: =February!C14-January!C14 -> 85 | D14: =February!D14-January!D14 -> 43 | E14: =February!E14-January!E14 -> 69 | F14: =SUM(B14:E14) -> 231
A15: COLLIER | B15: =February!B15-January!B15 -> 470 | C15: =February!C15-January!C15 -> 308 | D15: =February!D15-January!D15 -> 30 | E15: =February!E15-January!E15 -> 378 | F15: =SUM(B15:E15) -> 1186
A16: COLUMBIA | B16: =February!B16-January!B16 -> 64 | C16: =February!C16-January!C16 -> -9 | D16: =February!D16-January!D16 -> 6 | E16: =February!E16-January!E16 -> 15 | F16: =SUM(B16:E16) -> 76
... A71: WASHINGTON | B71: =February!B71-January!B71 -> 31 | C71: =February!C71-January!C71 -> -1 | D71: =February!D71-January!D71 -> 2 | E71: =February!E71-January!E71 -> 20 | F71: =SUM(B71:E71) -> 52
A72: TOTALS | B72: =SUM(B5:B71) -> 5845 | C72: =SUM(C5:C71) -> 4460 | D72: =SUM(D5:D71) -> 3282 | E72: =SUM(E5:E71) -> 11431 | F72: =SUM(F5:F71) -> 25018

Sheet NetFebToMar
A1: Monthly Report - Net Activity by Party Affiliation - Feburary to March
A2: Data comparison between 02/28/2018 - 03/31/2018
A3: ACTIVE REGISTERED VOTERS BY PARTY AFFILIATION BY COUNTY
A4: COUNTY | B4: REPUBLICAN PARTY OF FLORIDA | C4: FLORIDA DEMOCRATIC PARTY | D4: MINOR PARTY | E4: NO PARTY AFFILIATION | F4: TOTALS
A5: ALACHUA | B5: =March!B5-February!B5 -> 35 | C5: =March!C5-February!C5 -> 129 | D5: =March!D5-February!D5 -> 36 | E5: =March!E5-February!E5 -> 182 | F5: =SUM(B5:E5) -> 382
A6: BAKER | B6: =March!B6-February!B6 -> -10 | C6: =March!C6-February!C6 -> -18 | D6: =March!D6-February!D6 -> 0 | E6: =March!E6-February!E6 -> 5 | F6: =SUM(B6:E6) -> -23
A7: BAY | B7: =March!B7-February!B7 -> 202 | C7: =March!C7-February!C7 -> 0 | D7: =March!D7-February!D7 -> 40 | E7: =March!E7-February!E7 -> 157 | F7: =SUM(B7:E7) -> 399
A8: BRADFORD | B8: =March!B8-February!B8 -> 15 | C8: =March!C8-February!C8 -> -8 | D8: =March!D8-February!D8 -> -1 | E8: =March!E8-February!E8 -> 15 | F8: =SUM(B8:E8) -> 21
A9: BREVARD | B9: =March!B9-February!B9 -> -693 | C9: =March!C9-February!C9 -> -295 | D9: =March!D9-February!D9 -> -6 | E9: =March!E9-February!E9 -> -328 | F9: =SUM(B9:E9) -> -1322
A10: BROWARD | B10: =March!B10-February!B10 -> -4730 | C10: =March!C10-February!C10 -> -13104 | D10: =March!D10-February!D10 -> 157 | E10: =March!E10-February!E10 -> -7124 | F10: =SUM(B10:E10) -> -24801
A11: CALHOUN | B11: =March!B11-February!B11 -> 10 | C11: =March!C11-February!C11 -> -23 | D11: =March!D11-February!D11 -> 2 | E11: =March!E11-February!E11 -> 3 | F11: =SUM(B11:E11) -> -8
A12: CHARLOTTE | B12: =March!B12-February!B12 -> 269 | C12: =March!C12-February!C12 -> 75 | D12: =March!D12-February!D12 -> 42 | E12: =March!E12-February!E12 -> 252 | F12: =SUM(B12:E12) -> 638
A13: CITRUS | B13: =March!B13-February!B13 -> 153 | C13: =March!C13-February!C13 -> 27 | D13: =March!D13-February!D13 -> 14 | E13: =March!E13-February!E13 -> 119 | F13: =SUM(B13:E13) -> 313
A14: CLAY | B14: =March!B14-February!B14 -> 174 | C14: =March!C14-February!C14 -> 162 | D14: =March!D14-February!D14 -> 44 | E14: =March!E14-February!E14 -> 189 | F14: =SUM(B14:E14) -> 569
A15: COLLIER | B15: =March!B15-February!B15 -> 513 | C15: =March!C15-February!C15 -> 394 | D15: =March!D15-February!D15 -> 50 | E15: =March!E15-February!E15 -> 427 | F15: =SUM(B15:E15) -> 1384
A16: COLUMBIA | B16: =March!B16-February!B16 -> 84 | C16: =March!C16-February!C16 -> 3 | D16: =March!D16-February!D16 -> 6 | E16: =March!E16-February!E16 -> 44 | F16: =SUM(B16:E16) -> 137
... A71: WASHINGTON | B71: =March!B71-February!B71 -> 27 | C71: =March!C71-February!C71 -> -1 | D71: =March!D71-February!D71 -> 4 | E71: =March!E71-February!E71 -> 0 | F71: =SUM(B71:E71) -> 30
A72: TOTALS | B72: =SUM(B5:B71) -> -1570 | C72: =SUM(C5:C71) -> -9634 | D72: =SUM(D5:D71) -> 2277 | E72: =SUM(E5:E71) -> 3755 | F72: =SUM(F5:F71) -> -5172

Sheet NetMarToApr
A1: Monthly Report - Net Activity by Party Affiliation - March to April
A2: Data comparison between 03/31/2018 - 04/30/2018
A3: ACTIVE REGISTERED VOTERS BY PARTY AFFILIATION BY COUNTY
A4: COUNTY | B4: REPUBLICAN PARTY OF FLORIDA | C4: FLORIDA DEMOCRATIC PARTY | D4: MINOR PARTY | E4: NO PARTY AFFILIATION | F4: TOTALS
A5: ALACHUA | B5: =April!B5-March!B5 -> 40 | C5: =April!C5-March!C5 -> 67 | D5: =April!D5-March!D5 -> 26 | E5: =April!E5-March!E5 -> 144 | F5: =SUM(B5:E5) -> 277
A6: BAKER | B6: =April!B6-March!B6 -> -7 | C6: =April!C6-March!C6 -> -31 | D6: =April!D6-March!D6 -> 2 | E6: =April!E6-March!E6 -> 4 | F6: =SUM(B6:E6) -> -32
A7: BAY | B7: =April!B7-March!B7 -> 112 | C7: =April!C7-March!C7 -> 17 | D7: =April!D7-March!D7 -> 31 | E7: =April!E7-March!E7 -> 97 | F7: =SUM(B7:E7) -> 257
A8: BRADFORD | B8: =April!B8-March!B8 -> 17 | C8: =April!C8-March!C8 -> 4 | D8: =April!D8-March!D8 -> 4 | E8: =April!E8-March!E8 -> 10 | F8: =SUM(B8:E8) -> 35
A9: BREVARD | B9: =April!B9-March!B9 -> 501 | C9: =April!C9-March!C9 -> 463 | D9: =April!D9-March!D9 -> 133 | E9: =April!E9-March!E9 -> 491 | F9: =SUM(B9:E9) -> 1588
A10: BROWARD | B10: =April!B10-March!B10 -> -4104 | C10: =April!C10-March!C10 -> -11025 | D10: =April!D10-March!D10 -> 121 | E10: =April!E10-March!E10 -> -5956 | F10: =SUM(B10:E10) -> -20964
A11: CALHOUN | B11: =April!B11-March!B11 -> 9 | C11: =April!C11-March!C11 -> -8 | D11: =April!D11-March!D11 -> 0 | E11: =April!E11-March!E11 -> -1 | F11: =SUM(B11:E11) -> 0
A12: CHARLOTTE | B12: =April!B12-March!B12 -> 234 | C12: =April!C12-March!C12 -> 14 | D12: =April!D12-March!D12 -> 25 | E12: =April!E12-March!E12 -> 97 | F12: =SUM(B12:E12) -> 370
A13: CITRUS | B13: =April!B13-March!B13 -> 245 | C13: =April!C13-March!C13 -> 30 | D13: =April!D13-March!D13 -> 20 | E13: =April!E13-March!E13 -> 61 | F13: =SUM(B13:E13) -> 356
A14: CLAY | B14: =April!B14-March!B14 -> -33 | C14: =April!C14-March!C14 -> 2 | D14: =April!D14-March!D14 -> 15 | E14: =April!E14-March!E14 -> 99 | F14: =SUM(B14:E14) -> 83
A15: COLLIER | B15: =April!B15-March!B15 -> 423 | C15: =April!C15-March!C15 -> 283 | D15: =April!D15-March!D15 -> 22 | E15: =April!E15-March!E15 -> 323 | F15: =SUM(B15:E15) -> 1051
A16: COLUMBIA | B16: =April!B16-March!B16 -> 101 | C16: =April!C16-March!C16 -> 11 | D16: =April!D16-March!D16 -> 7 | E16: =April!E16-March!E16 -> 58 | F16: =SUM(B16:E16) -> 177
... A71: WASHINGTON | B71: =April!B71-March!B71 -> 31 | C71: =April!C71-March!C71 -> -11 | D71: =April!D71-March!D71 -> -2 | E71: =April!E71-March!E71 -> 14 | F71: =SUM(B71:E71) -> 32
A72: TOTALS | B72: =SUM(B5:B71) -> 942 | C72: =SUM(C5:C71) -> -6762 | D72: =SUM(D5:D71) -> 2510 | E72: =SUM(E5:E71) -> 4786 | F72: =SUM(F5:F71) -> 1476

Sheet NetAprToMay
A1: Monthly Report - Net Activity by Party Affiliation - April to May
A2: Data comparison between 04/30/2018 - 5/31-2018
A3: ACTIVE REGISTERED VOTERS BY PARTY AFFILIATION BY COUNTY
A4: COUNTY | B4: REPUBLICAN PARTY OF FLORIDA | C4: FLORIDA DEMOCRATIC PARTY | D4: MINOR PARTY | E4: NO PARTY AFFILIATION | F4: TOTALS
A5: ALACHUA | B5: =May!B5-April!B5 -> -22 | C5: =May!C5-April!C5 -> 90 | D5: =May!D5-April!D5 -> 32 | E5: =May!E5-April!E5 -> 120 | F5: =SUM(B5:E5) -> 220
A6: BAKER | B6: =May!B6-April!B6 -> -3 | C6: =May!C6-April!C6 -> -41 | D6: =May!D6-April!D6 -> 2 | E6: =May!E6-April!E6 -> -9 | F6: =SUM(B6:E6) -> -51
A7: BAY | B7: =May!B7-April!B7 -> 175 | C7: =May!C7-April!C7 -> -14 | D7: =May!D7-April!D7 -> 33 | E7: =May!E7-April!E7 -> 154 | F7: =SUM(B7:E7) -> 348
A8: BRADFORD | B8: =May!B8-April!B8 -> 6 | C8: =May!C8-April!C8 -> -19 | D8: =May!D8-April!D8 -> 0 | E8: =May!E8-April!E8 -> 7 | F8: =SUM(B8:E8) -> -6
A9: BREVARD | B9: =May!B9-April!B9 -> 573 | C9: =May!C9-April!C9 -> 234 | D9: =May!D9-April!D9 -> 119 | E9: =May!E9-April!E9 -> 502 | F9: =SUM(B9:E9) -> 1428
A10: BROWARD | B10: =May!B10-April!B10 -> 361 | C10: =May!C10-April!C10 -> 1017 | D10: =May!D10-April!D10 -> 246 | E10: =May!E10-April!E10 -> 1465 | F10: =SUM(B10:E10) -> 3089
A11: CALHOUN | B11: =May!B11-April!B11 -> 15 | C11: =May!C11-April!C11 -> -11 | D11: =May!D11-April!D11 -> -2 | E11: =May!E11-April!E11 -> 17 | F11: =SUM(B11:E11) -> 19
A12: CHARLOTTE | B12: =May!B12-April!B12 -> 220 | C12: =May!C12-April!C12 -> 61 | D12: =May!D12-April!D12 -> 51 | E12: =May!E12-April!E12 -> 126 | F12: =SUM(B12:E12) -> 458
A13: CITRUS | B13: =May!B13-April!B13 -> 208 | C13: =May!C13-April!C13 -> 20 | D13: =May!D13-April!D13 -> 30 | E13: =May!E13-April!E13 -> 107 | F13: =SUM(B13:E13) -> 365
A14: CLAY | B14: =May!B14-April!B14 -> -33 | C14: =May!C14-April!C14 -> 11 | D14: =May!D14-April!D14 -> 28 | E14: =May!E14-April!E14 -> -30 | F14: =SUM(B14:E14) -> -24
A15: COLLIER | B15: =May!B15-April!B15 -> 419 | C15: =May!C15-April!C15 -> 309 | D15: =May!D15-April!D15 -> 40 | E15: =May!E15-April!E15 -> 250 | F15: =SUM(B15:E15) -> 1018
A16: COLUMBIA | B16: =May!B16-April!B16 -> 60 | C16: =May!C16-April!C16 -> 25 | D16: =May!D16-April!D16 -> 2 | E16: =May!E16-April!E16 -> 29 | F16: =SUM(B16:E16) -> 116
... A71: WASHINGTON | B71: =May!B71-April!B71 -> -53 | C71: =May!C71-April!C71 -> -76 | D71: =May!D71-April!D71 -> 3 | E71: =May!E71-April!E71 -> -23 | F71: =SUM(B71:E71) -> -149
A72: TOTALS | B72: =SUM(B5:B71) -> -8138 | C72: =SUM(C5:C71) -> -22881 | D72: =SUM(D5:D71) -> 2634 | E72: =SUM(E5:E71) -> -10023 | F72: =SUM(F5:F71) -> -38408

Sheet NetMayToJun
A1: Monthly Report - Net Activity by Party Affiliation - May to June
A2: Data comparison between 05/31/2018 - 06/30/2018
A3: ACTIVE REGISTERED VOTERS BY PARTY AFFILIATION BY COUNTY
A4: COUNTY | B4: REPUBLICAN PARTY OF FLORIDA | C4: FLORIDA DEMOCRATIC PARTY | D4: MINOR PARTY | E4: NO PARTY AFFILIATION | F4: TOTALS
A5: ALACHUA | B5: =June!B5-May!B5 -> -1 | C5: =June!C5-May!C5 -> 119 | D5: =June!D5-May!D5 -> 28 | E5: =June!E5-May!E5 -> 180 | F5: =SUM(B5:E5) -> 326
A6: BAKER | B6: =June!B6-May!B6 -> -118 | C6: =June!C6-May!C6 -> -205 | D6: =June!D6-May!D6 -> 0 | E6: =June!E6-May!E6 -> -44 | F6: =SUM(B6:E6) -> -367
A7: BAY | B7: =June!B7-May!B7 -> 219 | C7: =June!C7-May!C7 -> 18 | D7: =June!D7-May!D7 -> 29 | E7: =June!E7-May!E7 -> 129 | F7: =SUM(B7:E7) -> 395
A8: BRADFORD | B8: =June!B8-May!B8 -> 29 | C8: =June!C8-May!C8 -> -37 | D8: =June!D8-May!D8 -> 0 | E8: =June!E8-May!E8 -> 19 | F8: =SUM(B8:E8) -> 11
A9: BREVARD | B9: =June!B9-May!B9 -> 784 | C9: =June!C9-May!C9 -> 411 | D9: =June!D9-May!D9 -> 146 | E9: =June!E9-May!E9 -> 361 | F9: =SUM(B9:E9) -> 1702
A10: BROWARD | B10: =June!B10-May!B10 -> 614 | C10: =June!C10-May!C10 -> 2175 | D10: =June!D10-May!D10 -> 253 | E10: =June!E10-May!E10 -> 1902 | F10: =SUM(B10:E10) -> 4944
A11: CALHOUN | B11: =June!B11-May!B11 -> 22 | C11: =June!C11-May!C11 -> -27 | D11: =June!D11-May!D11 -> 2 | E11: =June!E11-May!E11 -> 7 | F11: =SUM(B11:E11) -> 4
A12: CHARLOTTE | B12: =June!B12-May!B12 -> 214 | C12: =June!C12-May!C12 -> 161 | D12: =June!D12-May!D12 -> 50 | E12: =June!E12-May!E12 -> 66 | F12: =SUM(B12:E12) -> 491
A13: CITRUS | B13: =June!B13-May!B13 -> 232 | C13: =June!C13-May!C13 -> 28 | D13: =June!D13-May!D13 -> 28 | E13: =June!E13-May!E13 -> 62 | F13: =SUM(B13:E13) -> 350
A14: CLAY | B14: =June!B14-May!B14 -> 147 | C14: =June!C14-May!C14 -> 102 | D14: =June!D14-May!D14 -> 26 | E14: =June!E14-May!E14 -> 109 | F14: =SUM(B14:E14) -> 384
A15: COLLIER | B15: =June!B15-May!B15 -> 401 | C15: =June!C15-May!C15 -> 275 | D15: =June!D15-May!D15 -> 53 | E15: =June!E15-May!E15 -> 238 | F15: =SUM(B15:E15) -> 967
A16: COLUMBIA | B16: =June!B16-May!B16 -> 78 | C16: =June!C16-May!C16 -> 4 | D16: =June!D16-May!D16 -> 8 | E16: =June!E16-May!E16 -> 35 | F16: =SUM(B16:E16) -> 125
... A71: WASHINGTON | B71: =June!B71-May!B71 -> 47 | C71: =June!C71-May!C71 -> -5 | D71: =June!D71-May!D71 -> 3 | E71: =June!E71-May!E71 -> 12 | F71: =SUM(B71:E71) -> 57
A72: TOTALS | B72: =SUM(B5:B71) -> 14898 | C72: =SUM(C5:C71) -> 16507 | D72: =SUM(D5:D71) -> 3150 | E72: =SUM(E5:E71) -> 16765 | F72: =SUM(F5:F71) -> 51320

Sheet NetJunToJul
A1: Monthly Report - Net Activity by Party Affiliation - June to July
A2: Data comparison between 06/30/2018 - 07/31/2018
A3: ACTIVE REGISTERED VOTERS BY PARTY AFFILIATION BY COUNTY
A4: COUNTY | B4: REPUBLICAN PARTY OF FLORIDA | C4: FLORIDA DEMOCRATIC PARTY | D4: MINOR PARTY | E4: NO PARTY AFFILIATION | F4: TOTALS
A5: ALACHUA | B5: =July!B5-June!B5 -> 126 | C5: =July!C5-June!C5 -> 532 | D5: =July!D5-June!D5 -> 33 | E5: =July!E5-June!E5 -> -258 | F5: =SUM(B5:E5) -> 433
A6: BAKER | B6: =July!B6-June!B6 -> 142 | C6: =July!C6-June!C6 -> -57 | D6: =July!D6-June!D6 -> 0 | E6: =July!E6-June!E6 -> 8 | F6: =SUM(B6:E6) -> 93
A7: BAY | B7: =July!B7-June!B7 -> 395 | C7: =July!C7-June!C7 -> 205 | D7: =July!D7-June!D7 -> 34 | E7: =July!E7-June!E7 -> 46 | F7: =SUM(B7:E7) -> 680
A8: BRADFORD | B8: =July!B8-June!B8 -> 67 | C8: =July!C8-June!C8 -> -63 | D8: =July!D8-June!D8 -> 2 | E8: =July!E8-June!E8 -> 4 | F8: =SUM(B8:E8) -> 10
A9: BREVARD | B9: =July!B9-June!B9 -> 1240 | C9: =July!C9-June!C9 -> 1373 | D9: =July!D9-June!D9 -> 183 | E9: =July!E9-June!E9 -> -87 | F9: =SUM(B9:E9) -> 2709
A10: BROWARD | B10: =July!B10-June!B10 -> 1344 | C10: =July!C10-June!C10 -> 4741 | D10: =July!D10-June!D10 -> 345 | E10: =July!E10-June!E10 -> 535 | F10: =SUM(B10:E10) -> 6965
A11: CALHOUN | B11: =July!B11-June!B11 -> 66 | C11: =July!C11-June!C11 -> -52 | D11: =July!D11-June!D11 -> 0 | E11: =July!E11-June!E11 -> 1 | F11: =SUM(B11:E11) -> 15
A12: CHARLOTTE | B12: =July!B12-June!B12 -> 484 | C12: =July!C12-June!C12 -> 236 | D12: =July!D12-June!D12 -> 65 | E12: =July!E12-June!E12 -> -36 | F12: =SUM(B12:E12) -> 749
A13: CITRUS | B13: =July!B13-June!B13 -> 504 | C13: =July!C13-June!C13 -> 142 | D13: =July!D13-June!D13 -> 28 | E13: =July!E13-June!E13 -> -95 | F13: =SUM(B13:E13) -> 579
A14: CLAY | B14: =July!B14-June!B14 -> 375 | C14: =July!C14-June!C14 -> 386 | D14: =July!D14-June!D14 -> 46 | E14: =July!E14-June!E14 -> -7 | F14: =SUM(B14:E14) -> 800
A15: COLLIER | B15: =July!B15-June!B15 -> 629 | C15: =July!C15-June!C15 -> 696 | D15: =July!D15-June!D15 -> 56 | E15: =July!E15-June!E15 -> 189 | F15: =SUM(B15:E15) -> 1570
A16: COLUMBIA | B16: =July!B16-June!B16 -> 275 | C16: =July!C16-June!C16 -> -24 | D16: =July!D16-June!D16 -> 13 | E16: =July!E16-June!E16 -> 34 | F16: =SUM(B16:E16) -> 298
... A71: WASHINGTON | B71: =July!B71-June!B71 -> 50 | C71: =July!C71-June!C71 -> -23 | D71: =July!D71-June!D71 -> 7 | E71: =July!E71-June!E71 -> 14 | F71: =SUM(B71:E71) -> 48
A72: TOTALS | B72: =SUM(B5:B71) -> 31840 | C72: =SUM(C5:C71) -> 47520 | D72: =SUM(D5:D71) -> 4002 | E72: =SUM(E5:E71) -> 5227 | F72: =SUM(F5:F71) -> 88589

Sheet NetJulToAug
A1: Monthly Report - Net Activity by Party Affiliation - July to August
A2: Data comparison between 07/31/2018 - 08/31/2018
A3: ACTIVE REGISTERED VOTERS BY PARTY AFFILIATION BY COUNTY
A4: COUNTY | B4: REPUBLICAN PARTY OF FLORIDA | C4: FLORIDA DEMOCRATIC PARTY | D4: MINOR PARTY | E4: NO PARTY AFFILIATION | F4: TOTALS
A5: ALACHUA | B5: =August!B5-July!B5 -> 210 | C5: =August!C5-July!C5 -> 856 | D5: =August!D5-July!D5 -> 47 | E5: =August!E5-July!E5 -> 268 | F5: =SUM(B5:E5) -> 1381
A6: BAKER | B6: =August!B6-July!B6 -> 124 | C6: =August!C6-July!C6 -> -37 | D6: =August!D6-July!D6 -> 1 | E6: =August!E6-July!E6 -> 3 | F6: =SUM(B6:E6) -> 91
A7: BAY | B7: =August!B7-July!B7 -> 399 | C7: =August!C7-July!C7 -> 66 | D7: =August!D7-July!D7 -> 37 | E7: =August!E7-July!E7 -> 21 | F7: =SUM(B7:E7) -> 523
A8: BRADFORD | B8: =August!B8-July!B8 -> 83 | C8: =August!C8-July!C8 -> -52 | D8: =August!D8-July!D8 -> 4 | E8: =August!E8-July!E8 -> -20 | F8: =SUM(B8:E8) -> 15
A9: BREVARD | B9: =August!B9-July!B9 -> 1238 | C9: =August!C9-July!C9 -> 803 | D9: =August!D9-July!D9 -> 243 | E9: =August!E9-July!E9 -> -28 | F9: =SUM(B9:E9) -> 2256
A10: BROWARD | B10: =August!B10-July!B10 -> 955 | C10: =August!C10-July!C10 -> 4100 | D10: =August!D10-July!D10 -> 422 | E10: =August!E10-July!E10 -> -108 | F10: =SUM(B10:E10) -> 5369
A11: CALHOUN | B11: =August!B11-July!B11 -> 70 | C11: =August!C11-July!C11 -> -51 | D11: =August!D11-July!D11 -> 0 | E11: =August!E11-July!E11 -> -4 | F11: =SUM(B11:E11) -> 15
A12: CHARLOTTE | B12: =August!B12-July!B12 -> 432 | C12: =August!C12-July!C12 -> 66 | D12: =August!D12-July!D12 -> 54 | E12: =August!E12-July!E12 -> -147 | F12: =SUM(B12:E12) -> 405
A13: CITRUS | B13: =August!B13-July!B13 -> 594 | C13: =August!C13-July!C13 -> -17 | D13: =August!D13-July!D13 -> 57 | E13: =August!E13-July!E13 -> -73 | F13: =SUM(B13:E13) -> 561
A14: CLAY | B14: =August!B14-July!B14 -> 374 | C14: =August!C14-July!C14 -> 216 | D14: =August!D14-July!D14 -> 54 | E14: =August!E14-July!E14 -> -154 | F14: =SUM(B14:E14) -> 490
A15: COLLIER | B15: =August!B15-July!B15 -> 723 | C15: =August!C15-July!C15 -> 497 | D15: =August!D15-July!D15 -> 90 | E15: =August!E15-July!E15 -> 146 | F15: =SUM(B15:E15) -> 1456
A16: COLUMBIA | B16: =August!B16-July!B16 -> 275 | C16: =August!C16-July!C16 -> -21 | D16: =August!D16-July!D16 -> 5 | E16: =August!E16-July!E16 -> -55 | F16: =SUM(B16:E16) -> 204
... A71: WASHINGTON | B71: =August!B71-July!B71 -> 56 | C71: =August!C71-July!C71 -> -36 | D71: =August!D71-July!D71 -> 2 | E71: =August!E71-July!E71 -> -4 | F71: =SUM(B71:E71) -> 18
A72: TOTALS | B72: =SUM(B5:B71) -> 32442 | C72: =SUM(C5:C71) -> 35163 | D72: =SUM(D5:D71) -> 5003 | E72: =SUM(E5:E71) -> 5366 | F72: =SUM(F5:F71) -> 77974

Sheet NetAugToSep
A1: Monthly Report - Net Activity by Party Affiliation - August to September
A2: Data comparison between 08/31/2018 - 09/30/2018
A3: ACTIVE REGISTERED VOTERS BY PARTY AFFILIATION BY COUNTY
A4: COUNTY | B4: REPUBLICAN PARTY OF FLORIDA | C4: FLORIDA DEMOCRATIC PARTY | D4: MINOR PARTY | E4: NO PARTY AFFILIATION | F4: TOTALS
A5: ALACHUA | B5: =September!B5-August!B5 -> 473 | C5: =September!C5-August!C5 -> 1672 | D5: =September!D5-August!D5 -> 110 | E5: =September!E5-August!E5 -> 789 | F5: =SUM(B5:E5) -> 3044
A6: BAKER | B6: =September!B6-August!B6 -> 145 | C6: =September!C6-August!C6 -> -50 | D6: =September!D6-August!D6 -> 2 | E6: =September!E6-August!E6 -> 9 | F6: =SUM(B6:E6) -> 106
A7: BAY | B7: =September!B7-August!B7 -> 389 | C7: =September!C7-August!C7 -> 43 | D7: =September!D7-August!D7 -> 43 | E7: =September!E7-August!E7 -> 101 | F7: =SUM(B7:E7) -> 576
A8: BRADFORD | B8: =September!B8-August!B8 -> 83 | C8: =September!C8-August!C8 -> -40 | D8: =September!D8-August!D8 -> 6 | E8: =September!E8-August!E8 -> 3 | F8: =SUM(B8:E8) -> 52
A9: BREVARD | B9: =September!B9-August!B9 -> 1275 | C9: =September!C9-August!C9 -> 687 | D9: =September!D9-August!D9 -> 271 | E9: =September!E9-August!E9 -> 375 | F9: =SUM(B9:E9) -> 2608
A10: BROWARD | B10: =September!B10-August!B10 -> 1738 | C10: =September!C10-August!C10 -> 5338 | D10: =September!D10-August!D10 -> 584 | E10: =September!E10-August!E10 -> 1684 | F10: =SUM(B10:E10) -> 9344
A11: CALHOUN | B11: =September!B11-August!B11 -> 64 | C11: =September!C11-August!C11 -> -48 | D11: =September!D11-August!D11 -> 2 | E11: =September!E11-August!E11 -> 8 | F11: =SUM(B11:E11) -> 26
A12: CHARLOTTE | B12: =September!B12-August!B12 -> 416 | C12: =September!C12-August!C12 -> 80 | D12: =September!D12-August!D12 -> 89 | E12: =September!E12-August!E12 -> 111 | F12: =SUM(B12:E12) -> 696
A13: CITRUS | B13: =September!B13-August!B13 -> 432 | C13: =September!C13-August!C13 -> 24 | D13: =September!D13-August!D13 -> 69 | E13: =September!E13-August!E13 -> 5 | F13: =SUM(B13:E13) -> 530
A14: CLAY | B14: =September!B14-August!B14 -> 328 | C14: =September!C14-August!C14 -> 210 | D14: =September!D14-August!D14 -> 65 | E14: =September!E14-August!E14 -> 16 | F14: =SUM(B14:E14) -> 619
A15: COLLIER | B15: =September!B15-August!B15 -> 754 | C15: =September!C15-August!C15 -> 618 | D15: =September!D15-August!D15 -> 134 | E15: =September!E15-August!E15 -> 431 | F15: =SUM(B15:E15) -> 1937
A16: COLUMBIA | B16: =September!B16-August!B16 -> 275 | C16: =September!C16-August!C16 -> -84 | D16: =September!D16-August!D16 -> 22 | E16: =September!E16-August!E16 -> 15 | F16: =SUM(B16:E16) -> 228
... A71: WASHINGTON | B71: =September!B71-August!B71 -> 81 | C71: =September!C71-August!C71 -> -53 | D71: =September!D71-August!D71 -> 2 | E71: =September!E71-August!E71 -> 16 | F71: =SUM(B71:E71) -> 46
A72: TOTALS | B72: =SUM(B5:B71) -> 34415 | C72: =SUM(C5:C71) -> 43133 | D72: =SUM(D5:D71) -> 7580 | E72: =SUM(E5:E71) -> 21863 | F72: =SUM(F5:F71) -> 106991

Sheet NetSepToOct
A1: Monthly Report - Net Activity by Party Affiliation - September to October
A2: Data comparison between 09/30/2018 - 10/31/2018
A3: ACTIVE REGISTERED VOTERS BY PARTY AFFILIATION BY COUNTY
A4: COUNTY | B4: REPUBLICAN PARTY OF FLORIDA | C4: FLORIDA DEMOCRATIC PARTY | D4: MINOR PARTY | E4: NO PARTY AFFILIATION | F4: TOTALS
A5: ALACHUA | B5: =October!B5-September!B5 -> 672 | C5: =October!C5-September!C5 -> 1745 | D5: =October!D5-September!D5 -> 178 | E5: =October!E5-September!E5 -> 1185 | F5: =SUM(B5:E5) -> 3780
A6: BAKER | B6: =October!B6-September!B6 -> 234 | C6: =October!C6-September!C6 -> 0 | D6: =October!D6-September!D6 -> 4 | E6: =October!E6-September!E6 -> 24 | F6: =SUM(B6:E6) -> 262
A7: BAY | B7: =October!B7-September!B7 -> 369 | C7: =October!C7-September!C7 -> 51 | D7: =October!D7-September!D7 -> 54 | E7: =October!E7-September!E7 -> 191 | F7: =SUM(B7:E7) -> 665
A8: BRADFORD | B8: =October!B8-September!B8 -> 112 | C8: =October!C8-September!C8 -> -18 | D8: =October!D8-September!D8 -> 2 | E8: =October!E8-September!E8 -> 8 | F8: =SUM(B8:E8) -> 104
A9: BREVARD | B9: =October!B9-September!B9 -> 1323 | C9: =October!C9-September!C9 -> 805 | D9: =October!D9-September!D9 -> 261 | E9: =October!E9-September!E9 -> 1112 | F9: =SUM(B9:E9) -> 3501
A10: BROWARD | B10: =October!B10-September!B10 -> 2421 | C10: =October!C10-September!C10 -> 7771 | D10: =October!D10-September!D10 -> 763 | E10: =October!E10-September!E10 -> 4764 | F10: =SUM(B10:E10) -> 15719
A11: CALHOUN | B11: =October!B11-September!B11 -> 37 | C11: =October!C11-September!C11 -> -37 | D11: =October!D11-September!D11 -> 0 | E11: =October!E11-September!E11 -> 12 | F11: =SUM(B11:E11) -> 12
A12: CHARLOTTE | B12: =October!B12-September!B12 -> 403 | C12: =October!C12-September!C12 -> 144 | D12: =October!D12-September!D12 -> 65 | E12: =October!E12-September!E12 -> 250 | F12: =SUM(B12:E12) -> 862
A13: CITRUS | B13: =October!B13-September!B13 -> 482 | C13: =October!C13-September!C13 -> 19 | D13: =October!D13-September!D13 -> 49 | E13: =October!E13-September!E13 -> 147 | F13: =SUM(B13:E13) -> 697
A14: CLAY | B14: =October!B14-September!B14 -> 606 | C14: =October!C14-September!C14 -> 321 | D14: =October!D14-September!D14 -> 81 | E14: =October!E14-September!E14 -> 267 | F14: =SUM(B14:E14) -> 1275
A15: COLLIER | B15: =October!B15-September!B15 -> 1288 | C15: =October!C15-September!C15 -> 720 | D15: =October!D15-September!D15 -> 133 | E15: =October!E15-September!E15 -> 763 | F15: =SUM(B15:E15) -> 2904
A16: COLUMBIA | B16: =October!B16-September!B16 -> 243 | C16: =October!C16-September!C16 -> 31 | D16: =October!D16-September!D16 -> 12 | E16: =October!E16-September!E16 -> 70 | F16: =SUM(B16:E16) -> 356
... A71: WASHINGTON | B71: =October!B71-September!B71 -> 82 | C71: =October!C71-September!C71 -> -30 | D71: =October!D71-September!D71 -> 2 | E71: =October!E71-September!E71 -> 15 | F71: =SUM(B71:E71) -> 69
A72: TOTALS | B72: =SUM(B5:B71) -> 43605 | C72: =SUM(C5:C71) -> 50671 | D72: =SUM(D5:D71) -> 7923 | E72: =SUM(E5:E71) -> 46935 | F72: =SUM(F5:F71) -> 149134

Sheet NetOctToNov
A1: Monthly Report - Net Activity by Party Affiliation - October to November
A2: Data comparison between 10/31/2018 - 11/30/2018
A3: ACTIVE REGISTERED VOTERS BY PARTY AFFILIATION BY COUNTY
A4: COUNTY | B4: REPUBLICAN PARTY OF FLORIDA | C4: FLORIDA DEMOCRATIC PARTY | D4: MINOR PARTY | E4: NO PARTY AFFILIATION | F4: TOTALS
A5: ALACHUA | B5: =November!B5-October!B5 -> 83 | C5: =November!C5-October!C5 -> 258 | D5: =November!D5-October!D5 -> 27 | E5: =November!E5-October!E5 -> 130 | F5: =SUM(B5:E5) -> 498
A6: BAKER | B6: =November!B6-October!B6 -> 114 | C6: =November!C6-October!C6 -> 12 | D6: =November!D6-October!D6 -> 6 | E6: =November!E6-October!E6 -> 37 | F6: =SUM(B6:E6) -> 169
A7: BAY | B7: =November!B7-October!B7 -> 218 | C7: =November!C7-October!C7 -> 11 | D7: =November!D7-October!D7 -> 19 | E7: =November!E7-October!E7 -> 147 | F7: =SUM(B7:E7) -> 395
A8: BRADFORD | B8: =November!B8-October!B8 -> 53 | C8: =November!C8-October!C8 -> -9 | D8: =November!D8-October!D8 -> 3 | E8: =November!E8-October!E8 -> 16 | F8: =SUM(B8:E8) -> 63
A9: BREVARD | B9: =November!B9-October!B9 -> 535 | C9: =November!C9-October!C9 -> 335 | D9: =November!D9-October!D9 -> 153 | E9: =November!E9-October!E9 -> 674 | F9: =SUM(B9:E9) -> 1697
A10: BROWARD | B10: =November!B10-October!B10 -> 561 | C10: =November!C10-October!C10 -> 1843 | D10: =November!D10-October!D10 -> 305 | E10: =November!E10-October!E10 -> 1607 | F10: =SUM(B10:E10) -> 4316
A11: CALHOUN | B11: =November!B11-October!B11 -> 10 | C11: =November!C11-October!C11 -> -24 | D11: =November!D11-October!D11 -> -1 | E11: =November!E11-October!E11 -> 9 | F11: =SUM(B11:E11) -> -6
A12: CHARLOTTE | B12: =November!B12-October!B12 -> 260 | C12: =November!C12-October!C12 -> 109 | D12: =November!D12-October!D12 -> 48 | E12: =November!E12-October!E12 -> 205 | F12: =SUM(B12:E12) -> 622
A13: CITRUS | B13: =November!B13-October!B13 -> 231 | C13: =November!C13-October!C13 -> 25 | D13: =November!D13-October!D13 -> 37 | E13: =November!E13-October!E13 -> 118 | F13: =SUM(B13:E13) -> 411
A14: CLAY | B14: =November!B14-October!B14 -> -43 | C14: =November!C14-October!C14 -> 103 | D14: =November!D14-October!D14 -> 52 | E14: =November!E14-October!E14 -> -38 | F14: =SUM(B14:E14) -> 74
A15: COLLIER | B15: =November!B15-October!B15 -> 745 | C15: =November!C15-October!C15 -> 443 | D15: =November!D15-October!D15 -> 64 | E15: =November!E15-October!E15 -> 610 | F15: =SUM(B15:E15) -> 1862
A16: COLUMBIA | B16: =November!B16-October!B16 -> 62 | C16: =November!C16-October!C16 -> 1 | D16: =November!D16-October!D16 -> 3 | E16: =November!E16-October!E16 -> 19 | F16: =SUM(B16:E16) -> 85
... A71: WASHINGTON | B71: =November!B71-October!B71 -> 38 | C71: =November!C71-October!C71 -> -14 | D71: =November!D71-October!D71 -> 1 | E71: =November!E71-October!E71 -> 19 | F71: =SUM(B71:E71) -> 44
A72: TOTALS | B72: =SUM(B5:B71) -> 14011 | C72: =SUM(C5:C71) -> 11837 | D72: =SUM(D5:D71) -> 3669 | E72: =SUM(E5:E71) -> 16589 | F72: =SUM(F5:F71) -> 46106

Sheet NetNovToDec
A1: Monthly Report - Net Activity by Party Affiliation - November to December
A2: Data comparison between 11/30/2018 - 12/31/2018
A3: ACTIVE REGISTERED VOTERS BY PARTY AFFILIATION BY COUNTY
A4: COUNTY | B4: REPUBLICAN PARTY OF FLORIDA | C4: FLORIDA DEMOCRATIC PARTY | D4: MINOR PARTY | E4: NO PARTY AFFILIATION | F4: TOTALS
A5: ALACHUA | B5: =December!B5-November!B5 -> -46 | C5: =December!C5-November!C5 -> -18 | D5: =December!D5-November!D5 -> 13 | E5: =December!E5-November!E5 -> 44 | F5: =SUM(B5:E5) -> -7
A6: BAKER | B6: =December!B6-November!B6 -> 13 | C6: =December!C6-November!C6 -> -7 | D6: =December!D6-November!D6 -> 1 | E6: =December!E6-November!E6 -> 17 | F6: =SUM(B6:E6) -> 24
A7: BAY | B7: =December!B7-November!B7 -> -429 | C7: =December!C7-November!C7 -> -354 | D7: =December!D7-November!D7 -> 5 | E7: =December!E7-November!E7 -> -223 | F7: =SUM(B7:E7) -> -1001
A8: BRADFORD | B8: =December!B8-November!B8 -> 17 | C8: =December!C8-November!C8 -> 1 | D8: =December!D8-November!D8 -> 4 | E8: =December!E8-November!E8 -> 15 | F8: =SUM(B8:E8) -> 37
A9: BREVARD | B9: =December!B9-November!B9 -> 393 | C9: =December!C9-November!C9 -> 104 | D9: =December!D9-November!D9 -> 148 | E9: =December!E9-November!E9 -> 392 | F9: =SUM(B9:E9) -> 1037
A10: BROWARD | B10: =December!B10-November!B10 -> 166 | C10: =December!C10-November!C10 -> 954 | D10: =December!D10-November!D10 -> 223 | E10: =December!E10-November!E10 -> 1234 | F10: =SUM(B10:E10) -> 2577
A11: CALHOUN | B11: =December!B11-November!B11 -> -3 | C11: =December!C11-November!C11 -> -27 | D11: =December!D11-November!D11 -> 0 | E11: =December!E11-November!E11 -> 1 | F11: =SUM(B11:E11) -> -29
A12: CHARLOTTE | B12: =December!B12-November!B12 -> 275 | C12: =December!C12-November!C12 -> 57 | D12: =December!D12-November!D12 -> 43 | E12: =December!E12-November!E12 -> 176 | F12: =SUM(B12:E12) -> 551
A13: CITRUS | B13: =December!B13-November!B13 -> 217 | C13: =December!C13-November!C13 -> -15 | D13: =December!D13-November!D13 -> 22 | E13: =December!E13-November!E13 -> 121 | F13: =SUM(B13:E13) -> 345
A14: CLAY | B14: =December!B14-November!B14 -> -348 | C14: =December!C14-November!C14 -> -151 | D14: =December!D14-November!D14 -> 13 | E14: =December!E14-November!E14 -> -78 | F14: =SUM(B14:E14) -> -564
A15: COLLIER | B15: =December!B15-November!B15 -> -171 | C15: =December!C15-November!C15 -> -231 | D15: =December!D15-November!D15 -> 7 | E15: =December!E15-November!E15 -> -210 | F15: =SUM(B15:E15) -> -605
A16: COLUMBIA | B16: =December!B16-November!B16 -> -190 | C16: =December!C16-November!C16 -> -169 | D16: =December!D16-November!D16 -> -1 | E16: =December!E16-November!E16 -> -106 | F16: =SUM(B16:E16) -> -466
... A71: WASHINGTON | B71: =December!B71-November!B71 -> -44 | C71: =December!C71-November!C71 -> -66 | D71: =December!D71-November!D71 -> 3 | E71: =December!E71-November!E71 -> 4 | F71: =SUM(B71:E71) -> -103
A72: TOTALS | B72: =SUM(B5:B71) -> -126 | C72: =SUM(C5:C71) -> -5028 | D72: =SUM(D5:D71) -> 2575 | E72: =SUM(E5:E71) -> 3089 | F72: =SUM(F5:F71) -> 510

Sheet Net-Year-to-Date Total
A1: Monthly Report - Net Activity by Party Affiliation - Year-to-Date Total
A2: Data comparison between 01/31/2018 - 12/31/2018
A3: ACTIVE REGISTERED VOTERS BY PARTY AFFILIATION BY COUNTY
A4: COUNTY | B4: REPUBLICAN PARTY OF FLORIDA | C4: FLORIDA DEMOCRATIC PARTY | D4: MINOR PARTY | E4: NO PARTY AFFILIATION | F4: TOTALS
A5: ALACHUA | B5: =NetJanToFeb!B5+NetFebToMar!B5+NetMarToApr!B5+NetAprToMay!B5+NetMayToJun!B5+NetJunToJul!B5+NetJulToAug!B5+NetAugToSep!B5+NetSepToOct!B5+NetOctToNov!B5+NetNovToDec!B5 -> 1602 | C5: =NetJanToFeb!C5+NetFebToMar!C5+NetMarToApr!C5+NetAprToMay!C5+NetMayToJun!C5+NetJunToJul!C5+NetJulToAug!C5+NetAugToSep!C5+NetSepToOct!C5+NetOctToNov!C5+NetNovToDec!C5 -> 5609 | D5: =NetJanToFeb!D5+NetFebToMar!D5+NetMarToApr!D5+NetAprToMay!D5+NetMayToJun!D5+NetJunToJul!D5+NetJulToAug!D5+NetAugToSep!D5+NetSepToOct!D5+NetOctToNov!D5+NetNovToDec!D5 -> 545 | E5: =NetJanToFeb!E5+NetFebToMar!E5+NetMarToApr!E5+NetAprToMay!E5+NetMayToJun!E5+NetJunToJul!E5+NetJulToAug!E5+NetAugToSep!E5+NetSepToOct!E5+NetOctToNov!E5+NetNovToDec!E5 -> 2926 | F5: =SUM(B5:E5) -> 10682
A6: BAKER | B6: =NetJanToFeb!B6+NetFebToMar!B6+NetMarToApr!B6+NetAprToMay!B6+NetMayToJun!B6+NetJunToJul!B6+NetJulToAug!B6+NetAugToSep!B6+NetSepToOct!B6+NetOctToNov!B6+NetNovToDec!B6 -> 563 | C6: =NetJanToFeb!C6+NetFebToMar!C6+NetMarToApr!C6+NetAprToMay!C6+NetMayToJun!C6+NetJunToJul!C6+NetJulToAug!C6+NetAugToSep!C6+NetSepToOct!C6+NetOctToNov!C6+NetNovToDec!C6 -> -485 | D6: =NetJanToFeb!D6+NetFebToMar!D6+NetMarToApr!D6+NetAprToMay!D6+NetMayToJun!D6+NetJunToJul!D6+NetJulToAug!D6+NetAugToSep!D6+NetSepToOct!D6+NetOctToNov!D6+NetNovToDec!D6 -> 19 | E6: =NetJanToFeb!E6+NetFebToMar!E6+NetMarToApr!E6+NetAprToMay!E6+NetMayToJun!E6+NetJunToJul!E6+NetJulToAug!E6+NetAugToSep!E6+NetSepToOct!E6+NetOctToNov!E6+NetNovToDec!E6 -> 28 | F6: =SUM(B6:E6) -> 125
A7: BAY | B7: =NetJanToFeb!B7+NetFebToMar!B7+NetMarToApr!B7+NetAprToMay!B7+NetMayToJun!B7+NetJunToJul!B7+NetJulToAug!B7+NetAugToSep!B7+NetSepToOct!B7+NetOctToNov!B7+NetNovToDec!B7 -> 2234 | C7: =NetJanToFeb!C7+NetFebToMar!C7+NetMarToApr!C7+NetAprToMay!C7+NetMayToJun!C7+NetJunToJul!C7+NetJulToAug!C7+NetAugToSep!C7+NetSepToOct!C7+NetOctToNov!C7+NetNovToDec!C7 -> 105 | D7: =NetJanToFeb!D7+NetFebToMar!D7+NetMarToApr!D7+NetAprToMay!D7+NetMayToJun!D7+NetJunToJul!D7+NetJulToAug!D7+NetAugToSep!D7+NetSepToOct!D7+NetOctToNov!D7+NetNovToDec!D7 -> 356 | E7: =NetJanToFeb!E7+NetFebToMar!E7+NetMarToApr!E7+NetAprToMay!E7+NetMayToJun!E7+NetJunToJul!E7+NetJulToAug!E7+NetAugToSep!E7+NetSepToOct!E7+NetOctToNov!E7+NetNovToDec!E7 -> 1002 | F7: =SUM(B7:E7) -> 3697
A8: BRADFORD | B8: =NetJanToFeb!B8+NetFebToMar!B8+NetMarToApr!B8+NetAprToMay!B8+NetMayToJun!B8+NetJunToJul!B8+NetJulToAug!B8+NetAugToSep!B8+NetSepToOct!B8+NetOctToNov!B8+NetNovToDec!B8 -> 517 | C8: =NetJanToFeb!C8+NetFebToMar!C8+NetMarToApr!C8+NetAprToMay!C8+NetMayToJun!C8+NetJunToJul!C8+NetJulToAug!C8+NetAugToSep!C8+NetSepToOct!C8+NetOctToNov!C8+NetNovToDec!C8 -> -249 | D8: =NetJanToFeb!D8+NetFebToMar!D8+NetMarToApr!D8+NetAprToMay!D8+NetMayToJun!D8+NetJunToJul!D8+NetJulToAug!D8+NetAugToSep!D8+NetSepToOct!D8+NetOctToNov!D8+NetNovToDec!D8 -> 25 | E8: =NetJanToFeb!E8+NetFebToMar!E8+NetMarToApr!E8+NetAprToMay!E8+NetMayToJun!E8+NetJunToJul!E8+NetJulToAug!E8+NetAugToSep!E8+NetSepToOct!E8+NetOctToNov!E8+NetNovToDec!E8 -> 96 | F8: =SUM(B8:E8) -> 389
A9: BREVARD | B9: =NetJanToFeb!B9+NetFebToMar!B9+NetMarToApr!B9+NetAprToMay!B9+NetMayToJun!B9+NetJunToJul!B9+NetJulToAug!B9+NetAugToSep!B9+NetSepToOct!B9+NetOctToNov!B9+NetNovToDec!B9 -> 7400 | C9: =NetJanToFeb!C9+NetFebToMar!C9+NetMarToApr!C9+NetAprToMay!C9+NetMayToJun!C9+NetJunToJul!C9+NetJulToAug!C9+NetAugToSep!C9+NetSepToOct!C9+NetOctToNov!C9+NetNovToDec!C9 -> 5078 | D9: =NetJanToFeb!D9+NetFebToMar!D9+NetMarToApr!D9+NetAprToMay!D9+NetMayToJun!D9+NetJunToJul!D9+NetJulToAug!D9+NetAugToSep!D9+NetSepToOct!D9+NetOctToNov!D9+NetNovToDec!D9 -> 1766 | E9: =NetJanToFeb!E9+NetFebToMar!E9+NetMarToApr!E9+NetAprToMay!E9+NetMayToJun!E9+NetJunToJul!E9+NetJulToAug!E9+NetAugToSep!E9+NetSepToOct!E9+NetOctToNov!E9+NetNovToDec!E9 -> 3826 | F9: =SUM(B9:E9) -> 18070
