Workbook

Sheet January
A1: Monthly Report - Voter Registration by Party Affiliation - January
A2: Data as of 01/31/2017
A3: ACTIVE REGISTERED VOTERS BY PARTY AFFILIATION BY COUNTY
A4: COUNTY | B4: REPUBLICAN PARTY OF FLORIDA | C4: FLORIDA DEMOCRATIC PARTY | D4: MINOR PARTY | E4: NO PARTY AFFILIATION | F4: TOTALS
A5: ALACHUA | B5: 50482 | C5: 85522 | D5: 4155 | E5: 39250 | F5: =SUM(B5:E5) -> 179409
A6: BAKER | B6: 7866 | C6: 5912 | D6: 185 | E6: 1477 | F6: =SUM(B6:E6) -> 15440
A7: BAY | B7: 61365 | C7: 31751 | D7: 920 | E7: 24797 | F7: =SUM(B7:E7) -> 118833
A8: BRADFORD | B8: 7252 | C8: 6279 | D8: 252 | E8: 2059 | F8: =SUM(B8:E8) -> 15842
A9: BREVARD | B9: 172254 | C9: 128671 | D9: 3005 | E9: 103464 | F9: =SUM(B9:E9) -> 407394
A10: BROWARD | B10: 258326 | C10: 603884 | D10: 18960 | E10: 312572 | F10: =SUM(B10:E10) -> 1193742
A11: CALHOUN | B11: 2300 | C11: 5399 | D11: 32 | E11: 906 | F11: =SUM(B11:E11) -> 8637
A12: CHARLOTTE | B12: 57169 | C12: 36328 | D12: 5462 | E12: 30968 | F12: =SUM(B12:E12) -> 129927
A13: CITRUS | B13: 49582 | C13: 30499 | D13: 691 | E13: 26011 | F13: =SUM(B13:E13) -> 106783
A14: CLAY | B14: 80100 | C14: 32030 | D14: 990 | E14: 33707 | F14: =SUM(B14:E14) -> 146827
A15: COLLIER | B15: 104770 | C15: 49002 | D15: 842 | E15: 52169 | F15: =SUM(B15:E15) -> 206783
A16: COLUMBIA | B16: 16769 | C16: 14543 | D16: 926 | E16: 5962 | F16: =SUM(B16:E16) -> 38200
... A71: WASHINGTON | B71: 7719 | C71: 5607 | D71: 233 | E71: 1846 | F71: =SUM(B71:E71) -> 15405
A72: TOTALS | B72: =SUM(B5:B71) -> 4576388 | C72: =SUM(C5:C71) -> 4900184 | D72: =SUM(D5:D71) -> 178073 | E72: =SUM(E5:E71) -> 3307007 | F72: =SUM(F5:F71) -> 12961652

Sheet February
A1: Monthly Report - Voter Registration by Party Affiliation - February
A2: Data as of 02/28/2017
A3: ACTIVE REGISTERED VOTERS BY PARTY AFFILIATION BY COUNTY
A4: COUNTY | B4: REPUBLICAN PARTY OF FLORIDA | C4: FLORIDA DEMOCRATIC PARTY | D4: MINOR PARTY | E4: NO PARTY AFFILIATION | F4: TOTALS
A5: ALACHUA | B5: 50620 | C5: 85627 | D5: 1501 | E5: 41863 | F5: =SUM(B5:E5) -> 179611
A6: BAKER | B6: 7929 | C6: 5894 | D6: 45 | E6: 1592 | F6: =SUM(B6:E6) -> 15460
A7: BAY | B7: 61075 | C7: 31567 | D7: 936 | E7: 24618 | F7: =SUM(B7:E7) -> 118196
A8: BRADFORD | B8: 7270 | C8: 6266 | D8: 108 | E8: 2223 | F8: =SUM(B8:E8) -> 15867
A9: BREVARD | B9: 172715 | C9: 128802 | D9: 3085 | E9: 103864 | F9: =SUM(B9:E9) -> 408466
A10: BROWARD | B10: 257461 | C10: 601369 | D10: 5629 | E10: 324967 | F10: =SUM(B10:E10) -> 1189426
A11: CALHOUN | B11: 2314 | C11: 5351 | D11: 32 | E11: 904 | F11: =SUM(B11:E11) -> 8601
A12: CHARLOTTE | B12: 57795 | C12: 36632 | D12: 1102 | E12: 34843 | F12: =SUM(B12:E12) -> 130372
A13: CITRUS | B13: 49866 | C13: 30572 | D13: 707 | E13: 26027 | F13: =SUM(B13:E13) -> 107172
A14: CLAY | B14: 80218 | C14: 32145 | D14: 1018 | E14: 33757 | F14: =SUM(B14:E14) -> 147138
A15: COLLIER | B15: 105054 | C15: 49116 | D15: 857 | E15: 51991 | F15: =SUM(B15:E15) -> 207018
A16: COLUMBIA | B16: 16864 | C16: 14518 | D16: 223 | E16: 6634 | F16: =SUM(B16:E16) -> 38239
... A71: WASHINGTON | B71: 7742 | C71: 5589 | D71: 196 | E71: 1896 | F71: =SUM(B71:E71) -> 15423
A72: TOTALS | B72: =SUM(B5:B71) -> 4572462 | C72: =SUM(C5:C71) -> 4882964 | D72: =SUM(D5:D71) -> 86454 | E72: =SUM(E5:E71) -> 3383543 | F72: =SUM(F5:F71) -> 12925423

Sheet March
A1: Monthly Report - Voter Registration by Party Affiliation - March
A2: Data as of 03/31/2017
A3: ACTIVE REGISTERED VOTERS BY PARTY AFFILIATION BY COUNTY
A4: COUNTY | B4: REPUBLICAN PARTY OF FLORIDA | C4: FLORIDA DEMOCRATIC PARTY | D4: MINOR PARTY | E4: NO PARTY AFFILIATION | F4: TOTALS
A5: ALACHUA | B5: 50679 | C5: 85689 | D5: 1520 | E5: 41952 | F5: =SUM(B5:E5) -> 179840
A6: BAKER | B6: 7956 | C6: 5889 | D6: 46 | E6: 1595 | F6: =SUM(B6:E6) -> 15486
A7: BAY | B7: 60368 | C7: 31129 | D7: 940 | E7: 24108 | F7: =SUM(B7:E7) -> 116545
A8: BRADFORD | B8: 7298 | C8: 6268 | D8: 110 | E8: 2237 | F8: =SUM(B8:E8) -> 15913
A9: BREVARD | B9: 172706 | C9: 128678 | D9: 3183 | E9: 103922 | F9: =SUM(B9:E9) -> 408489
A10: BROWARD | B10: 256882 | C10: 599073 | D10: 5758 | E10: 323439 | F10: =SUM(B10:E10) -> 1185152
A11: CALHOUN | B11: 2315 | C11: 5332 | D11: 31 | E11: 909 | F11: =SUM(B11:E11) -> 8587
A12: CHARLOTTE | B12: 58029 | C12: 36674 | D12: 1120 | E12: 34902 | F12: =SUM(B12:E12) -> 130725
A13: CITRUS | B13: 49925 | C13: 30489 | D13: 717 | E13: 25980 | F13: =SUM(B13:E13) -> 107111
A14: CLAY | B14: 80253 | C14: 32263 | D14: 1046 | E14: 33865 | F14: =SUM(B14:E14) -> 147427
A15: COLLIER | B15: 105082 | C15: 49069 | D15: 864 | E15: 51983 | F15: =SUM(B15:E15) -> 206998
A16: COLUMBIA | B16: 16891 | C16: 14442 | D16: 228 | E16: 6584 | F16: =SUM(B16:E16) -> 38145
... A71: WASHINGTON | B71: 7781 | C71: 5584 | D71: 48 | E71: 2059 | F71: =SUM(B71:E71) -> 15472
A72: TOTALS | B72: =SUM(B5:B71) -> 4569664 | C72: =SUM(C5:C71) -> 4868240 | D72: =SUM(D5:D71) -> 86844 | E72: =SUM(E5:E71) -> 3375151 | F72: =SUM(F5:F71) -> 12899899

Sheet April
A1: Monthly Report - Voter Registration by Party Affiliation - April
A2: Data as of 04/30/2017
A3: ACTIVE REGISTERED VOTERS BY PARTY AFFILIATION BY COUNTY
A4: COUNTY | B4: REPUBLICAN PARTY OF FLORIDA | C4: FLORIDA DEMOCRATIC PARTY | D4: MINOR PARTY | E4: NO PARTY AFFILIATION | F4: TOTALS
A5: ALACHUA | B5: 50633 | C5: 85567 | D5: 1498 | E5: 41981 | F5: =SUM(B5:E5) -> 179679
A6: BAKER | B6: 7973 | C6: 5882 | D6: 46 | E6: 1601 | F6: =SUM(B6:E6) -> 15502
A7: BAY | B7: 60393 | C7: 31052 | D7: 956 | E7: 24182 | F7: =SUM(B7:E7) -> 116583
A8: BRADFORD | B8: 7308 | C8: 6261 | D8: 113 | E8: 2252 | F8: =SUM(B8:E8) -> 15934
A9: BREVARD | B9: 171850 | C9: 127932 | D9: 1799 | E9: 104691 | F9: =SUM(B9:E9) -> 406272
A10: BROWARD | B10: 256561 | C10: 597626 | D10: 5878 | E10: 323041 | F10: =SUM(B10:E10) -> 1183106
A11: CALHOUN | B11: 2327 | C11: 5320 | D11: 18 | E11: 923 | F11: =SUM(B11:E11) -> 8588
A12: CHARLOTTE | B12: 58215 | C12: 36752 | D12: 389 | E12: 35650 | F12: =SUM(B12:E12) -> 131006
A13: CITRUS | B13: 49722 | C13: 30129 | D13: 359 | E13: 26083 | F13: =SUM(B13:E13) -> 106293
A14: CLAY | B14: 80337 | C14: 32312 | D14: 549 | E14: 34498 | F14: =SUM(B14:E14) -> 147696
A15: COLLIER | B15: 102449 | C15: 46418 | D15: 547 | E15: 48612 | F15: =SUM(B15:E15) -> 198026
A16: COLUMBIA | B16: 16926 | C16: 14409 | D16: 157 | E16: 6613 | F16: =SUM(B16:E16) -> 38105
... A71: WASHINGTON | B71: 7751 | C71: 5560 | D71: 49 | E71: 2060 | F71: =SUM(B71:E71) -> 15420
A72: TOTALS | B72: =SUM(B5:B71) -> 4565267 | C72: =SUM(C5:C71) -> 4858172 | D72: =SUM(D5:D71) -> 51733 | E72: =SUM(E5:E71) -> 3407949 | F72: =SUM(F5:F71) -> 12883121

Sheet May
A1: Monthly Report - Voter Registration by Party Affiliation - May
A2: Data as of 05/31/2017
A3: ACTIVE REGISTERED VOTERS BY PARTY AFFILIATION BY COUNTY
A4: COUNTY | B4: REPUBLICAN PARTY OF FLORIDA | C4: FLORIDA DEMOCRATIC PARTY | D4: MINOR PARTY | E4: NO PARTY AFFILIATION | F4: TOTALS
A5: ALACHUA | B5: 50672 | C5: 85581 | D5: 1076 | E5: 42520 | F5: =SUM(B5:E5) -> 179849
A6: BAKER | B6: 7880 | C6: 5826 | D6: 44 | E6: 1580 | F6: =SUM(B6:E6) -> 15330
A7: BAY | B7: 59708 | C7: 30461 | D7: 642 | E7: 23905 | F7: =SUM(B7:E7) -> 114716
A8: BRADFORD | B8: 7335 | C8: 6255 | D8: 58 | E8: 2318 | F8: =SUM(B8:E8) -> 15966
A9: BREVARD | B9: 172239 | C9: 128000 | D9: 1921 | E9: 105087 | F9: =SUM(B9:E9) -> 407247
A10: BROWARD | B10: 256436 | C10: 597459 | D10: 2660 | E10: 326554 | F10: =SUM(B10:E10) -> 1183109
A11: CALHOUN | B11: 2329 | C11: 5316 | D11: 19 | E11: 921 | F11: =SUM(B11:E11) -> 8585
A12: CHARLOTTE | B12: 58039 | C12: 36612 | D12: 413 | E12: 35469 | F12: =SUM(B12:E12) -> 130533
A13: CITRUS | B13: 49580 | C13: 29900 | D13: 377 | E13: 25865 | F13: =SUM(B13:E13) -> 105722
A14: CLAY | B14: 80393 | C14: 32354 | D14: 596 | E14: 34590 | F14: =SUM(B14:E14) -> 147933
A15: COLLIER | B15: 102809 | C15: 46623 | D15: 566 | E15: 48901 | F15: =SUM(B15:E15) -> 198899
A16: COLUMBIA | B16: 16943 | C16: 14390 | D16: 164 | E16: 6612 | F16: =SUM(B16:E16) -> 38109
... A71: WASHINGTON | B71: 7782 | C71: 5540 | D71: 51 | E71: 2079 | F71: =SUM(B71:E71) -> 15452
A72: TOTALS | B72: =SUM(B5:B71) -> 4564470 | C72: =SUM(C5:C71) -> 4852277 | D72: =SUM(D5:D71) -> 45222 | E72: =SUM(E5:E71) -> 3418998 | F72: =SUM(F5:F71) -> 12880967

Sheet June
A1: Monthly Report - Voter Registration by Party Affiliation - June
A2: Data as of 06/30/2017
A3: ACTIVE REGISTERED VOTERS BY PARTY AFFILIATION BY COUNTY
A4: COUNTY | B4: REPUBLICAN PARTY OF FLORIDA | C4: FLORIDA DEMOCRATIC PARTY | D4: MINOR PARTY | E4: NO PARTY AFFILIATION | F4: TOTALS
A5: ALACHUA | B5: 48440 | C5: 81427 | D5: 1043 | E5: 39148 | F5: =SUM(B5:E5) -> 170058
A6: BAKER | B6: 7859 | C6: 5801 | D6: 44 | E6: 1589 | F6: =SUM(B6:E6) -> 15293
A7: BAY | B7: 59856 | C7: 30489 | D7: 661 | E7: 24085 | F7: =SUM(B7:E7) -> 115091
A8: BRADFORD | B8: 7313 | C8: 6211 | D8: 58 | E8: 2300 | F8: =SUM(B8:E8) -> 15882
A9: BREVARD | B9: 172721 | C9: 128262 | D9: 2074 | E9: 105769 | F9: =SUM(B9:E9) -> 408826
A10: BROWARD | B10: 255173 | C10: 594835 | D10: 2874 | E10: 325556 | F10: =SUM(B10:E10) -> 1178438
A11: CALHOUN | B11: 2334 | C11: 5313 | D11: 20 | E11: 928 | F11: =SUM(B11:E11) -> 8595
A12: CHARLOTTE | B12: 58238 | C12: 36692 | D12: 461 | E12: 35644 | F12: =SUM(B12:E12) -> 131035
A13: CITRUS | B13: 49806 | C13: 29951 | D13: 397 | E13: 26073 | F13: =SUM(B13:E13) -> 106227
A14: CLAY | B14: 80703 | C14: 32572 | D14: 645 | E14: 34795 | F14: =SUM(B14:E14) -> 148715
A15: COLLIER | B15: 103159 | C15: 46922 | D15: 591 | E15: 49312 | F15: =SUM(B15:E15) -> 199984
A16: COLUMBIA | B16: 17008 | C16: 14407 | D16: 174 | E16: 6654 | F16: =SUM(B16:E16) -> 38243
... A71: WASHINGTON | B71: 7799 | C71: 5541 | D71: 52 | E71: 2095 | F71: =SUM(B71:E71) -> 15487
A72: TOTALS | B72: =SUM(B5:B71) -> 4561787 | C72: =SUM(C5:C71) -> 4842064 | D72: =SUM(D5:D71) -> 47597 | E72: =SUM(E5:E71) -> 3419055 | F72: =SUM(F5:F71) -> 12870503

Sheet July
A1: Monthly Report - Voter Registration by Party Affiliation - July
A2: Data as of 07/31/2017
A3: ACTIVE REGISTERED VOTERS BY PARTY AFFILIATION BY COUNTY
A4: COUNTY | B4: REPUBLICAN PARTY OF FLORIDA | C4: FLORIDA DEMOCRATIC PARTY | D4: MINOR PARTY | E4: NO PARTY AFFILIATION | F4: TOTALS
A5: ALACHUA | B5: 48491 | C5: 81491 | D5: 1080 | E5: 39337 | F5: =SUM(B5:E5) -> 170399
A6: BAKER | B6: 7851 | C6: 5767 | D6: 46 | E6: 1583 | F6: =SUM(B6:E6) -> 15247
A7: BAY | B7: 60036 | C7: 30496 | D7: 680 | E7: 24251 | F7: =SUM(B7:E7) -> 115463
A8: BRADFORD | B8: 7343 | C8: 6193 | D8: 59 | E8: 2312 | F8: =SUM(B8:E8) -> 15907
A9: BREVARD | B9: 172736 | C9: 128057 | D9: 2248 | E9: 106126 | F9: =SUM(B9:E9) -> 409167
A10: BROWARD | B10: 255012 | C10: 595533 | D10: 3116 | E10: 326284 | F10: =SUM(B10:E10) -> 1179945
A11: CALHOUN | B11: 2334 | C11: 5302 | D11: 21 | E11: 928 | F11: =SUM(B11:E11) -> 8585
A12: CHARLOTTE | B12: 58372 | C12: 36739 | D12: 501 | E12: 35776 | F12: =SUM(B12:E12) -> 131388
A13: CITRUS | B13: 49993 | C13: 29923 | D13: 418 | E13: 26179 | F13: =SUM(B13:E13) -> 106513
A14: CLAY | B14: 80572 | C14: 32473 | D14: 689 | E14: 34763 | F14: =SUM(B14:E14) -> 148497
A15: COLLIER | B15: 103511 | C15: 47102 | D15: 620 | E15: 49711 | F15: =SUM(B15:E15) -> 200944
A16: COLUMBIA | B16: 17065 | C16: 14408 | D16: 184 | E16: 6694 | F16: =SUM(B16:E16) -> 38351
... A71: WASHINGTON | B71: 7824 | C71: 5540 | D71: 52 | E71: 2108 | F71: =SUM(B71:E71) -> 15524
A72: TOTALS | B72: =SUM(B5:B71) -> 4548354 | C72: =SUM(C5:C71) -> 4825859 | D72: =SUM(D5:D71) -> 50747 | E72: =SUM(E5:E71) -> 3411869 | F72: =SUM(F5:F71) -> 12836829

Sheet August
A1: Monthly Report - Voter Registration by Party Affiliation - August
A2: Data as of 08/31/2017
A3: ACTIVE REGISTERED VOTERS BY PARTY AFFILIATION BY COUNTY
A4: COUNTY | B4: REPUBLICAN PARTY OF FLORIDA | C4: FLORIDA DEMOCRATIC PARTY | D4: MINOR PARTY | E4: NO PARTY AFFILIATION | F4: TOTALS
A5: ALACHUA | B5: 48645 | C5: 81698 | D5: 1109 | E5: 39630 | F5: =SUM(B5:E5) -> 171082
A6: BAKER | B6: 7862 | C6: 5750 | D6: 47 | E6: 1582 | F6: =SUM(B6:E6) -> 15241
A7: BAY | B7: 60008 | C7: 30391 | D7: 704 | E7: 24244 | F7: =SUM(B7:E7) -> 115347
A8: BRADFORD | B8: 7372 | C8: 6191 | D8: 61 | E8: 2331 | F8: =SUM(B8:E8) -> 15955
A9: BREVARD | B9: 172217 | C9: 127612 | D9: 2410 | E9: 106159 | F9: =SUM(B9:E9) -> 408398
A10: BROWARD | B10: 254773 | C10: 595323 | D10: 3269 | E10: 327004 | F10: =SUM(B10:E10) -> 1180369
A11: CALHOUN | B11: 2343 | C11: 5296 | D11: 21 | E11: 929 | F11: =SUM(B11:E11) -> 8589
A12: CHARLOTTE | B12: 58599 | C12: 36774 | D12: 539 | E12: 35955 | F12: =SUM(B12:E12) -> 131867
A13: CITRUS | B13: 50156 | C13: 29944 | D13: 463 | E13: 26259 | F13: =SUM(B13:E13) -> 106822
A14: CLAY | B14: 80531 | C14: 32516 | D14: 738 | E14: 34835 | F14: =SUM(B14:E14) -> 148620
A15: COLLIER | B15: 103477 | C15: 47176 | D15: 646 | E15: 49916 | F15: =SUM(B15:E15) -> 201215
A16: COLUMBIA | B16: 17119 | C16: 14422 | D16: 190 | E16: 6720 | F16: =SUM(B16:E16) -> 38451
... A71: WASHINGTON | B71: 7842 | C71: 5523 | D71: 55 | E71: 2116 | F71: =SUM(B71:E71) -> 15536
A72: TOTALS | B72: =SUM(B5:B71) -> 4547933 | C72: =SUM(C5:C71) -> 4823263 | D72: =SUM(D5:D71) -> 53680 | E72: =SUM(E5:E71) -> 3420210 | F72: =SUM(F5:F71) -> 12845086

Sheet September
A1: Monthly Report - Voter Registration by Party Affiliation - September
A2: Data as of 09/30/2017
A3: ACTIVE REGISTERED VOTERS BY PARTY AFFILIATION BY COUNTY
A4: COUNTY | B4: REPUBLICAN PARTY OF FLORIDA | C4: FLORIDA DEMOCRATIC PARTY | D4: MINOR PARTY | E4: NO PARTY AFFILIATION | F4: TOTALS
A5: ALACHUA | B5: 48717 | C5: 81782 | D5: 1142 | E5: 39812 | F5: =SUM(B5:E5) -> 171453
A6: BAKER | B6: 7877 | C6: 5745 | D6: 47 | E6: 1590 | F6: =SUM(B6:E6) -> 15259
A7: BAY | B7: 60139 | C7: 30404 | D7: 728 | E7: 24392 | F7: =SUM(B7:E7) -> 115663
A8: BRADFORD | B8: 7399 | C8: 6182 | D8: 64 | E8: 2346 | F8: =SUM(B8:E8) -> 15991
A9: BREVARD | B9: 172403 | C9: 127702 | D9: 2573 | E9: 106623 | F9: =SUM(B9:E9) -> 409301
A10: BROWARD | B10: 253270 | C10: 592271 | D10: 3622 | E10: 326411 | F10: =SUM(B10:E10) -> 1175574
A11: CALHOUN | B11: 2369 | C11: 5286 | D11: 21 | E11: 932 | F11: =SUM(B11:E11) -> 8608
A12: CHARLOTTE | B12: 58727 | C12: 36823 | D12: 578 | E12: 36073 | F12: =SUM(B12:E12) -> 132201
A13: CITRUS | B13: 50282 | C13: 29944 | D13: 513 | E13: 26348 | F13: =SUM(B13:E13) -> 107087
A14: CLAY | B14: 80425 | C14: 32477 | D14: 771 | E14: 34821 | F14: =SUM(B14:E14) -> 148494
A15: COLLIER | B15: 102631 | C15: 46814 | D15: 678 | E15: 49639 | F15: =SUM(B15:E15) -> 199762
A16: COLUMBIA | B16: 17184 | C16: 14405 | D16: 196 | E16: 6774 | F16: =SUM(B16:E16) -> 38559
... A71: WASHINGTON | B71: 7871 | C71: 5503 | D71: 56 | E71: 2129 | F71: =SUM(B71:E71) -> 15559
A72: TOTALS | B72: =SUM(B5:B71) -> 4540034 | C72: =SUM(C5:C71) -> 4806071 | D72: =SUM(D5:D71) -> 56926 | E72: =SUM(E5:E71) -> 3417193 | F72: =SUM(F5:F71) -> 12820224

Sheet October
A1: Monthly Report - Voter Registration by Party Affiliation - October
A2: Data as of 10/31/2017
A3: ACTIVE REGISTERED VOTERS BY PARTY AFFILIATION BY COUNTY
A4: COUNTY | B4: REPUBLICAN PARTY OF FLORIDA | C4: FLORIDA DEMOCRATIC PARTY | D4: MINOR PARTY | E4: NO PARTY AFFILIATION | F4: TOTALS
A5: ALACHUA | B5: 48809 | C5: 81997 | D5: 1156 | E5: 40036 | F5: =SUM(B5:E5) -> 171998
A6: BAKER | B6: 7882 | C6: 5748 | D6: 49 | E6: 1597 | F6: =SUM(B6:E6) -> 15276
A7: BAY | B7: 60292 | C7: 30445 | D7: 746 | E7: 24496 | F7: =SUM(B7:E7) -> 115979
A8: BRADFORD | B8: 7413 | C8: 6184 | D8: 65 | E8: 2359 | F8: =SUM(B8:E8) -> 16021
A9: BREVARD | B9: 172599 | C9: 127764 | D9: 2694 | E9: 107018 | F9: =SUM(B9:E9) -> 410075
A10: BROWARD | B10: 253430 | C10: 592932 | D10: 3873 | E10: 327793 | F10: =SUM(B10:E10) -> 1178028
A11: CALHOUN | B11: 2379 | C11: 5285 | D11: 22 | E11: 941 | F11: =SUM(B11:E11) -> 8627
A12: CHARLOTTE | B12: 59002 | C12: 36958 | D12: 624 | E12: 36291 | F12: =SUM(B12:E12) -> 132875
A13: CITRUS | B13: 50458 | C13: 29974 | D13: 537 | E13: 26479 | F13: =SUM(B13:E13) -> 107448
A14: CLAY | B14: 80534 | C14: 32571 | D14: 805 | E14: 35016 | F14: =SUM(B14:E14) -> 148926
A15: COLLIER | B15: 102859 | C15: 46932 | D15: 723 | E15: 49929 | F15: =SUM(B15:E15) -> 200443
A16: COLUMBIA | B16: 17238 | C16: 14406 | D16: 203 | E16: 6817 | F16: =SUM(B16:E16) -> 38664
... A71: WASHINGTON | B71: 7884 | C71: 5499 | D71: 56 | E71: 2141 | F71: =SUM(B71:E71) -> 15580
A72: TOTALS | B72: =SUM(B5:B71) -> 4548627 | C72: =SUM(C5:C71) -> 4814215 | D72: =SUM(D5:D71) -> 59682 | E72: =SUM(E5:E71) -> 3435109 | F72: =SUM(F5:F71) -> 12857633

Sheet November
A1: Monthly Report - Voter Registration by Party Affiliation - November
A2: Data as of 11/30/2017
A3: ACTIVE REGISTERED VOTERS BY PARTY AFFILIATION BY COUNTY
A4: COUNTY | B4: REPUBLICAN PARTY OF FLORIDA | C4: FLORIDA DEMOCRATIC PARTY | D4: MINOR PARTY | E4: NO PARTY AFFILIATION | F4: TOTALS
A5: ALACHUA | B5: 48851 | C5: 82119 | D5: 1178 | E5: 40231 | F5: =SUM(B5:E5) -> 172379
A6: BAKER | B6: 7887 | C6: 5735 | D6: 50 | E6: 1607 | F6: =SUM(B6:E6) -> 15279
A7: BAY | B7: 60368 | C7: 30454 | D7: 772 | E7: 24649 | F7: =SUM(B7:E7) -> 116243
A8: BRADFORD | B8: 7430 | C8: 6190 | D8: 68 | E8: 2367 | F8: =SUM(B8:E8) -> 16055
A9: BREVARD | B9: 171628 | C9: 126447 | D9: 2842 | E9: 106067 | F9: =SUM(B9:E9) -> 406984
A10: BROWARD | B10: 253415 | C10: 593131 | D10: 4109 | E10: 329067 | F10: =SUM(B10:E10) -> 1179722
A11: CALHOUN | B11: 2385 | C11: 5272 | D11: 24 | E11: 951 | F11: =SUM(B11:E11) -> 8632
A12: CHARLOTTE | B12: 59214 | C12: 37041 | D12: 687 | E12: 36495 | F12: =SUM(B12:E12) -> 133437
A13: CITRUS | B13: 50056 | C13: 29682 | D13: 561 | E13: 26275 | F13: =SUM(B13:E13) -> 106574
A14: CLAY | B14: 80540 | C14: 32621 | D14: 848 | E14: 35049 | F14: =SUM(B14:E14) -> 149058
A15: COLLIER | B15: 102364 | C15: 46601 | D15: 753 | E15: 49692 | F15: =SUM(B15:E15) -> 199410
A16: COLUMBIA | B16: 17266 | C16: 14410 | D16: 209 | E16: 6868 | F16: =SUM(B16:E16) -> 38753
... A71: WASHINGTON | B71: 7899 | C71: 5493 | D71: 58 | E71: 2146 | F71: =SUM(B71:E71) -> 15596
A72: TOTALS | B72: =SUM(B5:B71) -> 4550146 | C72: =SUM(C5:C71) -> 4815749 | D72: =SUM(D5:D71) -> 62675 | E72: =SUM(E5:E71) -> 3447811 | F72: =SUM(F5:F71) -> 12876381

Sheet December
A1: Monthly Report - Voter Registration by Party Affiliation - December
A2: Data as of 12/31/2017
A3: ACTIVE REGISTERED VOTERS BY PARTY AFFILIATION BY COUNTY
A4: COUNTY | B4: REPUBLICAN PARTY OF FLORIDA | C4: FLORIDA DEMOCRATIC PARTY | D4: MINOR PARTY | E4: NO PARTY AFFILIATION | F4: TOTALS
A5: ALACHUA | B5: 48875 | C5: 82204 | D5: 1198 | E5: 40387 | F5: =SUM(B5:E5) -> 172664
A6: BAKER | B6: 7913 | C6: 5725 | D6: 50 | E6: 1613 | F6: =SUM(B6:E6) -> 15301
A7: BAY | B7: 60493 | C7: 30458 | D7: 804 | E7: 24756 | F7: =SUM(B7:E7) -> 116511
A8: BRADFORD | B8: 7446 | C8: 6185 | D8: 68 | E8: 2381 | F8: =SUM(B8:E8) -> 16080
A9: BREVARD | B9: 171942 | C9: 126602 | D9: 3000 | E9: 106557 | F9: =SUM(B9:E9) -> 408101
A10: BROWARD | B10: 253589 | C10: 593644 | D10: 4399 | E10: 330135 | F10: =SUM(B10:E10) -> 1181767
A11: CALHOUN | B11: 2393 | C11: 5256 | D11: 25 | E11: 948 | F11: =SUM(B11:E11) -> 8622
A12: CHARLOTTE | B12: 57904 | C12: 35773 | D12: 729 | E12: 34763 | F12: =SUM(B12:E12) -> 129169
A13: CITRUS | B13: 49336 | C13: 29187 | D13: 592 | E13: 25854 | F13: =SUM(B13:E13) -> 104969
A14: CLAY | B14: 80561 | C14: 32691 | D14: 881 | E14: 35107 | F14: =SUM(B14:E14) -> 149240
A15: COLLIER | B15: 102913 | C15: 46848 | D15: 789 | E15: 50133 | F15: =SUM(B15:E15) -> 200683
A16: COLUMBIA | B16: 17311 | C16: 14412 | D16: 214 | E16: 6908 | F16: =SUM(B16:E16) -> 38845
... A71: WASHINGTON | B71: 7909 | C71: 5478 | D71: 59 | E71: 2161 | F71: =SUM(B71:E71) -> 15607
A72: TOTALS | B72: =SUM(B5:B71) -> 4544708 | C72: =SUM(C5:C71) -> 4807950 | D72: =SUM(D5:D71) -> 65526 | E72: =SUM(E5:E71) -> 3449005 | F72: =SUM(F5:F71) -> 12867189

Sheet NetJanToFeb
A1: Monthly Report - Net Activity by Party Affiliation - January to February
A2: Data comparison between 01/31/2017 - 02/28/2017
A3: ACTIVE REGISTERED VOTERS BY PARTY AFFILIATION BY COUNTY
A4: COUNTY | B4: REPUBLICAN PARTY OF FLORIDA | C4: FLORIDA DEMOCRATIC PARTY | D4: MINOR PARTY | E4: NO PARTY AFFILIATION | F4: TOTALS
A5: ALACHUA | B5: =February!B5-January!B5 -> 138 | C5: =February!C5-January!C5 -> 105 | D5: =February!D5-January!D5 -> -2654 | E5: =February!E5-January!E5 -> 2613 | F5: =SUM(B5:E5) -> 202
A6: BAKER | B6: =February!B6-January!B6 -> 63 | C6: =February!C6-January!C6 -> -18 | D6: =February!D6-January!D6 -> -140 | E6: =February!E6-January!E6 -> 115 | F6: =SUM(B6:E6) -> 20
A7: BAY | B7: =February!B7-January!B7 -> -290 | C7: =February!C7-January!C7 -> -184 | D7: =February!D7-January!D7 -> 16 | E7: =February!E7-January!E7 -> -179 | F7: =SUM(B7:E7) -> -637
A8: BRADFORD | B8: =February!B8-January!B8 -> 18 | C8: =February!C8-January!C8 -> -13 | D8: =February!D8-January!D8 -> -144 | E8: =February!E8-January!E8 -> 164 | F8: =SUM(B8:E8) -> 25
A9: BREVARD | B9: =February!B9-January!B9 -> 461 | C9: =February!C9-January!C9 -> 131 | D9: =February!D9-January!D9 -> 80 | E9: =February!E9-January!E9 -> 400 | F9: =SUM(B9:E9) -> 1072
A10: BROWARD | B10: =February!B10-January!B10 -> -865 | C10: =February!C10-January!C10 -> -2515 | D10: =February!D10-January!D10 -> -13331 | E10: =February!E10-January!E10 -> 12395 | F10: =SUM(B10:E10) -> -4316
A11: CALHOUN | B11: =February!B11-January!B11 -> 14 | C11: =February!C11-January!C11 -> -48 | D11: =February!D11-January!D11 -> 0 | E11: =February!E11-January!E11 -> -2 | F11: =SUM(B11:E11) -> -36
A12: CHARLOTTE | B12: =February!B12-January!B12 -> 626 | C12: =February!C12-January!C12 -> 304 | D12: =February!D12-January!D12 -> -4360 | E12: =February!E12-January!E12 -> 3875 | F12: =SUM(B12:E12) -> 445
A13: CITRUS | B13: =February!B13-January!B13 -> 284 | C13: =February!C13-January!C13 -> 73 | D13: =February!D13-January!D13 -> 16 | E13: =February!E13-January!E13 -> 16 | F13: =SUM(B13:E13) -> 389
A14: CLAY | B14: =February!B14-January!B14 -> 118 | C14: =February!C14-January!C14 -> 115 | D14: =February!D14-January!D14 -> 28 | E14: =February!E14-January!E14 -> 50 | F14: =SUM(B14:E14) -> 311
A15: COLLIER | B15: =February!B15-January!B15 -> 284 | C15: =February!C15-January!C15 -> 114 | D15: =February!D15-January!D15 -> 15 | E15: =February!E15-January!E15 -> -178 | F15: =SUM(B15:E15) -> 235
A16: COLUMBIA | B16: =February!B16-January!B16 -> 95 | C16: =February!C16-January!C16 -> -25 | D16: =February!D16-January!D16 -> -703 | E16: =February!E16-January!E16 -> 672 | F16: =SUM(B16:E16) -> 39
... A71: WASHINGTON | B71: =February!B71-January!B71 -> 23 | C71: =February!C71-January!C71 -> -18 | D71: =February!D71-January!D71 -> -37 | E71: =February!E71-January!E71 -> 50 | F71: =SUM(B71:E71) -> 18
A72: TOTALS | B72: =SUM(B5:B71) -> -3926 | C72: =SUM(C5:C71) -> -17220 | D72: =SUM(D5:D71) -> -91619 | E72: =SUM(E5:E71) -> 76536 | F72: =SUM(F5:F71) -> -36229

Sheet NetFebToMar
A1: Monthly Report - Net Activity by Party Affiliation - Feburary to March
A2: Data comparison between 02/28/2017 - 03/31/2017
A3: ACTIVE REGISTERED VOTERS BY PARTY AFFILIATION BY COUNTY
A4: COUNTY | B4: REPUBLICAN PARTY OF FLORIDA | C4: FLORIDA DEMOCRATIC PARTY | D4: MINOR PARTY | E4: NO PARTY AFFILIATION | F4: TOTALS
A5: ALACHUA | B5: =March!B5-February!B5 -> 59 | C5: =March!C5-February!C5 -> 62 | D5: =March!D5-February!D5 -> 19 | E5: =March!E5-February!E5 -> 89 | F5: =SUM(B5:E5) -> 229
A6: BAKER | B6: =March!B6-February!B6 -> 27 | C6: =March!C6-February!C6 -> -5 | D6: =March!D6-February!D6 -> 1 | E6: =March!E6-February!E6 -> 3 | F6: =SUM(B6:E6) -> 26
A7: BAY | B7: =March!B7-February!B7 -> -707 | C7: =March!C7-February!C7 -> -438 | D7: =March!D7-February!D7 -> 4 | E7: =March!E7-February!E7 -> -510 | F7: =SUM(B7:E7) -> -1651
A8: BRADFORD | B8: =March!B8-February!B8 -> 28 | C8: =March!C8-February!C8 -> 2 | D8: =March!D8-February!D8 -> 2 | E8: =March!E8-February!E8 -> 14 | F8: =SUM(B8:E8) -> 46
A9: BREVARD | B9: =March!B9-February!B9 -> -9 | C9: =March!C9-February!C9 -> -124 | D9: =March!D9-February!D9 -> 98 | E9: =March!E9-February!E9 -> 58 | F9: =SUM(B9:E9) -> 23
A10: BROWARD | B10: =March!B10-February!B10 -> -579 | C10: =March!C10-February!C10 -> -2296 | D10: =March!D10-February!D10 -> 129 | E10: =March!E10-February!E10 -> -1528 | F10: =SUM(B10:E10) -> -4274
A11: CALHOUN | B11: =March!B11-February!B11 -> 1 | C11: =March!C11-February!C11 -> -19 | D11: =March!D11-February!D11 -> -1 | E11: =March!E11-February!E11 -> 5 | F11: =SUM(B11:E11) -> -14
A12: CHARLOTTE | B12: =March!B12-February!B12 -> 234 | C12: =March!C12-February!C12 -> 42 | D12: =March!D12-February!D12 -> 18 | E12: =March!E12-February!E12 -> 59 | F12: =SUM(B12:E12) -> 353
A13: CITRUS | B13: =March!B13-February!B13 -> 59 | C13: =March!C13-February!C13 -> -83 | D13: =March!D13-February!D13 -> 10 | E13: =March!E13-February!E13 -> -47 | F13: =SUM(B13:E13) -> -61
A14: CLAY | B14: =March!B14-February!B14 -> 35 | C14: =March!C14-February!C14 -> 118 | D14: =March!D14-February!D14 -> 28 | E14: =March!E14-February!E14 -> 108 | F14: =SUM(B14:E14) -> 289
A15: COLLIER | B15: =March!B15-February!B15 -> 28 | C15: =March!C15-February!C15 -> -47 | D15: =March!D15-February!D15 -> 7 | E15: =March!E15-February!E15 -> -8 | F15: =SUM(B15:E15) -> -20
A16: COLUMBIA | B16: =March!B16-February!B16 -> 27 | C16: =March!C16-February!C16 -> -76 | D16: =March!D16-February!D16 -> 5 | E16: =March!E16-February!E16 -> -50 | F16: =SUM(B16:E16) -> -94
... A71: WASHINGTON | B71: =March!B71-February!B71 -> 39 | C71: =March!C71-February!C71 -> -5 | D71: =March!D71-February!D71 -> -148 | E71: =March!E71-February!E71 -> 163 | F71: =SUM(B71:E71) -> 49
A72: TOTALS | B72: =SUM(B5:B71) -> -2798 | C72: =SUM(C5:C71) -> -14724 | D72: =SUM(D5:D71) -> 390 | E72: =SUM(E5:E71) -> -8392 | F72: =SUM(F5:F71) -> -25524

Sheet NetMarToApr
A1: Monthly Report - Net Activity by Party Affiliation - March to April
A2: Data comparison between 03/31/2017 - 04/30/2017
A3: ACTIVE REGISTERED VOTERS BY PARTY AFFILIATION BY COUNTY
A4: COUNTY | B4: REPUBLICAN PARTY OF FLORIDA | C4: FLORIDA DEMOCRATIC PARTY | D4: MINOR PARTY | E4: NO PARTY AFFILIATION | F4: TOTALS
A5: ALACHUA | B5: =April!B5-March!B5 -> -46 | C5: =April!C5-March!C5 -> -122 | D5: =April!D5-March!D5 -> -22 | E5: =April!E5-March!E5 -> 29 | F5: =SUM(B5:E5) -> -161
A6: BAKER | B6: =April!B6-March!B6 -> 17 | C6: =April!C6-March!C6 -> -7 | D6: =April!D6-March!D6 -> 0 | E6: =April!E6-March!E6 -> 6 | F6: =SUM(B6:E6) -> 16
A7: BAY | B7: =April!B7-March!B7 -> 25 | C7: =April!C7-March!C7 -> -77 | D7: =April!D7-March!D7 -> 16 | E7: =April!E7-March!E7 -> 74 | F7: =SUM(B7:E7) -> 38
A8: BRADFORD | B8: =April!B8-March!B8 -> 10 | C8: =April!C8-March!C8 -> -7 | D8: =April!D8-March!D8 -> 3 | E8: =April!E8-March!E8 -> 15 | F8: =SUM(B8:E8) -> 21
A9: BREVARD | B9: =April!B9-March!B9 -> -856 | C9: =April!C9-March!C9 -> -746 | D9: =April!D9-March!D9 -> -1384 | E9: =April!E9-March!E9 -> 769 | F9: =SUM(B9:E9) -> -2217
A10: BROWARD | B10: =April!B10-March!B10 -> -321 | C10: =April!C10-March!C10 -> -1447 | D10: =April!D10-March!D10 -> 120 | E10: =April!E10-March!E10 -> -398 | F10: =SUM(B10:E10) -> -2046
A11: CALHOUN | B11: =April!B11-March!B11 -> 12 | C11: =April!C11-March!C11 -> -12 | D11: =April!D11-March!D11 -> -13 | E11: =April!E11-March!E11 -> 14 | F11: =SUM(B11:E11) -> 1
A12: CHARLOTTE | B12: =April!B12-March!B12 -> 186 | C12: =April!C12-March!C12 -> 78 | D12: =April!D12-March!D12 -> -731 | E12: =April!E12-March!E12 -> 748 | F12: =SUM(B12:E12) -> 281
A13: CITRUS | B13: =April!B13-March!B13 -> -203 | C13: =April!C13-March!C13 -> -360 | D13: =April!D13-March!D13 -> -358 | E13: =April!E13-March!E13 -> 103 | F13: =SUM(B13:E13) -> -818
A14: CLAY | B14: =April!B14-March!B14 -> 84 | C14: =April!C14-March!C14 -> 49 | D14: =April!D14-March!D14 -> -497 | E14: =April!E14-March!E14 -> 633 | F14: =SUM(B14:E14) -> 269
A15: COLLIER | B15: =April!B15-March!B15 -> -2633 | C15: =April!C15-March!C15 -> -2651 | D15: =April!D15-March!D15 -> -317 | E15: =April!E15-March!E15 -> -3371 | F15: =SUM(B15:E15) -> -8972
A16: COLUMBIA | B16: =April!B16-March!B16 -> 35 | C16: =April!C16-March!C16 -> -33 | D16: =April!D16-March!D16 -> -71 | E16: =April!E16-March!E16 -> 29 | F16: =SUM(B16:E16) -> -40
... A71: WASHINGTON | B71: =April!B71-March!B71 -> -30 | C71: =April!C71-March!C71 -> -24 | D71: =April!D71-March!D71 -> 1 | E71: =April!E71-March!E71 -> 1 | F71: =SUM(B71:E71) -> -52
A72: TOTALS | B72: =SUM(B5:B71) -> -4397 | C72: =SUM(C5:C71) -> -10068 | D72: =SUM(D5:D71) -> -35111 | E72: =SUM(E5:E71) -> 32798 | F72: =SUM(F5:F71) -> -16778

Sheet NetAprToMay
A1: Monthly Report - Net Activity by Party Affiliation - April to May
A2: Data comparison between 04/30/2017 - 05/31/2017
A3: ACTIVE REGISTERED VOTERS BY PARTY AFFILIATION BY COUNTY
A4: COUNTY | B4: REPUBLICAN PARTY OF FLORIDA | C4: FLORIDA DEMOCRATIC PARTY | D4: MINOR PARTY | E4: NO PARTY AFFILIATION | F4: TOTALS
A5: ALACHUA | B5: =May!B5-April!B5 -> 39 | C5: =May!C5-April!C5 -> 14 | D5: =May!D5-April!D5 -> -422 | E5: =May!E5-April!E5 -> 539 | F5: =SUM(B5:E5) -> 170
A6: BAKER | B6: =May!B6-April!B6 -> -93 | C6: =May!C6-April!C6 -> -56 | D6: =May!D6-April!D6 -> -2 | E6: =May!E6-April!E6 -> -21 | F6: =SUM(B6:E6) -> -172
A7: BAY | B7: =May!B7-April!B7 -> -685 | C7: =May!C7-April!C7 -> -591 | D7: =May!D7-April!D7 -> -314 | E7: =May!E7-April!E7 -> -277 | F7: =SUM(B7:E7) -> -1867
A8: BRADFORD | B8: =May!B8-April!B8 -> 27 | C8: =May!C8-April!C8 -> -6 | D8: =May!D8-April!D8 -> -55 | E8: =May!E8-April!E8 -> 66 | F8: =SUM(B8:E8) -> 32
A9: BREVARD | B9: =May!B9-April!B9 -> 389 | C9: =May!C9-April!C9 -> 68 | D9: =May!D9-April!D9 -> 122 | E9: =May!E9-April!E9 -> 396 | F9: =SUM(B9:E9) -> 975
A10: BROWARD | B10: =May!B10-April!B10 -> -125 | C10: =May!C10-April!C10 -> -167 | D10: =May!D10-April!D10 -> -3218 | E10: =May!E10-April!E10 -> 3513 | F10: =SUM(B10:E10) -> 3
A11: CALHOUN | B11: =May!B11-April!B11 -> 2 | C11: =May!C11-April!C11 -> -4 | D11: =May!D11-April!D11 -> 1 | E11: =May!E11-April!E11 -> -2 | F11: =SUM(B11:E11) -> -3
A12: CHARLOTTE | B12: =May!B12-April!B12 -> -176 | C12: =May!C12-April!C12 -> -140 | D12: =May!D12-April!D12 -> 24 | E12: =May!E12-April!E12 -> -181 | F12: =SUM(B12:E12) -> -473
A13: CITRUS | B13: =May!B13-April!B13 -> -142 | C13: =May!C13-April!C13 -> -229 | D13: =May!D13-April!D13 -> 18 | E13: =May!E13-April!E13 -> -218 | F13: =SUM(B13:E13) -> -571
A14: CLAY | B14: =May!B14-April!B14 -> 56 | C14: =May!C14-April!C14 -> 42 | D14: =May!D14-April!D14 -> 47 | E14: =May!E14-April!E14 -> 92 | F14: =SUM(B14:E14) -> 237
A15: COLLIER | B15: =May!B15-April!B15 -> 360 | C15: =May!C15-April!C15 -> 205 | D15: =May!D15-April!D15 -> 19 | E15: =May!E15-April!E15 -> 289 | F15: =SUM(B15:E15) -> 873
A16: COLUMBIA | B16: =May!B16-April!B16 -> 17 | C16: =May!C16-April!C16 -> -19 | D16: =May!D16-April!D16 -> 7 | E16: =May!E16-April!E16 -> -1 | F16: =SUM(B16:E16) -> 4
... A71: WASHINGTON | B71: =May!B71-April!B71 -> 31 | C71: =May!C71-April!C71 -> -20 | D71: =May!D71-April!D71 -> 2 | E71: =May!E71-April!E71 -> 19 | F71: =SUM(B71:E71) -> 32
A72: TOTALS | B72: =SUM(B5:B71) -> -797 | C72: =SUM(C5:C71) -> -5895 | D72: =SUM(D5:D71) -> -6511 | E72: =SUM(E5:E71) -> 11049 | F72: =SUM(F5:F71) -> -2154

Sheet NetMayToJun
A1: Monthly Report - Net Activity by Party Affiliation - May to June
A2: Data comparison between 05/31/2017 - 06/30/2017
A3: ACTIVE REGISTERED VOTERS BY PARTY AFFILIATION BY COUNTY
A4: COUNTY | B4: REPUBLICAN PARTY OF FLORIDA | C4: FLORIDA DEMOCRATIC PARTY | D4: MINOR PARTY | E4: NO PARTY AFFILIATION | F4: TOTALS
A5: ALACHUA | B5: =June!B5-May!B5 -> -2232 | C5: =June!C5-May!C5 -> -4154 | D5: =June!D5-May!D5 -> -33 | E5: =June!E5-May!E5 -> -3372 | F5: =SUM(B5:E5) -> -9791
A6: BAKER | B6: =June!B6-May!B6 -> -21 | C6: =June!C6-May!C6 -> -25 | D6: =June!D6-May!D6 -> 0 | E6: =June!E6-May!E6 -> 9 | F6: =SUM(B6:E6) -> -37
A7: BAY | B7: =June!B7-May!B7 -> 148 | C7: =June!C7-May!C7 -> 28 | D7: =June!D7-May!D7 -> 19 | E7: =June!E7-May!E7 -> 180 | F7: =SUM(B7:E7) -> 375
A8: BRADFORD | B8: =June!B8-May!B8 -> -22 | C8: =June!C8-May!C8 -> -44 | D8: =June!D8-May!D8 -> 0 | E8: =June!E8-May!E8 -> -18 | F8: =SUM(B8:E8) -> -84
A9: BREVARD | B9: =June!B9-May!B9 -> 482 | C9: =June!C9-May!C9 -> 262 | D9: =June!D9-May!D9 -> 153 | E9: =June!E9-May!E9 -> 682 | F9: =SUM(B9:E9) -> 1579
A10: BROWARD | B10: =June!B10-May!B10 -> -1263 | C10: =June!C10-May!C10 -> -2624 | D10: =June!D10-May!D10 -> 214 | E10: =June!E10-May!E10 -> -998 | F10: =SUM(B10:E10) -> -4671
A11: CALHOUN | B11: =June!B11-May!B11 -> 5 | C11: =June!C11-May!C11 -> -3 | D11: =June!D11-May!D11 -> 1 | E11: =June!E11-May!E11 -> 7 | F11: =SUM(B11:E11) -> 10
A12: CHARLOTTE | B12: =June!B12-May!B12 -> 199 | C12: =June!C12-May!C12 -> 80 | D12: =June!D12-May!D12 -> 48 | E12: =June!E12-May!E12 -> 175 | F12: =SUM(B12:E12) -> 502
A13: CITRUS | B13: =June!B13-May!B13 -> 226 | C13: =June!C13-May!C13 -> 51 | D13: =June!D13-May!D13 -> 20 | E13: =June!E13-May!E13 -> 208 | F13: =SUM(B13:E13) -> 505
A14: CLAY | B14: =June!B14-May!B14 -> 310 | C14: =June!C14-May!C14 -> 218 | D14: =June!D14-May!D14 -> 49 | E14: =June!E14-May!E14 -> 205 | F14: =SUM(B14:E14) -> 782
A15: COLLIER | B15: =June!B15-May!B15 -> 350 | C15: =June!C15-May!C15 -> 299 | D15: =June!D15-May!D15 -> 25 | E15: =June!E15-May!E15 -> 411 | F15: =SUM(B15:E15) -> 1085
A16: COLUMBIA | B16: =June!B16-May!B16 -> 65 | C16: =June!C16-May!C16 -> 17 | D16: =June!D16-May!D16 -> 10 | E16: =June!E16-May!E16 -> 42 | F16: =SUM(B16:E16) -> 134
... A71: WASHINGTON | B71: =June!B71-May!B71 -> 17 | C71: =June!C71-May!C71 -> 1 | D71: =June!D71-May!D71 -> 1 | E71: =June!E71-May!E71 -> 16 | F71: =SUM(B71:E71) -> 35
A72: TOTALS | B72: =SUM(B5:B71) -> -2683 | C72: =SUM(C5:C71) -> -10213 | D72: =SUM(D5:D71) -> 2375 | E72: =SUM(E5:E71) -> 57 | F72: =SUM(F5:F71) -> -10464

Sheet NetJunToJul
A1: Monthly Report - Net Activity by Party Affiliation - June to July
A2: Data comparison between 06/30/2017 - 07/31/2017
A3: ACTIVE REGISTERED VOTERS BY PARTY AFFILIATION BY COUNTY
A4: COUNTY | B4: REPUBLICAN PARTY OF FLORIDA | C4: FLORIDA DEMOCRATIC PARTY | D4: MINOR PARTY | E4: NO PARTY AFFILIATION | F4: TOTALS
A5: ALACHUA | B5: =July!B5-June!B5 -> 51 | C5: =July!C5-June!C5 -> 64 | D5: =July!D5-June!D5 -> 37 | E5: =July!E5-June!E5 -> 189 | F5: =SUM(B5:E5) -> 341
A6: BAKER | B6: =July!B6-June!B6 -> -8 | C6: =July!C6-June!C6 -> -34 | D6: =July!D6-June!D6 -> 2 | E6: =July!E6-June!E6 -> -6 | F6: =SUM(B6:E6) -> -46
A7: BAY | B7: =July!B7-June!B7 -> 180 | C7: =July!C7-June!C7 -> 7 | D7: =July!D7-June!D7 -> 19 | E7: =July!E7-June!E7 -> 166 | F7: =SUM(B7:E7) -> 372
A8: BRADFORD | B8: =July!B8-June!B8 -> 30 | C8: =July!C8-June!C8 -> -18 | D8: =July!D8-June!D8 -> 1 | E8: =July!E8-June!E8 -> 12 | F8: =SUM(B8:E8) -> 25
A9: BREVARD | B9: =July!B9-June!B9 -> 15 | C9: =July!C9-June!C9 -> -205 | D9: =July!D9-June!D9 -> 174 | E9: =July!E9-June!E9 -> 357 | F9: =SUM(B9:E9) -> 341
A10: BROWARD | B10: =July!B10-June!B10 -> -161 | C10: =July!C10-June!C10 -> 698 | D10: =July!D10-June!D10 -> 242 | E10: =July!E10-June!E10 -> 728 | F10: =SUM(B10:E10) -> 1507
A11: CALHOUN | B11: =July!B11-June!B11 -> 0 | C11: =July!C11-June!C11 -> -11 | D11: =July!D11-June!D11 -> 1 | E11: =July!E11-June!E11 -> 0 | F11: =SUM(B11:E11) -> -10
A12: CHARLOTTE | B12: =July!B12-June!B12 -> 134 | C12: =July!C12-June!C12 -> 47 | D12: =July!D12-June!D12 -> 40 | E12: =July!E12-June!E12 -> 132 | F12: =SUM(B12:E12) -> 353
A13: CITRUS | B13: =July!B13-June!B13 -> 187 | C13: =July!C13-June!C13 -> -28 | D13: =July!D13-June!D13 -> 21 | E13: =July!E13-June!E13 -> 106 | F13: =SUM(B13:E13) -> 286
A14: CLAY | B14: =July!B14-June!B14 -> -131 | C14: =July!C14-June!C14 -> -99 | D14: =July!D14-June!D14 -> 44 | E14: =July!E14-June!E14 -> -32 | F14: =SUM(B14:E14) -> -218
A15: COLLIER | B15: =July!B15-June!B15 -> 352 | C15: =July!C15-June!C15 -> 180 | D15: =July!D15-June!D15 -> 29 | E15: =July!E15-June!E15 -> 399 | F15: =SUM(B15:E15) -> 960
A16: COLUMBIA | B16: =July!B16-June!B16 -> 57 | C16: =July!C16-June!C16 -> 1 | D16: =July!D16-June!D16 -> 10 | E16: =July!E16-June!E16 -> 40 | F16: =SUM(B16:E16) -> 108
... A71: WASHINGTON | B71: =July!B71-June!B71 -> 25 | C71: =July!C71-June!C71 -> -1 | D71: =July!D71-June!D71 -> 0 | E71: =July!E71-June!E71 -> 13 | F71: =SUM(B71:E71) -> 37
A72: TOTALS | B72: =SUM(B5:B71) -> -13433 | C72: =SUM(C5:C71) -> -16205 | D72: =SUM(D5:D71) -> 3150 | E72: =SUM(E5:E71) -> -7186 | F72: =SUM(F5:F71) -> -33674

Sheet NetJulToAug
A1: Monthly Report - Net Activity by Party Affiliation - July to August
A2: Data comparison between 07/31/2017 - 08/31/2017
A3: ACTIVE REGISTERED VOTERS BY PARTY AFFILIATION BY COUNTY
A4: COUNTY | B4: REPUBLICAN PARTY OF FLORIDA | C4: FLORIDA DEMOCRATIC PARTY | D4: MINOR PARTY | E4: NO PARTY AFFILIATION | F4: TOTALS
A5: ALACHUA | B5: =August!B5-July!B5 -> 154 | C5: =August!C5-July!C5 -> 207 | D5: =August!D5-July!D5 -> 29 | E5: =August!E5-July!E5 -> 293 | F5: =SUM(B5:E5) -> 683
A6: BAKER | B6: =August!B6-July!B6 -> 11 | C6: =August!C6-July!C6 -> -17 | D6: =August!D6-July!D6 -> 1 | E6: =August!E6-July!E6 -> -1 | F6: =SUM(B6:E6) -> -6
A7: BAY | B7: =August!B7-July!B7 -> -28 | C7: =August!C7-July!C7 -> -105 | D7: =August!D7-July!D7 -> 24 | E7: =August!E7-July!E7 -> -7 | F7: =SUM(B7:E7) -> -116
A8: BRADFORD | B8: =August!B8-July!B8 -> 29 | C8: =August!C8-July!C8 -> -2 | D8: =August!D8-July!D8 -> 2 | E8: =August!E8-July!E8 -> 19 | F8: =SUM(B8:E8) -> 48
A9: BREVARD | B9: =August!B9-July!B9 -> -519 | C9: =August!C9-July!C9 -> -445 | D9: =August!D9-July!D9 -> 162 | E9: =August!E9-July!E9 -> 33 | F9: =SUM(B9:E9) -> -769
A10: BROWARD | B10: =August!B10-July!B10 -> -239 | C10: =August!C10-July!C10 -> -210 | D10: =August!D10-July!D10 -> 153 | E10: =August!E10-July!E10 -> 720 | F10: =SUM(B10:E10) -> 424
A11: CALHOUN | B11: =August!B11-July!B11 -> 9 | C11: =August!C11-July!C11 -> -6 | D11: =August!D11-July!D11 -> 0 | E11: =August!E11-July!E11 -> 1 | F11: =SUM(B11:E11) -> 4
A12: CHARLOTTE | B12: =August!B12-July!B12 -> 227 | C12: =August!C12-July!C12 -> 35 | D12: =August!D12-July!D12 -> 38 | E12: =August!E12-July!E12 -> 179 | F12: =SUM(B12:E12) -> 479
A13: CITRUS | B13: =August!B13-July!B13 -> 163 | C13: =August!C13-July!C13 -> 21 | D13: =August!D13-July!D13 -> 45 | E13: =August!E13-July!E13 -> 80 | F13: =SUM(B13:E13) -> 309
A14: CLAY | B14: =August!B14-July!B14 -> -41 | C14: =August!C14-July!C14 -> 43 | D14: =August!D14-July!D14 -> 49 | E14: =August!E14-July!E14 -> 72 | F14: =SUM(B14:E14) -> 123
A15: COLLIER | B15: =August!B15-July!B15 -> -34 | C15: =August!C15-July!C15 -> 74 | D15: =August!D15-July!D15 -> 26 | E15: =August!E15-July!E15 -> 205 | F15: =SUM(B15:E15) -> 271
A16: COLUMBIA | B16: =August!B16-July!B16 -> 54 | C16: =August!C16-July!C16 -> 14 | D16: =August!D16-July!D16 -> 6 | E16: =August!E16-July!E16 -> 26 | F16: =SUM(B16:E16) -> 100
... A71: WASHINGTON | B71: =August!B71-July!B71 -> 18 | C71: =August!C71-July!C71 -> -17 | D71: =August!D71-July!D71 -> 3 | E71: =August!E71-July!E71 -> 8 | F71: =SUM(B71:E71) -> 12
A72: TOTALS | B72: =SUM(B5:B71) -> -421 | C72: =SUM(C5:C71) -> -2596 | D72: =SUM(D5:D71) -> 2933 | E72: =SUM(E5:E71) -> 8341 | F72: =SUM(F5:F71) -> 8257

Sheet NetAugToSep
A1: Monthly Report - Net Activity by Party Affiliation - August to September
A2: Data comparison between 08/31/2017 - 09/30/2017
A3: ACTIVE REGISTERED VOTERS BY PARTY AFFILIATION BY COUNTY
A4: COUNTY | B4: REPUBLICAN PARTY OF FLORIDA | C4: FLORIDA DEMOCRATIC PARTY | D4: MINOR PARTY | E4: NO PARTY AFFILIATION | F4: TOTALS
A5: ALACHUA | B5: =September!B5-August!B5 -> 72 | C5: =September!C5-August!C5 -> 84 | D5: =September!D5-August!D5 -> 33 | E5: =September!E5-August!E5 -> 182 | F5: =SUM(B5:E5) -> 371
A6: BAKER | B6: =September!B6-August!B6 -> 15 | C6: =September!C6-August!C6 -> -5 | D6: =September!D6-August!D6 -> 0 | E6: =September!E6-August!E6 -> 8 | F6: =SUM(B6:E6) -> 18
A7: BAY | B7: =September!B7-August!B7 -> 131 | C7: =September!C7-August!C7 -> 13 | D7: =September!D7-August!D7 -> 24 | E7: =September!E7-August!E7 -> 148 | F7: =SUM(B7:E7) -> 316
A8: BRADFORD | B8: =September!B8-August!B8 -> 27 | C8: =September!C8-August!C8 -> -9 | D8: =September!D8-August!D8 -> 3 | E8: =September!E8-August!E8 -> 15 | F8: =SUM(B8:E8) -> 36
A9: BREVARD | B9: =September!B9-August!B9 -> 186 | C9: =September!C9-August!C9 -> 90 | D9: =September!D9-August!D9 -> 163 | E9: =September!E9-August!E9 -> 464 | F9: =SUM(B9:E9) -> 903
A10: BROWARD | B10: =September!B10-August!B10 -> -1503 | C10: =September!C10-August!C10 -> -3052 | D10: =September!D10-August!D10 -> 353 | E10: =September!E10-August!E10 -> -593 | F10: =SUM(B10:E10) -> -4795
A11: CALHOUN | B11: =September!B11-August!B11 -> 26 | C11: =September!C11-August!C11 -> -10 | D11: =September!D11-August!D11 -> 0 | E11: =September!E11-August!E11 -> 3 | F11: =SUM(B11:E11) -> 19
A12: CHARLOTTE | B12: =September!B12-August!B12 -> 128 | C12: =September!C12-August!C12 -> 49 | D12: =September!D12-August!D12 -> 39 | E12: =September!E12-August!E12 -> 118 | F12: =SUM(B12:E12) -> 334
A13: CITRUS | B13: =September!B13-August!B13 -> 126 | C13: =September!C13-August!C13 -> 0 | D13: =September!D13-August!D13 -> 50 | E13: =September!E13-August!E13 -> 89 | F13: =SUM(B13:E13) -> 265
A14: CLAY | B14: =September!B14-August!B14 -> -106 | C14: =September!C14-August!C14 -> -39 | D14: =September!D14-August!D14 -> 33 | E14: =September!E14-August!E14 -> -14 | F14: =SUM(B14:E14) -> -126
A15: COLLIER | B15: =September!B15-August!B15 -> -846 | C15: =September!C15-August!C15 -> -362 | D15: =September!D15-August!D15 -> 32 | E15: =September!E15-August!E15 -> -277 | F15: =SUM(B15:E15) -> -1453
A16: COLUMBIA | B16: =September!B16-August!B16 -> 65 | C16: =September!C16-August!C16 -> -17 | D16: =September!D16-August!D16 -> 6 | E16: =September!E16-August!E16 -> 54 | F16: =SUM(B16:E16) -> 108
... A71: WASHINGTON | B71: =September!B71-August!B71 -> 29 | C71: =September!C71-August!C71 -> -20 | D71: =September!D71-August!D71 -> 1 | E71: =September!E71-August!E71 -> 13 | F71: =SUM(B71:E71) -> 23
A72: TOTALS | B72: =SUM(B5:B71) -> -7899 | C72: =SUM(C5:C71) -> -17192 | D72: =SUM(D5:D71) -> 3246 | E72: =SUM(E5:E71) -> -3017 | F72: =SUM(F5:F71) -> -24862

Sheet NetSepToOct
A1: Monthly Report - Net Activity by Party Affiliation - September to October
A2: Data comparison between 09/30/2017 - 10/31/2017
A3: ACTIVE REGISTERED VOTERS BY PARTY AFFILIATION BY COUNTY
A4: COUNTY | B4: REPUBLICAN PARTY OF FLORIDA | C4: FLORIDA DEMOCRATIC PARTY | D4: MINOR PARTY | E4: NO PARTY AFFILIATION | F4: TOTALS
A5: ALACHUA | B5: =October!B5-September!B5 -> 92 | C5: =October!C5-September!C5 -> 215 | D5: =October!D5-September!D5 -> 14 | E5: =October!E5-September!E5 -> 224 | F5: =SUM(B5:E5) -> 545
A6: BAKER | B6: =October!B6-September!B6 -> 5 | C6: =October!C6-September!C6 -> 3 | D6: =October!D6-September!D6 -> 2 | E6: =October!E6-September!E6 -> 7 | F6: =SUM(B6:E6) -> 17
A7: BAY | B7: =October!B7-September!B7 -> 153 | C7: =October!C7-September!C7 -> 41 | D7: =October!D7-September!D7 -> 18 | E7: =October!E7-September!E7 -> 104 | F7: =SUM(B7:E7) -> 316
A8: BRADFORD | B8: =October!B8-September!B8 -> 14 | C8: =October!C8-September!C8 -> 2 | D8: =October!D8-September!D8 -> 1 | E8: =October!E8-September!E8 -> 13 | F8: =SUM(B8:E8) -> 30
A9: BREVARD | B9: =October!B9-September!B9 -> 196 | C9: =October!C9-September!C9 -> 62 | D9: =October!D9-September!D9 -> 121 | E9: =October!E9-September!E9 -> 395 | F9: =SUM(B9:E9) -> 774
A10: BROWARD | B10: =October!B10-September!B10 -> 160 | C10: =October!C10-September!C10 -> 661 | D10: =October!D10-September!D10 -> 251 | E10: =October!E10-September!E10 -> 1382 | F10: =SUM(B10:E10) -> 2454
A11: CALHOUN | B11: =October!B11-September!B11 -> 10 | C11: =October!C11-September!C11 -> -1 | D11: =October!D11-September!D11 -> 1 | E11: =October!E11-September!E11 -> 9 | F11: =SUM(B11:E11) -> 19
A12: CHARLOTTE | B12: =October!B12-September!B12 -> 275 | C12: =October!C12-September!C12 -> 135 | D12: =October!D12-September!D12 -> 46 | E12: =October!E12-September!E12 -> 218 | F12: =SUM(B12:E12) -> 674
A13: CITRUS | B13: =October!B13-September!B13 -> 176 | C13: =October!C13-September!C13 -> 30 | D13: =October!D13-September!D13 -> 24 | E13: =October!E13-September!E13 -> 131 | F13: =SUM(B13:E13) -> 361
A14: CLAY | B14: =October!B14-September!B14 -> 109 | C14: =October!C14-September!C14 -> 94 | D14: =October!D14-September!D14 -> 34 | E14: =October!E14-September!E14 -> 195 | F14: =SUM(B14:E14) -> 432
A15: COLLIER | B15: =October!B15-September!B15 -> 228 | C15: =October!C15-September!C15 -> 118 | D15: =October!D15-September!D15 -> 45 | E15: =October!E15-September!E15 -> 290 | F15: =SUM(B15:E15) -> 681
A16: COLUMBIA | B16: =October!B16-September!B16 -> 54 | C16: =October!C16-September!C16 -> 1 | D16: =October!D16-September!D16 -> 7 | E16: =October!E16-September!E16 -> 43 | F16: =SUM(B16:E16) -> 105
... A71: WASHINGTON | B71: =October!B71-September!B71 -> 13 | C71: =October!C71-September!C71 -> -4 | D71: =October!D71-September!D71 -> 0 | E71: =October!E71-September!E71 -> 12 | F71: =SUM(B71:E71) -> 21
A72: TOTALS | B72: =SUM(B5:B71) -> 8593 | C72: =SUM(C5:C71) -> 8144 | D72: =SUM(D5:D71) -> 2756 | E72: =SUM(E5:E71) -> 17916 | F72: =SUM(F5:F71) -> 37409

Sheet NetOctToNov
A1: Monthly Report - Net Activity by Party Affiliation - October to November
A2: Data comparison between 10/31/2017 - 11/30/2017
A3: ACTIVE REGISTERED VOTERS BY PARTY AFFILIATION BY COUNTY
A4: COUNTY | B4: REPUBLICAN PARTY OF FLORIDA | C4: FLORIDA DEMOCRATIC PARTY | D4: MINOR PARTY | E4: NO PARTY AFFILIATION | F4: TOTALS
A5: ALACHUA | B5: =November!B5-October!B5 -> 42 | C5: =November!C5-October!C5 -> 122 | D5: =November!D5-October!D5 -> 22 | E5: =November!E5-October!E5 -> 195 | F5: =SUM(B5:E5) -> 381
A6: BAKER | B6: =November!B6-October!B6 -> 5 | C6: =November!C6-October!C6 -> -13 | D6: =November!D6-October!D6 -> 1 | E6: =November!E6-October!E6 -> 10 | F6: =SUM(B6:E6) -> 3
A7: BAY | B7: =November!B7-October!B7 -> 76 | C7: =November!C7-October!C7 -> 9 | D7: =November!D7-October!D7 -> 26 | E7: =November!E7-October!E7 -> 153 | F7: =SUM(B7:E7) -> 264
A8: BRADFORD | B8: =November!B8-October!B8 -> 17 | C8: =November!C8-October!C8 -> 6 | D8: =November!D8-October!D8 -> 3 | E8: =November!E8-October!E8 -> 8 | F8: =SUM(B8:E8) -> 34
A9: BREVARD | B9: =November!B9-October!B9 -> -971 | C9: =November!C9-October!C9 -> -1317 | D9: =November!D9-October!D9 -> 148 | E9: =November!E9-October!E9 -> -951 | F9: =SUM(B9:E9) -> -3091
A10: BROWARD | B10: =November!B10-October!B10 -> -15 | C10: =November!C10-October!C10 -> 199 | D10: =November!D10-October!D10 -> 236 | E10: =November!E10-October!E10 -> 1274 | F10: =SUM(B10:E10) -> 1694
A11: CALHOUN | B11: =November!B11-October!B11 -> 6 | C11: =November!C11-October!C11 -> -13 | D11: =November!D11-October!D11 -> 2 | E11: =November!E11-October!E11 -> 10 | F11: =SUM(B11:E11) -> 5
A12: CHARLOTTE | B12: =November!B12-October!B12 -> 212 | C12: =November!C12-October!C12 -> 83 | D12: =November!D12-October!D12 -> 63 | E12: =November!E12-October!E12 -> 204 | F12: =SUM(B12:E12) -> 562
A13: CITRUS | B13: =November!B13-October!B13 -> -402 | C13: =November!C13-October!C13 -> -292 | D13: =November!D13-October!D13 -> 24 | E13: =November!E13-October!E13 -> -204 | F13: =SUM(B13:E13) -> -874
A14: CLAY | B14: =November!B14-October!B14 -> 6 | C14: =November!C14-October!C14 -> 50 | D14: =November!D14-October!D14 -> 43 | E14: =November!E14-October!E14 -> 33 | F14: =SUM(B14:E14) -> 132
A15: COLLIER | B15: =November!B15-October!B15 -> -495 | C15: =November!C15-October!C15 -> -331 | D15: =November!D15-October!D15 -> 30 | E15: =November!E15-October!E15 -> -237 | F15: =SUM(B15:E15) -> -1033
A16: COLUMBIA | B16: =November!B16-October!B16 -> 28 | C16: =November!C16-October!C16 -> 4 | D16: =November!D16-October!D16 -> 6 | E16: =November!E16-October!E16 -> 51 | F16: =SUM(B16:E16) -> 89
... A71: WASHINGTON | B71: =November!B71-October!B71 -> 15 | C71: =November!C71-October!C71 -> -6 | D71: =November!D71-October!D71 -> 2 | E71: =November!E71-October!E71 -> 5 | F71: =SUM(B71:E71) -> 16
A72: TOTALS | B72: =SUM(B5:B71) -> 1519 | C72: =SUM(C5:C71) -> 1534 | D72: =SUM(D5:D71) -> 2993 | E72: =SUM(E5:E71) -> 12702 | F72: =SUM(F5:F71) -> 18748

Sheet NetNovToDec
A1: Monthly Report - Net Activity by Party Affiliation - November to December
A2: Data comparison between 11/30/2017 - 12/31/2017
A3: ACTIVE REGISTERED VOTERS BY PARTY AFFILIATION BY COUNTY
A4: COUNTY | B4: REPUBLICAN PARTY OF FLORIDA | C4: FLORIDA DEMOCRATIC PARTY | D4: MINOR PARTY | E4: NO PARTY AFFILIATION | F4: TOTALS
A5: ALACHUA | B5: =December!B5-November!B5 -> 24 | C5: =December!C5-November!C5 -> 85 | D5: =December!D5-November!D5 -> 20 | E5: =December!E5-November!E5 -> 156 | F5: =SUM(B5:E5) -> 285
A6: BAKER | B6: =December!B6-November!B6 -> 26 | C6: =December!C6-November!C6 -> -10 | D6: =December!D6-November!D6 -> 0 | E6: =December!E6-November!E6 -> 6 | F6: =SUM(B6:E6) -> 22
A7: BAY | B7: =December!B7-November!B7 -> 125 | C7: =December!C7-November!C7 -> 4 | D7: =December!D7-November!D7 -> 32 | E7: =December!E7-November!E7 -> 107 | F7: =SUM(B7:E7) -> 268
A8: BRADFORD | B8: =December!B8-November!B8 -> 16 | C8: =December!C8-November!C8 -> -5 | D8: =December!D8-November!D8 -> 0 | E8: =December!E8-November!E8 -> 14 | F8: =SUM(B8:E8) -> 25
A9: BREVARD | B9: =December!B9-November!B9 -> 314 | C9: =December!C9-November!C9 -> 155 | D9: =December!D9-November!D9 -> 158 | E9: =December!E9-November!E9 -> 490 | F9: =SUM(B9:E9) -> 1117
A10: BROWARD | B10: =December!B10-November!B10 -> 174 | C10: =December!C10-November!C10 -> 513 | D10: =December!D10-November!D10 -> 290 | E10: =December!E10-November!E10 -> 1068 | F10: =SUM(B10:E10) -> 2045
A11: CALHOUN | B11: =December!B11-November!B11 -> 8 | C11: =December!C11-November!C11 -> -16 | D11: =December!D11-November!D11 -> 1 | E11: =December!E11-November!E11 -> -3 | F11: =SUM(B11:E11) -> -10
A12: CHARLOTTE | B12: =December!B12-November!B12 -> -1310 | C12: =December!C12-November!C12 -> -1268 | D12: =December!D12-November!D12 -> 42 | E12: =December!E12-November!E12 -> -1732 | F12: =SUM(B12:E12) -> -4268
A13: CITRUS | B13: =December!B13-November!B13 -> -720 | C13: =December!C13-November!C13 -> -495 | D13: =December!D13-November!D13 -> 31 | E13: =December!E13-November!E13 -> -421 | F13: =SUM(B13:E13) -> -1605
A14: CLAY | B14: =December!B14-November!B14 -> 21 | C14: =December!C14-November!C14 -> 70 | D14: =December!D14-November!D14 -> 33 | E14: =December!E14-November!E14 -> 58 | F14: =SUM(B14:E14) -> 182
A15: COLLIER | B15: =December!B15-November!B15 -> 549 | C15: =December!C15-November!C15 -> 247 | D15: =December!D15-November!D15 -> 36 | E15: =December!E15-November!E15 -> 441 | F15: =SUM(B15:E15) -> 1273
A16: COLUMBIA | B16: =December!B16-November!B16 -> 45 | C16: =December!C16-November!C16 -> 2 | D16: =December!D16-November!D16 -> 5 | E16: =December!E16-November!E16 -> 40 | F16: =SUM(B16:E16) -> 92
... A71: WASHINGTON | B71: =December!B71-November!B71 -> 10 | C71: =December!C71-November!C71 -> -15 | D71: =December!D71-November!D71 -> 1 | E71: =December!E71-November!E71 -> 15 | F71: =SUM(B71:E71) -> 11
A72: TOTALS | B72: =SUM(B5:B71) -> -5438 | C72: =SUM(C5:C71) -> -7799 | D72: =SUM(D5:D71) -> 2851 | E72: =SUM(E5:E71) -> 1194 | F72: =SUM(F5:F71) -> -9192

Sheet Net-Year-to-Date Total
A1: Monthly Report - Net Activity by Party Affiliation - Year-to-Date Total
A2: Data comparison between 01/31/2017 - 12/31/2017
A3: ACTIVE REGISTERED VOTERS BY PARTY AFFILIATION BY COUNTY
A4: COUNTY | B4: REPUBLICAN PARTY OF FLORIDA | C4: FLORIDA DEMOCRATIC PARTY | D4: MINOR PARTY | E4: NO PARTY AFFILIATION | F4: TOTALS
A5: ALACHUA | B5: =NetJanToFeb!B5+NetFebToMar!B5+NetMarToApr!B5+NetAprToMay!B5+NetMayToJun!B5+NetJunToJul!B5+NetJulToAug!B5+NetAugToSep!B5+NetSepToOct!B5+NetOctToNov!B5+NetNovToDec!B5 -> -1607 | C5: =NetJanToFeb!C5+NetFebToMar!C5+NetMarToApr!C5+NetAprToMay!C5+NetMayToJun!C5+NetJunToJul!C5+NetJulToAug!C5+NetAugToSep!C5+NetSepToOct!C5+NetOctToNov!C5+NetNovToDec!C5 -> -3318 | D5: =NetJanToFeb!D5+NetFebToMar!D5+NetMarToApr!D5+NetAprToMay!D5+NetMayToJun!D5+NetJunToJul!D5+NetJulToAug!D5+NetAugToSep!D5+NetSepToOct!D5+NetOctToNov!D5+NetNovToDec!D5 -> -2957 | E5: =NetJanToFeb!E5+NetFebToMar!E5+NetMarToApr!E5+NetAprToMay!E5+NetMayToJun!E5+NetJunToJul!E5+NetJulToAug!E5+NetAugToSep!E5+NetSepToOct!E5+NetOctToNov!E5+NetNovToDec!E5 -> 1137 | F5: =SUM(B5:E5) -> -6745
A6: BAKER | B6: =NetJanToFeb!B6+NetFebToMar!B6+NetMarToApr!B6+NetAprToMay!B6+NetMayToJun!B6+NetJunToJul!B6+NetJulToAug!B6+NetAugToSep!B6+NetSepToOct!B6+NetOctToNov!B6+NetNovToDec!B6 -> 47 | C6: =NetJanToFeb!C6+NetFebToMar!C6+NetMarToApr!C6+NetAprToMay!C6+NetMayToJun!C6+NetJunToJul!C6+NetJulToAug!C6+NetAugToSep!C6+NetSepToOct!C6+NetOctToNov!C6+NetNovToDec!C6 -> -187 | D6: =NetJanToFeb!D6+NetFebToMar!D6+NetMarToApr!D6+NetAprToMay!D6+NetMayToJun!D6+NetJunToJul!D6+NetJulToAug!D6+NetAugToSep!D6+NetSepToOct!D6+NetOctToNov!D6+NetNovToDec!D6 -> -135 | E6: =NetJanToFeb!E6+NetFebToMar!E6+NetMarToApr!E6+NetAprToMay!E6+NetMayToJun!E6+NetJunToJul!E6+NetJulToAug!E6+NetAugToSep!E6+NetSepToOct!E6+NetOctToNov!E6+NetNovToDec!E6 -> 136 | F6: =SUM(B6:E6) -> -139
A7: BAY | B7: =NetJanToFeb!B7+NetFebToMar!B7+NetMarToApr!B7+NetAprToMay!B7+NetMayToJun!B7+NetJunToJul!B7+NetJulToAug!B7+NetAugToSep!B7+NetSepToOct!B7+NetOctToNov!B7+NetNovToDec!B7 -> -872 | C7: =NetJanToFeb!C7+NetFebToMar!C7+NetMarToApr!C7+NetAprToMay!C7+NetMayToJun!C7+NetJunToJul!C7+NetJulToAug!C7+NetAugToSep!C7+NetSepToOct!C7+NetOctToNov!C7+NetNovToDec!C7 -> -1293 | D7: =NetJanToFeb!D7+NetFebToMar!D7+NetMarToApr!D7+NetAprToMay!D7+NetMayToJun!D7+NetJunToJul!D7+NetJulToAug!D7+NetAugToSep!D7+NetSepToOct!D7+NetOctToNov!D7+NetNovToDec!D7 -> -116 | E7: =NetJanToFeb!E7+NetFebToMar!E7+NetMarToApr!E7+NetAprToMay!E7+NetMayToJun!E7+NetJunToJul!E7+NetJulToAug!E7+NetAugToSep!E7+NetSepToOct!E7+NetOctToNov!E7+NetNovToDec!E7 -> -41 | F7: =SUM(B7:E7) -> -2322
A8: BRADFORD | B8: =NetJanToFeb!B8+NetFebToMar!B8+NetMarToApr!B8+NetAprToMay!B8+NetMayToJun!B8+NetJunToJul!B8+NetJulToAug!B8+NetAugToSep!B8+NetSepToOct!B8+NetOctToNov!B8+NetNovToDec!B8 -> 194 | C8: =NetJanToFeb!C8+NetFebToMar!C8+NetMarToApr!C8+NetAprToMay!C8+NetMayToJun!C8+NetJunToJul!C8+NetJulToAug!C8+NetAugToSep!C8+NetSepToOct!C8+NetOctToNov!C8+NetNovToDec!C8 -> -94 | D8: =NetJanToFeb!D8+NetFebToMar!D8+NetMarToApr!D8+NetAprToMay!D8+NetMayToJun!D8+NetJunToJul!D8+NetJulToAug!D8+NetAugToSep!D8+NetSepToOct!D8+NetOctToNov!D8+NetNovToDec!D8 -> -184 | E8: =NetJanToFeb!E8+NetFebToMar!E8+NetMarToApr!E8+NetAprToMay!E8+NetMayToJun!E8+NetJunToJul!E8+NetJulToAug!E8+NetAugToSep!E8+NetSepToOct!E8+NetOctToNov!E8+NetNovToDec!E8 -> 322 | F8: =SUM(B8:E8) -> 238
A9: BREVARD | B9: =NetJanToFeb!B9+NetFebToMar!B9+NetMarToApr!B9+NetAprToMay!B9+NetMayToJun!B9+NetJunToJul!B9+NetJulToAug!B9+NetAugToSep!B9+NetSepToOct!B9+NetOctToNov!B9+NetNovToDec!B9 -> -312 | C9: =NetJanToFeb!C9+NetFebToMar!C9+NetMarToApr!C9+NetAprToMay!C9+NetMayToJun!C9+NetJunToJul!C9+NetJulToAug!C9+NetAugToSep!C9+NetSepToOct!C9+NetOctToNov!C9+NetNovToDec!C9 -> -2069 | D9: =NetJanToFeb!D9+NetFebToMar!D9+NetMarToApr!D9+NetAprToMay!D9+NetMayToJun!D9+NetJunToJul!D9+NetJulToAug!D9+NetAugToSep!D9+NetSepToOct!D9+NetOctToNov!D9+NetNovToDec!D9 -> -5 | E9: =NetJanToFeb!E9+NetFebToMar!E9+NetMarToApr!E9+NetAprToMay!E9+NetMayToJun!E9+NetJunToJul!E9+NetJulToAug!E9+NetAugToSep!E9+NetSepToOct!E9+NetOctToNov!E9+NetNovToDec!E9 -> 3093 | F9: =SUM(B9:E9) -> 707
A10: BROWARD | B10: =NetJanToFeb!B10+NetFebToMar!B10+NetMarToApr!B10+NetAprToMay!B10+NetMayToJun!B10+NetJunToJul!B10+NetJulToAug!B10+NetAugToSep!B10+NetSepToOct!B10+NetOctToNov!B10+NetNovToDec!B10 -> -4737 | C10: =NetJanToFeb!C10+NetFebToMar!C10+NetMarToApr!C10+NetAprToMay!C10+NetMayToJun!C10+NetJunToJul!C10+NetJulToAug!C10+NetAugToSep!C10+NetSepToOct!C10+NetOctToNov!C10+NetNovToDec!C10 -> -10240 | D10: =NetJanToFeb!D10+NetFebToMar!D10+NetMarToApr!D10+NetAprToMay!D10+NetMayToJun!D10+NetJunToJul!D10+NetJulToAug!D10+NetAugToSep!D10+NetSepToOct!D10+NetOctToNov!D10+NetNovToDec!D10 -> -14561 | E10: =NetJanToFeb!E10+NetFebToMar!E10+NetMarToApr!E10+NetAprToMay!E10+NetMayToJun!E10+NetJunToJul!E10+NetJulToAug!E10+NetAugToSep!E10+NetSepToOct!E10+NetOctToNov!E10+NetNovToDec!E10 -> 17563 | F10: =SUM(B10:E10) -> -11975
A11: CALHOUN | B11: =NetJanToFeb!B11+NetFebToMar!B11+NetMarToApr!B11+NetAprToMay!B11+NetMayToJun!B11+NetJunToJul!B11+NetJulToAug!B11+NetAugToSep!B11+NetSepToOct!B11+NetOctToNov!B11+NetNovToDec!B11 -> 93 | C11: =NetJanToFeb!C11+NetFebToMar!C11+NetMarToApr!C11+NetAprToMay!C11+NetMayToJun!C11+NetJunToJul!C11+NetJulToAug!C11+NetAugToSep!C11+NetSepToOct!C11+NetOctToNov!C11+NetNovToDec!C11 -> -143 | D11: =NetJanToFeb!D11+NetFebToMar!D11+NetMarToApr!D11+NetAprToMay!D11+NetMayToJun!D11+NetJunToJul!D11+NetJulToAug!D11+NetAugToSep!D11+NetSepToOct!D11+NetOctToNov!D11+NetNovToDec!D11 -> -7 | E11: =NetJanToFeb!E11+NetFebToMar!E11+NetMarToApr!E11+NetAprToMay!E11+NetMayToJun!E11+NetJunToJul!E11+NetJulToAug!E11+NetAugToSep!E11+NetSepToOct!E11+NetOctToNov!E11+NetNovToDec!E11 -> 42 | F11: =SUM(B11:E11) -> -15
A12: CHARLOTTE | B12: =NetJanToFeb!B12+NetFebToMar!B12+NetMarToApr!B12+NetAprToMay!B12+NetMayToJun!B12+NetJunToJul!B12+NetJulToAug!B12+NetAugToSep!B12+NetSepToOct!B12+NetOctToNov!B12+NetNovToDec!B12 -> 735 | C12: =NetJanToFeb!C12+NetFebToMar!C12+NetMarToApr!C12+NetAprToMay!C12+NetMayToJun!C12+NetJunToJul!C12+NetJulToAug!C12+NetAugToSep!C12+NetSepToOct!C12+NetOctToNov!C12+NetNovToDec!C12 -> -555 | D12: =NetJanToFeb!D12+NetFebToMar!D12+NetMarToApr!D12+NetAprToMay!D12+NetMayToJun!D12+NetJunToJul!D12+NetJulToAug!D12+NetAugToSep!D12+NetSepToOct!D12+NetOctToNov!D12+NetNovToDec!D12 -> -4733 | E12: =NetJanToFeb!E12+NetFebToMar!E12+NetMarToApr!E12+NetAprToMay!E12+NetMayToJun!E12+NetJunToJul!E12+NetJulToAug!E12+NetAugToSep!E12+NetSepToOct!E12+NetOctToNov!E12+NetNovToDec!E12 -> 3795 | F12: =SUM(B12:E12) -> -758
A13: CITRUS | B13: =NetJanToFeb!B13+NetFebToMar!B13+NetMarToApr!B13+NetAprToMay!B13+NetMayToJun!B13+NetJunToJul!B13+NetJulToAug!B13+NetAugToSep!B13+NetSepToOct!B13+NetOctToNov!B13+NetNovToDec!B13 -> -246 | C13: =NetJanToFeb!C13+NetFebToMar!C13+NetMarToApr!C13+NetAprToMay!C13+NetMayToJun!C13+NetJunToJul!C13+NetJulToAug!C13+NetAugToSep!C13+NetSepToOct!C13+NetOctToNov!C13+NetNovToDec!C13 -> -1312 | D13: =NetJanToFeb!D13+NetFebToMar!D13+NetMarToApr!D13+NetAprToMay!D13+NetMayToJun!D13+NetJunToJul!D13+NetJulToAug!D13+NetAugToSep!D13+NetSepToOct!D13+NetOctToNov!D13+NetNovToDec!D13 -> -99 | E13: =NetJanToFeb!E13+NetFebToMar!E13+NetMarToApr!E13+NetAprToMay!E13+NetMayToJun!E13+NetJunToJul!E13+NetJulToAug!E13+NetAugToSep!E13+NetSepToOct!E13+NetOctToNov!E13+NetNovToDec!E13 -> -157 | F13: =SUM(B13:E13) -> -1814
A14: CLAY | B14: =NetJanToFeb!B14+NetFebToMar!B14+NetMarToApr!B14+NetAprToMay!B14+NetMayToJun!B14+NetJunToJul!B14+NetJulToAug!B14+NetAugToSep!B14+NetSepToOct!B14+NetOctToNov!B14+NetNovToDec!B14 -> 461 | C14: =NetJanToFeb!C14+NetFebToMar!C14+NetMarToApr!C14+NetAprToMay!C14+NetMayToJun!C14+NetJunToJul!C14+NetJulToAug!C14+NetAugToSep!C14+NetSepToOct!C14+NetOctToNov!C14+NetNovToDec!C14 -> 661 | D14: =NetJanToFeb!D14+NetFebToMar!D14+NetMarToApr!D14+NetAprToMay!D14+NetMayToJun!D14+NetJunToJul!D14+NetJulToAug!D14+NetAugToSep!D14+NetSepToOct!D14+NetOctToNov!D14+NetNovToDec!D14 -> -109 | E14: =NetJanToFeb!E14+NetFebToMar!E14+NetMarToApr!E14+NetAprToMay!E14+NetMayToJun!E14+NetJunToJul!E14+NetJulToAug!E14+NetAugToSep!E14+NetSepToOct!E14+NetOctToNov!E14+NetNovToDec!E14 -> 1400 | F14: =SUM(B14:E14) -> 2413
