Workbook

Sheet PriorDecember
A1: Monthly Report - Voter Registration by Party Affiliation - Prior December
A2: Data as of 12/31/2024
A3: ACTIVE REGISTERED VOTERS BY PARTY AFFILIATION BY COUNTY
A4: County | B4: Republican Party Of Florida | C4: Florida Democratic Party | D4: Minor Party | E4: No Party Affiliation | F4: Totals
A5: ALACHUA | B5: 49407 | C5: 78894 | D5: 5094 | E5: 40576 | F5: 173971
A6: BAKER | B6: 12894 | C6: 3620 | D6: 423 | E6: 2397 | F6: 19334
A7: BAY | B7: 75354 | C7: 26297 | D7: 4619 | E7: 27878 | F7: 134148
A8: BRADFORD | B8: 11188 | C8: 4342 | D8: 407 | E8: 2673 | F8: 18610
A9: BREVARD | B9: 204499 | C9: 118133 | D9: 16746 | E9: 113369 | F9: 452747
A10: BROWARD | B10: 276345 | C10: 523275 | D10: 28647 | E10: 346944 | F10: 1175211
A11: CALHOUN | B11: 4917 | C11: 2390 | D11: 88 | E11: 920 | F11: 8315
A12: CHARLOTTE | B12: 79782 | C12: 31486 | D12: 5911 | E12: 36972 | F12: 154151
A13: CITRUS | B13: 69816 | C13: 22519 | D13: 4144 | E13: 25310 | F13: 121789
A14: CLAY | B14: 89376 | C14: 32309 | D14: 5359 | E14: 32962 | F14: 160006
A15: COLLIER | B15: 144243 | C15: 53712 | D15: 7259 | E15: 62199 | F15: 267413
A16: COLUMBIA | B16: 24468 | C16: 10405 | D16: 1208 | E16: 7014 | F16: 43095
... A72: TOTALS | B72: 5635902 | C72: 4479820 | D72: 431377 | E72: 3710036 | F72: 14257135

Sheet January
A1: Monthly Report - Voter Registration by Party Affiliation - January
A2: Data as of 01/31/2025
A3: ACTIVE REGISTERED VOTERS BY PARTY AFFILIATION BY COUNTY
A4: County | B4: Republican Party Of Florida | C4: Florida Democratic Party | D4: Minor Party | E4: No Party Affiliation | F4: Totals
A5: ALACHUA | B5: 49464 | C5: 78637 | D5: 5165 | E5: 40586 | F5: 173852
A6: BAKER | B6: 12948 | C6: 3609 | D6: 431 | E6: 2416 | F6: 19404
A7: BAY | B7: 75650 | C7: 26273 | D7: 4697 | E7: 27906 | F7: 134526
A8: BRADFORD | B8: 11228 | C8: 4349 | D8: 401 | E8: 2686 | F8: 18664
A9: BREVARD | B9: 204082 | C9: 117216 | D9: 16785 | E9: 113010 | F9: 451093
A10: BROWARD | B10: 275998 | C10: 521104 | D10: 28717 | E10: 346232 | F10: 1172051
A11: CALHOUN | B11: 4910 | C11: 2369 | D11: 89 | E11: 921 | F11: 8289
A12: CHARLOTTE | B12: 78971 | C12: 30815 | D12: 5884 | E12: 36125 | F12: 151795
A13: CITRUS | B13: 70077 | C13: 22502 | D13: 4102 | E13: 25472 | F13: 122153
A14: CLAY | B14: 89575 | C14: 32337 | D14: 5163 | E14: 33254 | F14: 160329
A15: COLLIER | B15: 144742 | C15: 53759 | D15: 7107 | E15: 62593 | F15: 268201
A16: COLUMBIA | B16: 24530 | C16: 10387 | D16: 1227 | E16: 7034 | F16: 43178
... A72: TOTALS | B72: 5643100 | C72: 4463592 | D72: 431269 | E72: 3709462 | F72: 14247423

Sheet February
A1: Monthly Report - Voter Registration by Party Affiliation - February
A2: Data as of 02/28/2025
A3: ACTIVE REGISTERED VOTERS BY PARTY AFFILIATION BY COUNTY
A4: County | B4: Republican Party Of Florida | C4: Florida Democratic Party | D4: Minor Party | E4: No Party Affiliation | F4: Totals
A5: ALACHUA | B5: 49402 | C5: 78192 | D5: 4980 | E5: 40698 | F5: 173272
A6: BAKER | B6: 12979 | C6: 3605 | D6: 418 | E6: 2434 | F6: 19436
A7: BAY | B7: 75871 | C7: 26260 | D7: 4529 | E7: 28170 | F7: 134830
A8: BRADFORD | B8: 11253 | C8: 4345 | D8: 411 | E8: 2683 | F8: 18692
A9: BREVARD | B9: 204406 | C9: 117070 | D9: 16339 | E9: 113783 | F9: 451598
A10: BROWARD | B10: 277596 | C10: 521867 | D10: 28112 | E10: 349418 | F10: 1176993
A11: CALHOUN | B11: 4673 | C11: 1975 | D11: 84 | E11: 711 | F11: 7443
A12: CHARLOTTE | B12: 79456 | C12: 30832 | D12: 5732 | E12: 36433 | F12: 152453
A13: CITRUS | B13: 66959 | C13: 20739 | D13: 3965 | E13: 22323 | F13: 113986
A14: CLAY | B14: 89336 | C14: 32115 | D14: 5189 | E14: 32976 | F14: 159616
A15: COLLIER | B15: 145228 | C15: 53803 | D15: 7227 | E15: 62648 | F15: 268906
A16: COLUMBIA | B16: 24595 | C16: 10383 | D16: 1242 | E16: 7023 | F16: 43243
... A72: TOTALS | B72: 5635743 | C72: 4437884 | D72: 424809 | E72: 3696621 | F72: 14195057

Sheet March
A1: Monthly Report - Voter Registration by Party Affiliation - March
A2: Data as of 03/31/2025
A3: ACTIVE REGISTERED VOTERS BY PARTY AFFILIATION BY COUNTY
A4: County | B4: Republican Party Of Florida | C4: Florida Democratic Party | D4: Minor Party | E4: No Party Affiliation | F4: Totals
A5: ALACHUA | B5: 49447 | C5: 78106 | D5: 5057 | E5: 40793 | F5: 173403
A6: BAKER | B6: 12971 | C6: 3583 | D6: 415 | E6: 2420 | F6: 19389
A7: BAY | B7: 76182 | C7: 26314 | D7: 4636 | E7: 28224 | F7: 135356
A8: BRADFORD | B8: 11193 | C8: 4296 | D8: 408 | E8: 2655 | F8: 18552
A9: BREVARD | B9: 204125 | C9: 116416 | D9: 16390 | E9: 113184 | F9: 450115
A10: BROWARD | B10: 278448 | C10: 521756 | D10: 28491 | E10: 350699 | F10: 1179394
A11: CALHOUN | B11: 4680 | C11: 1964 | D11: 84 | E11: 719 | F11: 7447
A12: CHARLOTTE | B12: 79829 | C12: 30844 | D12: 5805 | E12: 36546 | F12: 153024
A13: CITRUS | B13: 66869 | C13: 20596 | D13: 4012 | E13: 22261 | F13: 113738
A14: CLAY | B14: 89566 | C14: 32221 | D14: 5283 | E14: 33046 | F14: 160116
A15: COLLIER | B15: 145398 | C15: 53659 | D15: 7348 | E15: 62590 | F15: 268995
A16: COLUMBIA | B16: 24680 | C16: 10386 | D16: 1192 | E16: 7146 | F16: 43404
... A72: TOTALS | B72: 5635771 | C72: 4424888 | D72: 429068 | E72: 3690537 | F72: 14180264

Sheet April
A1: Monthly Report - Voter Registration by Party Affiliation - April
A2: Data as of 04/30/2025
A3: ACTIVE REGISTERED VOTERS BY PARTY AFFILIATION BY COUNTY
A4: County | B4: Republican Party Of Florida | C4: Florida Democratic Party | D4: Minor Party | E4: No Party Affiliation | F4: Totals
A5: ALACHUA | B5: 49572 | C5: 78146 | D5: 5104 | E5: 40941 | F5: 173763
A6: BAKER | B6: 13004 | C6: 3573 | D6: 419 | E6: 2419 | F6: 19415
A7: BAY | B7: 76522 | C7: 26345 | D7: 4703 | E7: 28309 | F7: 135879
A8: BRADFORD | B8: 11174 | C8: 4239 | D8: 405 | E8: 2633 | F8: 18451
A9: BREVARD | B9: 204555 | C9: 116395 | D9: 16558 | E9: 113427 | F9: 450935
A10: BROWARD | B10: 279154 | C10: 521669 | D10: 28741 | E10: 352237 | F10: 1181801
A11: CALHOUN | B11: 4697 | C11: 1967 | D11: 85 | E11: 731 | F11: 7480
A12: CHARLOTTE | B12: 76657 | C12: 28530 | D12: 5498 | E12: 32450 | F12: 143135
A13: CITRUS | B13: 67100 | C13: 20639 | D13: 4085 | E13: 22339 | F13: 114163
A14: CLAY | B14: 89360 | C14: 32154 | D14: 5281 | E14: 32852 | F14: 159647
A15: COLLIER | B15: 141751 | C15: 49910 | D15: 7188 | E15: 57783 | F15: 256632
A16: COLUMBIA | B16: 24765 | C16: 10410 | D16: 1205 | E16: 7170 | F16: 43550
... A72: TOTALS | B72: 5578457 | C72: 4329371 | D72: 425882 | E72: 3583834 | F72: 13917544

Sheet May
A1: Monthly Report - Voter Registration by Party Affiliation - May
A2: Data as of 05/31/2025
A3: ACTIVE REGISTERED VOTERS BY PARTY AFFILIATION BY COUNTY
A4: County | B4: Republican Party Of Florida | C4: Florida Democratic Party | D4: Minor Party | E4: No Party Affiliation | F4: Totals
A5: ALACHUA | B5: 49393 | C5: 77714 | D5: 5106 | E5: 40595 | F5: 172808
A6: BAKER | B6: 12519 | C6: 3147 | D6: 404 | E6: 2080 | F6: 18150
A7: BAY | B7: 76858 | C7: 26408 | D7: 4790 | E7: 28363 | F7: 136419
A8: BRADFORD | B8: 11189 | C8: 4229 | D8: 412 | E8: 2622 | F8: 18452
A9: BREVARD | B9: 205179 | C9: 116578 | D9: 16773 | E9: 113891 | F9: 452421
A10: BROWARD | B10: 279596 | C10: 521729 | D10: 29026 | E10: 353598 | F10: 1183949
A11: CALHOUN | B11: 4707 | C11: 1969 | D11: 86 | E11: 739 | F11: 7501
A12: CHARLOTTE | B12: 77104 | C12: 28615 | D12: 5586 | E12: 32599 | F12: 143904
A13: CITRUS | B13: 67354 | C13: 20684 | D13: 4158 | E13: 22393 | F13: 114589
A14: CLAY | B14: 89341 | C14: 32138 | D14: 5334 | E14: 32743 | F14: 159556
A15: COLLIER | B15: 142132 | C15: 49998 | D15: 7292 | E15: 57870 | F15: 257292
A16: COLUMBIA | B16: 23429 | C16: 9435 | D16: 1117 | E16: 6008 | F16: 39989
... A72: TOTALS | B72: 5522017 | C72: 4211158 | D72: 426723 | E72: 3456755 | F72: 13616653

Sheet June
A1: Monthly Report - Voter Registration by Party Affiliation - June
A2: Data as of 06/30/2025
A3: ACTIVE REGISTERED VOTERS BY PARTY AFFILIATION BY COUNTY
A4: County | B4: Republican Party Of Florida | C4: Florida Democratic Party | D4: Minor Party | E4: No Party Affiliation | F4: Totals
A5: ALACHUA | B5: 49515 | C5: 77846 | D5: 5166 | E5: 40696 | F5: 173223
A6: BAKER | B6: 12264 | C6: 2941 | D6: 397 | E6: 1884 | F6: 17486
A7: BAY | B7: 76635 | C7: 26298 | D7: 4824 | E7: 28191 | F7: 135948
A8: BRADFORD | B8: 11211 | C8: 4227 | D8: 416 | E8: 2625 | F8: 18479
A9: BREVARD | B9: 205555 | C9: 116606 | D9: 16942 | E9: 114245 | F9: 453348
A10: BROWARD | B10: 279966 | C10: 521896 | D10: 29269 | E10: 354571 | F10: 1185702
A11: CALHOUN | B11: 4711 | C11: 1963 | D11: 85 | E11: 746 | F11: 7505
A12: CHARLOTTE | B12: 77526 | C12: 28662 | D12: 5681 | E12: 32722 | F12: 144591
A13: CITRUS | B13: 67601 | C13: 20714 | D13: 4218 | E13: 22467 | F13: 115000
A14: CLAY | B14: 89235 | C14: 32026 | D14: 5379 | E14: 32594 | F14: 159234
A15: COLLIER | B15: 142507 | C15: 50076 | D15: 7400 | E15: 57956 | F15: 257939
A16: COLUMBIA | B16: 23500 | C16: 9423 | D16: 1138 | E16: 6039 | F16: 40100
... A72: TOTALS | B72: 5509500 | C72: 4192786 | D72: 430587 | E72: 3438211 | F72: 13571084

Sheet July
A1: Monthly Report - Voter Registration by Party Affiliation - July
A2: Data as of 07/31/2025
A3: ACTIVE REGISTERED VOTERS BY PARTY AFFILIATION BY COUNTY
A4: County | B4: Republican Party Of Florida | C4: Florida Democratic Party | D4: Minor Party | E4: No Party Affiliation | F4: Totals
A5: ALACHUA | B5: 49637 | C5: 77840 | D5: 5233 | E5: 40800 | F5: 173510
A6: BAKER | B6: 12264 | C6: 2876 | D6: 406 | E6: 1852 | F6: 17398
A7: BAY | B7: 76732 | C7: 26295 | D7: 4897 | E7: 28155 | F7: 136079
A8: BRADFORD | B8: 11216 | C8: 4218 | D8: 427 | E8: 2623 | F8: 18484
A9: BREVARD | B9: 197940 | C9: 109081 | D9: 16272 | E9: 102829 | F9: 426122
A10: BROWARD | B10: 281060 | C10: 522009 | D10: 29839 | E10: 355991 | F10: 1188899
A11: CALHOUN | B11: 4725 | C11: 1962 | D11: 86 | E11: 745 | F11: 7518
A12: CHARLOTTE | B12: 77977 | C12: 28704 | D12: 5757 | E12: 32788 | F12: 145226
A13: CITRUS | B13: 67769 | C13: 20677 | D13: 4251 | E13: 22419 | F13: 115116
A14: CLAY | B14: 85770 | C14: 29615 | D14: 5169 | E14: 28760 | F14: 149314
A15: COLLIER | B15: 142887 | C15: 50137 | D15: 7482 | E15: 58053 | F15: 258559
A16: COLUMBIA | B16: 23580 | C16: 9455 | D16: 1163 | E16: 6094 | F16: 40292
... A72: TOTALS | B72: 5499643 | C72: 4173426 | D72: 434861 | E72: 3415965 | F72: 13523895

Sheet August
A1: Monthly Report - Voter Registration by Party Affiliation - August
A2: Data as of 08/31/2025
A3: ACTIVE REGISTERED VOTERS BY PARTY AFFILIATION BY COUNTY
A4: County | B4: Republican Party Of Florida | C4: Florida Democratic Party | D4: Minor Party | E4: No Party Affiliation | F4: Totals
A5: ALACHUA | B5: 49769 | C5: 77930 | D5: 5254 | E5: 40926 | F5: 173879
A6: BAKER | B6: 12239 | C6: 2858 | D6: 403 | E6: 1840 | F6: 17340
A7: BAY | B7: 77084 | C7: 26322 | D7: 4952 | E7: 28195 | F7: 136553
A8: BRADFORD | B8: 11256 | C8: 4209 | D8: 436 | E8: 2629 | F8: 18530
A9: BREVARD | B9: 198891 | C9: 109323 | D9: 16462 | E9: 103343 | F9: 428019
A10: BROWARD | B10: 281311 | C10: 521542 | D10: 30048 | E10: 356498 | F10: 1189399
A11: CALHOUN | B11: 4723 | C11: 1951 | D11: 89 | E11: 752 | F11: 7515
A12: CHARLOTTE | B12: 78397 | C12: 28719 | D12: 5832 | E12: 32835 | F12: 145783
A13: CITRUS | B13: 68028 | C13: 20661 | D13: 4296 | E13: 22454 | F13: 115439
A14: CLAY | B14: 86176 | C14: 29766 | D14: 5273 | E14: 28949 | F14: 150164
A15: COLLIER | B15: 143235 | C15: 50210 | D15: 7573 | E15: 58194 | F15: 259212
A16: COLUMBIA | B16: 23641 | C16: 9475 | D16: 1180 | E16: 6117 | F16: 40413
... A72: TOTALS | B72: 5495517 | C72: 4140030 | D72: 438254 | E72: 3387390 | F72: 13461191

Sheet September
A1: Monthly Report - Voter Registration by Party Affiliation - September
A2: Data as of 09/30/2025
A3: ACTIVE REGISTERED VOTERS BY PARTY AFFILIATION BY COUNTY
A4: County | B4: Republican Party Of Florida | C4: Florida Democratic Party | D4: Minor Party | E4: No Party Affiliation | F4: Totals
A5: ALACHUA | B5: 49872 | C5: 77766 | D5: 5335 | E5: 41042 | F5: 174015
A6: BAKER | B6: 12267 | C6: 2859 | D6: 412 | E6: 1844 | F6: 17382
A7: BAY | B7: 77391 | C7: 26288 | D7: 5049 | E7: 28265 | F7: 136993
A8: BRADFORD | B8: 10510 | C8: 3467 | D8: 426 | E8: 2033 | F8: 16436
A9: BREVARD | B9: 199884 | C9: 109317 | D9: 16655 | E9: 103918 | F9: 429774
A10: BROWARD | B10: 282973 | C10: 521878 | D10: 30634 | E10: 358404 | F10: 1193889
A11: CALHOUN | B11: 4739 | C11: 1943 | D11: 92 | E11: 749 | F11: 7523
A12: CHARLOTTE | B12: 78903 | C12: 28753 | D12: 5912 | E12: 32850 | F12: 146418
A13: CITRUS | B13: 68111 | C13: 20569 | D13: 4373 | E13: 22375 | F13: 115428
A14: CLAY | B14: 86481 | C14: 29823 | D14: 5345 | E14: 29051 | F14: 150700
A15: COLLIER | B15: 143703 | C15: 50197 | D15: 7690 | E15: 58378 | F15: 259968
A16: COLUMBIA | B16: 23700 | C16: 9467 | D16: 1197 | E16: 6140 | F16: 40504
... A72: TOTALS | B72: 5505326 | C72: 4117871 | D72: 443971 | E72: 3384837 | F72: 13452005

Sheet October
A1: Monthly Report - Voter Registration by Party Affiliation - October
A2: Data as of 10/31/2025
A3: ACTIVE REGISTERED VOTERS BY PARTY AFFILIATION BY COUNTY
A4: County | B4: Republican Party Of Florida | C4: Florida Democratic Party | D4: Minor Party | E4: No Party Affiliation | F4: Totals
A5: ALACHUA | B5: 49948 | C5: 77819 | D5: 5400 | E5: 41221 | F5: 174388
A6: BAKER | B6: 12234 | C6: 2842 | D6: 407 | E6: 1836 | F6: 17319
A7: BAY | B7: 72679 | C7: 23420 | D7: 4751 | E7: 23647 | F7: 124497
A8: BRADFORD | B8: 10521 | C8: 3467 | D8: 436 | E8: 2051 | F8: 16475
A9: BREVARD | B9: 200678 | C9: 109514 | D9: 16912 | E9: 104498 | F9: 431602
A10: BROWARD | B10: 283727 | C10: 521427 | D10: 31058 | E10: 358872 | F10: 1195084
A11: CALHOUN | B11: 4749 | C11: 1940 | D11: 95 | E11: 753 | F11: 7537
A12: CHARLOTTE | B12: 79501 | C12: 28833 | D12: 6047 | E12: 32966 | F12: 147347
A13: CITRUS | B13: 68484 | C13: 20548 | D13: 4457 | E13: 22418 | F13: 115907
A14: CLAY | B14: 86521 | C14: 29840 | D14: 5425 | E14: 29146 | F14: 150932
A15: COLLIER | B15: 143987 | C15: 50214 | D15: 7780 | E15: 58475 | F15: 260456
A16: COLUMBIA | B16: 23783 | C16: 9477 | D16: 1214 | E16: 6161 | F16: 40635
... A72: TOTALS | B72: 5509102 | C72: 4104990 | D72: 449849 | E72: 3374490 | F72: 13438431

Sheet November
A1: Monthly Report - Voter Registration by Party Affiliation - November
A2: Data as of 11/30/2025
A3: ACTIVE REGISTERED VOTERS BY PARTY AFFILIATION BY COUNTY
A4: County | B4: Republican Party Of Florida | C4: Florida Democratic Party | D4: Minor Party | E4: No Party Affiliation | F4: Totals
A5: ALACHUA | B5: 50029 | C5: 77877 | D5: 5474 | E5: 41290 | F5: 174670
A6: BAKER | B6: 12282 | C6: 2847 | D6: 407 | E6: 1843 | F6: 17379
A7: BAY | B7: 72949 | C7: 23492 | D7: 4822 | E7: 23717 | F7: 124980
A8: BRADFORD | B8: 10533 | C8: 3483 | D8: 453 | E8: 2050 | F8: 16519
A9: BREVARD | B9: 201228 | C9: 109688 | D9: 17135 | E9: 104949 | F9: 433000
A10: BROWARD | B10: 284190 | C10: 521401 | D10: 31270 | E10: 359449 | F10: 1196310
A11: CALHOUN | B11: 4761 | C11: 1938 | D11: 98 | E11: 755 | F11: 7552
A12: CHARLOTTE | B12: 79974 | C12: 28913 | D12: 6199 | E12: 33071 | F12: 148157
A13: CITRUS | B13: 68815 | C13: 20577 | D13: 4561 | E13: 22434 | F13: 116387
A14: CLAY | B14: 86739 | C14: 29911 | D14: 5494 | E14: 29209 | F14: 151353
A15: COLLIER | B15: 144106 | C15: 50179 | D15: 7871 | E15: 58460 | F15: 260616
A16: COLUMBIA | B16: 23810 | C16: 9495 | D16: 1233 | E16: 6182 | F16: 40720
... A72: TOTALS | B72: 5522833 | C72: 4108884 | D72: 455725 | E72: 3381443 | F72: 13468885

Sheet December
A1: Monthly Report - Voter Registration by Party Affiliation - December
A2: Data as of 12/31/2025
A3: ACTIVE REGISTERED VOTERS BY PARTY AFFILIATION BY COUNTY
A4: County | B4: Republican Party Of Florida | C4: Florida Democratic Party | D4: Minor Party | E4: No Party Affiliation | F4: Totals
A5: ALACHUA | B5: 47605 | C5: 72535 | D5: 5243 | E5: 36647 | F5: 162030
A6: BAKER | B6: 12321 | C6: 2852 | D6: 420 | E6: 1862 | F6: 17455
A7: BAY | B7: 73223 | C7: 23521 | D7: 4902 | E7: 23806 | F7: 125452
A8: BRADFORD | B8: 10568 | C8: 3484 | D8: 457 | E8: 2056 | F8: 16565
A9: BREVARD | B9: 201713 | C9: 109847 | D9: 17337 | E9: 105365 | F9: 434262
A10: BROWARD | B10: 263498 | C10: 461220 | D10: 28556 | E10: 308727 | F10: 1062001
A11: CALHOUN | B11: 4770 | C11: 1931 | D11: 99 | E11: 760 | F11: 7560
A12: CHARLOTTE | B12: 80445 | C12: 29002 | D12: 6305 | E12: 33202 | F12: 148954
A13: CITRUS | B13: 69057 | C13: 20566 | D13: 4656 | E13: 22444 | F13: 116723
A14: CLAY | B14: 86930 | C14: 30041 | D14: 5579 | E14: 29298 | F14: 151848
A15: COLLIER | B15: 144768 | C15: 50327 | D15: 7993 | E15: 58660 | F15: 261748
A16: COLUMBIA | B16: 23836 | C16: 9499 | D16: 1255 | E16: 6190 | F16: 40780
... A72: TOTALS | B72: 5509354 | C72: 4044390 | D72: 457841 | E72: 3329329 | F72: 13340914

Sheet NetPriorDecToJan
A1: Monthly Report - Net Activity by Party Affiliation - December to January
A2: Data comparison between 12/31/2024 - 01/31/2025
A3: ACTIVE REGISTERED VOTERS BY PARTY AFFILIATION BY COUNTY
A4: County | B4: Republican Party Of Florida | C4: Florida Democratic Party | D4: Minor Party | E4: No Party Affiliation | F4: Totals
A5: Alachua | B5: =[1]January!B5-[1]PriorDecember!B5 -> 57 | C5: =[1]January!C5-[1]PriorDecember!C5 -> -257 | D5: =[1]January!D5-[1]PriorDecember!D5 -> 71 | E5: =[1]January!E5-[1]PriorDecember!E5 -> 10 | F5: =SUM(B5:E5) -> -119
A6: Baker | B6: =[1]January!B6-[1]PriorDecember!B6 -> 54 | C6: =[1]January!C6-[1]PriorDecember!C6 -> -11 | D6: =[1]January!D6-[1]PriorDecember!D6 -> 8 | E6: =[1]January!E6-[1]PriorDecember!E6 -> 19 | F6: =SUM(B6:E6) -> 70
A7: Bay | B7: =[1]January!B7-[1]PriorDecember!B7 -> 296 | C7: =[1]January!C7-[1]PriorDecember!C7 -> -24 | D7: =[1]January!D7-[1]PriorDecember!D7 -> 78 | E7: =[1]January!E7-[1]PriorDecember!E7 -> 28 | F7: =SUM(B7:E7) -> 378
A8: Bradford | B8: =[1]January!B8-[1]PriorDecember!B8 -> 40 | C8: =[1]January!C8-[1]PriorDecember!C8 -> 7 | D8: =[1]January!D8-[1]PriorDecember!D8 -> -6 | E8: =[1]January!E8-[1]PriorDecember!E8 -> 13 | F8: =SUM(B8:E8) -> 54
A9: Brevard | B9: =[1]January!B9-[1]PriorDecember!B9 -> -417 | C9: =[1]January!C9-[1]PriorDecember!C9 -> -917 | D9: =[1]January!D9-[1]PriorDecember!D9 -> 39 | E9: =[1]January!E9-[1]PriorDecember!E9 -> -359 | F9: =SUM(B9:E9) -> -1654
A10: Broward | B10: =[1]January!B10-[1]PriorDecember!B10 -> -347 | C10: =[1]January!C10-[1]PriorDecember!C10 -> -2171 | D10: =[1]January!D10-[1]PriorDecember!D10 -> 70 | E10: =[1]January!E10-[1]PriorDecember!E10 -> -712 | F10: =SUM(B10:E10) -> -3160
A11: Calhoun | B11: =[1]January!B11-[1]PriorDecember!B11 -> -7 | C11: =[1]January!C11-[1]PriorDecember!C11 -> -21 | D11: =[1]January!D11-[1]PriorDecember!D11 -> 1 | E11: =[1]January!E11-[1]PriorDecember!E11 -> 1 | F11: =SUM(B11:E11) -> -26
A12: Charlotte | B12: =[1]January!B12-[1]PriorDecember!B12 -> -811 | C12: =[1]January!C12-[1]PriorDecember!C12 -> -671 | D12: =[1]January!D12-[1]PriorDecember!D12 -> -27 | E12: =[1]January!E12-[1]PriorDecember!E12 -> -847 | F12: =SUM(B12:E12) -> -2356
A13: Citrus | B13: =[1]January!B13-[1]PriorDecember!B13 -> 261 | C13: =[1]January!C13-[1]PriorDecember!C13 -> -17 | D13: =[1]January!D13-[1]PriorDecember!D13 -> -42 | E13: =[1]January!E13-[1]PriorDecember!E13 -> 162 | F13: =SUM(B13:E13) -> 364
A14: Clay | B14: =[1]January!B14-[1]PriorDecember!B14 -> 199 | C14: =[1]January!C14-[1]PriorDecember!C14 -> 28 | D14: =[1]January!D14-[1]PriorDecember!D14 -> -196 | E14: =[1]January!E14-[1]PriorDecember!E14 -> 292 | F14: =SUM(B14:E14) -> 323
A15: Collier | B15: =[1]January!B15-[1]PriorDecember!B15 -> 499 | C15: =[1]January!C15-[1]PriorDecember!C15 -> 47 | D15: =[1]January!D15-[1]PriorDecember!D15 -> -152 | E15: =[1]January!E15-[1]PriorDecember!E15 -> 394 | F15: =SUM(B15:E15) -> 788
A16: Columbia | B16: =[1]January!B16-[1]PriorDecember!B16 -> 62 | C16: =[1]January!C16-[1]PriorDecember!C16 -> -18 | D16: =[1]January!D16-[1]PriorDecember!D16 -> 19 | E16: =[1]January!E16-[1]PriorDecember!E16 -> 20 | F16: =SUM(B16:E16) -> 83
... A71: Washington | B71: =[1]January!B71-[1]PriorDecember!B71 -> 74 | C71: =[1]January!C71-[1]PriorDecember!C71 -> -7 | D71: =[1]January!D71-[1]PriorDecember!D71 -> 7 | E71: =[1]January!E71-[1]PriorDecember!E71 -> 11 | F71: =SUM(B71:E71) -> 85
A72: TOTALS | B72: =SUM(B5:B71) -> 7198 | C72: =SUM(C5:C71) -> -16228 | D72: =SUM(D5:D71) -> -108 | E72: =SUM(E5:E71) -> -574 | F72: =SUM(F5:F71) -> -9712

Sheet NetJanToFeb
A1: Monthly Report - Net Activity by Party Affiliation - January to February
A2: Data comparison between 01/31/2025 - 02/28/2025
A3: ACTIVE REGISTERED VOTERS BY PARTY AFFILIATION BY COUNTY
A4: County | B4: Republican Party Of Florida | C4: Florida Democratic Party | D4: Minor Party | E4: No Party Affiliation | F4: Totals
A5: Alachua | B5: =February!B5-January!B5 -> -62 | C5: =February!C5-January!C5 -> -445 | D5: =February!D5-January!D5 -> -185 | E5: =February!E5-January!E5 -> 112 | F5: =SUM(B5:E5) -> -580
A6: Baker | B6: =February!B6-January!B6 -> 31 | C6: =February!C6-January!C6 -> -4 | D6: =February!D6-January!D6 -> -13 | E6: =February!E6-January!E6 -> 18 | F6: =SUM(B6:E6) -> 32
A7: Bay | B7: =February!B7-January!B7 -> 221 | C7: =February!C7-January!C7 -> -13 | D7: =February!D7-January!D7 -> -168 | E7: =February!E7-January!E7 -> 264 | F7: =SUM(B7:E7) -> 304
A8: Bradford | B8: =February!B8-January!B8 -> 25 | C8: =February!C8-January!C8 -> -4 | D8: =February!D8-January!D8 -> 10 | E8: =February!E8-January!E8 -> -3 | F8: =SUM(B8:E8) -> 28
A9: Brevard | B9: =February!B9-January!B9 -> 324 | C9: =February!C9-January!C9 -> -146 | D9: =February!D9-January!D9 -> -446 | E9: =February!E9-January!E9 -> 773 | F9: =SUM(B9:E9) -> 505
A10: Broward | B10: =February!B10-January!B10 -> 1598 | C10: =February!C10-January!C10 -> 763 | D10: =February!D10-January!D10 -> -605 | E10: =February!E10-January!E10 -> 3186 | F10: =SUM(B10:E10) -> 4942
A11: Calhoun | B11: =February!B11-January!B11 -> -237 | C11: =February!C11-January!C11 -> -394 | D11: =February!D11-January!D11 -> -5 | E11: =February!E11-January!E11 -> -210 | F11: =SUM(B11:E11) -> -846
A12: Charlotte | B12: =February!B12-January!B12 -> 485 | C12: =February!C12-January!C12 -> 17 | D12: =February!D12-January!D12 -> -152 | E12: =February!E12-January!E12 -> 308 | F12: =SUM(B12:E12) -> 658
A13: Citrus | B13: =February!B13-January!B13 -> -3118 | C13: =February!C13-January!C13 -> -1763 | D13: =February!D13-January!D13 -> -137 | E13: =February!E13-January!E13 -> -3149 | F13: =SUM(B13:E13) -> -8167
A14: Clay | B14: =February!B14-January!B14 -> -239 | C14: =February!C14-January!C14 -> -222 | D14: =February!D14-January!D14 -> 26 | E14: =February!E14-January!E14 -> -278 | F14: =SUM(B14:E14) -> -713
A15: Collier | B15: =February!B15-January!B15 -> 486 | C15: =February!C15-January!C15 -> 44 | D15: =February!D15-January!D15 -> 120 | E15: =February!E15-January!E15 -> 55 | F15: =SUM(B15:E15) -> 705
A16: Columbia | B16: =February!B16-January!B16 -> 65 | C16: =February!C16-January!C16 -> -4 | D16: =February!D16-January!D16 -> 15 | E16: =February!E16-January!E16 -> -11 | F16: =SUM(B16:E16) -> 65
... A71: Washington | B71: =February!B71-January!B71 -> 60 | C71: =February!C71-January!C71 -> 11 | D71: =February!D71-January!D71 -> 1 | E71: =February!E71-January!E71 -> 24 | F71: =SUM(B71:E71) -> 96
A72: TOTALS | B72: =SUM(B5:B71) -> -7357 | C72: =SUM(C5:C71) -> -25708 | D72: =SUM(D5:D71) -> -6460 | E72: =SUM(E5:E71) -> -12841 | F72: =SUM(B72:E72) -> -52366

Sheet NetFebToMar
A1: Monthly Report - Net Activity by Party Affiliation - Feburary to March
A2: Data comparison between 02/28/2025 - 03/31/2025
A3: ACTIVE REGISTERED VOTERS BY PARTY AFFILIATION BY COUNTY
A4: County | B4: Republican Party Of Florida | C4: Florida Democratic Party | D4: Minor Party | E4: No Party Affiliation | F4: Totals
A5: Alachua | B5: =[1]March!B5-[1]February!B5 -> 45 | C5: =[1]March!C5-[1]February!C5 -> -86 | D5: =[1]March!D5-[1]February!D5 -> 77 | E5: =[1]March!E5-[1]February!E5 -> 95 | F5: =[1]March!F5-[1]February!F5 -> 131
A6: Baker | B6: =[1]March!B6-[1]February!B6 -> -8 | C6: =[1]March!C6-[1]February!C6 -> -22 | D6: =[1]March!D6-[1]February!D6 -> -3 | E6: =[1]March!E6-[1]February!E6 -> -14 | F6: =[1]March!F6-[1]February!F6 -> -47
A7: Bay | B7: =[1]March!B7-[1]February!B7 -> 311 | C7: =[1]March!C7-[1]February!C7 -> 54 | D7: =[1]March!D7-[1]February!D7 -> 107 | E7: =[1]March!E7-[1]February!E7 -> 54 | F7: =[1]March!F7-[1]February!F7 -> 526
A8: Bradford | B8: =[1]March!B8-[1]February!B8 -> -60 | C8: =[1]March!C8-[1]February!C8 -> -49 | D8: =[1]March!D8-[1]February!D8 -> -3 | E8: =[1]March!E8-[1]February!E8 -> -28 | F8: =[1]March!F8-[1]February!F8 -> -140
A9: Brevard | B9: =[1]March!B9-[1]February!B9 -> -281 | C9: =[1]March!C9-[1]February!C9 -> -654 | D9: =[1]March!D9-[1]February!D9 -> 51 | E9: =[1]March!E9-[1]February!E9 -> -599 | F9: =[1]March!F9-[1]February!F9 -> -1483
A10: Broward | B10: =[1]March!B10-[1]February!B10 -> 852 | C10: =[1]March!C10-[1]February!C10 -> -111 | D10: =[1]March!D10-[1]February!D10 -> 379 | E10: =[1]March!E10-[1]February!E10 -> 1281 | F10: =[1]March!F10-[1]February!F10 -> 2401
A11: Calhoun | B11: =[1]March!B11-[1]February!B11 -> 7 | C11: =[1]March!C11-[1]February!C11 -> -11 | D11: =[1]March!D11-[1]February!D11 -> 0 | E11: =[1]March!E11-[1]February!E11 -> 8 | F11: =[1]March!F11-[1]February!F11 -> 4
A12: Charlotte | B12: =[1]March!B12-[1]February!B12 -> 373 | C12: =[1]March!C12-[1]February!C12 -> 12 | D12: =[1]March!D12-[1]February!D12 -> 73 | E12: =[1]March!E12-[1]February!E12 -> 113 | F12: =[1]March!F12-[1]February!F12 -> 571
A13: Citrus | B13: =[1]March!B13-[1]February!B13 -> -90 | C13: =[1]March!C13-[1]February!C13 -> -143 | D13: =[1]March!D13-[1]February!D13 -> 47 | E13: =[1]March!E13-[1]February!E13 -> -62 | F13: =[1]March!F13-[1]February!F13 -> -248
A14: Clay | B14: =[1]March!B14-[1]February!B14 -> 230 | C14: =[1]March!C14-[1]February!C14 -> 106 | D14: =[1]March!D14-[1]February!D14 -> 94 | E14: =[1]March!E14-[1]February!E14 -> 70 | F14: =[1]March!F14-[1]February!F14 -> 500
A15: Collier | B15: =[1]March!B15-[1]February!B15 -> 170 | C15: =[1]March!C15-[1]February!C15 -> -144 | D15: =[1]March!D15-[1]February!D15 -> 121 | E15: =[1]March!E15-[1]February!E15 -> -58 | F15: =[1]March!F15-[1]February!F15 -> 89
A16: Columbia | B16: =[1]March!B16-[1]February!B16 -> 85 | C16: =[1]March!C16-[1]February!C16 -> 3 | D16: =[1]March!D16-[1]February!D16 -> -50 | E16: =[1]March!E16-[1]February!E16 -> 123 | F16: =[1]March!F16-[1]February!F16 -> 161
... A71: Washington | B71: =[1]March!B71-[1]February!B71 -> 52 | C71: =[1]March!C71-[1]February!C71 -> -9 | D71: =[1]March!D71-[1]February!D71 -> 5 | E71: =[1]March!E71-[1]February!E71 -> 12 | F71: =[1]March!F71-[1]February!F71 -> 60
A72: TOTALS | B72: =SUM(B5:B71) -> 28 | C72: =SUM(C5:C71) -> -12996 | D72: =SUM(D5:D71) -> 4259 | E72: =SUM(E5:E71) -> -6084 | F72: =SUM(F5:F71) -> -14793

Sheet NetMarToApr
A1: Monthly Report - Net Activity by Party Affiliation - March to April
A2: Data comparison between 03/31/2025 - 4/30/2025
A3: ACTIVE REGISTERED VOTERS BY PARTY AFFILIATION BY COUNTY
A4: County | B4: Republican Party Of Florida | C4: Florida Democratic Party | D4: Minor Party | E4: No Party Affiliation | F4: Totals
A5: Alachua | B5: =[1]April!B5-[1]March!B5 -> 125 | C5: =[1]April!C5-[1]March!C5 -> 40 | D5: =[1]April!D5-[1]March!D5 -> 47 | E5: =[1]April!E5-[1]March!E5 -> 148 | F5: =[1]April!F5-[1]March!F5 -> 360
A6: Baker | B6: =[1]April!B6-[1]March!B6 -> 33 | C6: =[1]April!C6-[1]March!C6 -> -10 | D6: =[1]April!D6-[1]March!D6 -> 4 | E6: =[1]April!E6-[1]March!E6 -> -1 | F6: =[1]April!F6-[1]March!F6 -> 26
A7: Bay | B7: =[1]April!B7-[1]March!B7 -> 340 | C7: =[1]April!C7-[1]March!C7 -> 31 | D7: =[1]April!D7-[1]March!D7 -> 67 | E7: =[1]April!E7-[1]March!E7 -> 85 | F7: =[1]April!F7-[1]March!F7 -> 523
A8: Bradford | B8: =[1]April!B8-[1]March!B8 -> -19 | C8: =[1]April!C8-[1]March!C8 -> -57 | D8: =[1]April!D8-[1]March!D8 -> -3 | E8: =[1]April!E8-[1]March!E8 -> -22 | F8: =[1]April!F8-[1]March!F8 -> -101
A9: Brevard | B9: =[1]April!B9-[1]March!B9 -> 430 | C9: =[1]April!C9-[1]March!C9 -> -21 | D9: =[1]April!D9-[1]March!D9 -> 168 | E9: =[1]April!E9-[1]March!E9 -> 243 | F9: =[1]April!F9-[1]March!F9 -> 820
A10: Broward | B10: =[1]April!B10-[1]March!B10 -> 706 | C10: =[1]April!C10-[1]March!C10 -> -87 | D10: =[1]April!D10-[1]March!D10 -> 250 | E10: =[1]April!E10-[1]March!E10 -> 1538 | F10: =[1]April!F10-[1]March!F10 -> 2407
A11: Calhoun | B11: =[1]April!B11-[1]March!B11 -> 17 | C11: =[1]April!C11-[1]March!C11 -> 3 | D11: =[1]April!D11-[1]March!D11 -> 1 | E11: =[1]April!E11-[1]March!E11 -> 12 | F11: =[1]April!F11-[1]March!F11 -> 33
A12: Charlotte | B12: =[1]April!B12-[1]March!B12 -> -3172 | C12: =[1]April!C12-[1]March!C12 -> -2314 | D12: =[1]April!D12-[1]March!D12 -> -307 | E12: =[1]April!E12-[1]March!E12 -> -4096 | F12: =[1]April!F12-[1]March!F12 -> -9889
A13: Citrus | B13: =[1]April!B13-[1]March!B13 -> 231 | C13: =[1]April!C13-[1]March!C13 -> 43 | D13: =[1]April!D13-[1]March!D13 -> 73 | E13: =[1]April!E13-[1]March!E13 -> 78 | F13: =[1]April!F13-[1]March!F13 -> 425
A14: Clay | B14: =[1]April!B14-[1]March!B14 -> -206 | C14: =[1]April!C14-[1]March!C14 -> -67 | D14: =[1]April!D14-[1]March!D14 -> -2 | E14: =[1]April!E14-[1]March!E14 -> -194 | F14: =[1]April!F14-[1]March!F14 -> -469
A15: Collier | B15: =[1]April!B15-[1]March!B15 -> -3647 | C15: =[1]April!C15-[1]March!C15 -> -3749 | D15: =[1]April!D15-[1]March!D15 -> -160 | E15: =[1]April!E15-[1]March!E15 -> -4807 | F15: =[1]April!F15-[1]March!F15 -> -12363
A16: Columbia | B16: =[1]April!B16-[1]March!B16 -> 85 | C16: =[1]April!C16-[1]March!C16 -> 24 | D16: =[1]April!D16-[1]March!D16 -> 13 | E16: =[1]April!E16-[1]March!E16 -> 24 | F16: =[1]April!F16-[1]March!F16 -> 146
... A71: Washington | B71: =[1]April!B71-[1]March!B71 -> -18 | C71: =[1]April!C71-[1]March!C71 -> -11 | D71: =[1]April!D71-[1]March!D71 -> -1 | E71: =[1]April!E71-[1]March!E71 -> -5 | F71: =[1]April!F71-[1]March!F71 -> -35
A72: TOTALS | B72: =SUM(B5:B71) -> -57314 | C72: =SUM(C5:C71) -> -95517 | D72: =SUM(D5:D71) -> -3186 | E72: =SUM(E5:E71) -> -106703 | F72: =SUM(F5:F71) -> -262720

Sheet NetAprToMay
A1: Monthly Report - Net Activity by Party Affiliation - April to May
A2: Data comparison between 04/30/2025 - 5/31/2025
A3: ACTIVE REGISTERED VOTERS BY PARTY AFFILIATION BY COUNTY
A4: County | B4: Republican Party Of Florida | C4: Florida Democratic Party | D4: Minor Party | E4: No Party Affiliation | F4: Totals
A5: Alachua | B5: =[1]May!B5-[1]April!B5 -> -179 | C5: =[1]May!C5-[1]April!C5 -> -432 | D5: =[1]May!D5-[1]April!D5 -> 2 | E5: =[1]May!E5-[1]April!E5 -> -346 | F5: =[1]May!F5-[1]April!F5 -> -955
A6: Baker | B6: =[1]May!B6-[1]April!B6 -> -485 | C6: =[1]May!C6-[1]April!C6 -> -426 | D6: =[1]May!D6-[1]April!D6 -> -15 | E6: =[1]May!E6-[1]April!E6 -> -339 | F6: =[1]May!F6-[1]April!F6 -> -1265
A7: Bay | B7: =[1]May!B7-[1]April!B7 -> 336 | C7: =[1]May!C7-[1]April!C7 -> 63 | D7: =[1]May!D7-[1]April!D7 -> 87 | E7: =[1]May!E7-[1]April!E7 -> 54 | F7: =[1]May!F7-[1]April!F7 -> 540
A8: Bradford | B8: =[1]May!B8-[1]April!B8 -> 15 | C8: =[1]May!C8-[1]April!C8 -> -10 | D8: =[1]May!D8-[1]April!D8 -> 7 | E8: =[1]May!E8-[1]April!E8 -> -11 | F8: =[1]May!F8-[1]April!F8 -> 1
A9: Brevard | B9: =[1]May!B9-[1]April!B9 -> 624 | C9: =[1]May!C9-[1]April!C9 -> 183 | D9: =[1]May!D9-[1]April!D9 -> 215 | E9: =[1]May!E9-[1]April!E9 -> 464 | F9: =[1]May!F9-[1]April!F9 -> 1486
A10: Broward | B10: =[1]May!B10-[1]April!B10 -> 442 | C10: =[1]May!C10-[1]April!C10 -> 60 | D10: =[1]May!D10-[1]April!D10 -> 285 | E10: =[1]May!E10-[1]April!E10 -> 1361 | F10: =[1]May!F10-[1]April!F10 -> 2148
A11: Calhoun | B11: =[1]May!B11-[1]April!B11 -> 10 | C11: =[1]May!C11-[1]April!C11 -> 2 | D11: =[1]May!D11-[1]April!D11 -> 1 | E11: =[1]May!E11-[1]April!E11 -> 8 | F11: =[1]May!F11-[1]April!F11 -> 21
A12: Charlotte | B12: =[1]May!B12-[1]April!B12 -> 447 | C12: =[1]May!C12-[1]April!C12 -> 85 | D12: =[1]May!D12-[1]April!D12 -> 88 | E12: =[1]May!E12-[1]April!E12 -> 149 | F12: =[1]May!F12-[1]April!F12 -> 769
A13: Citrus | B13: =[1]May!B13-[1]April!B13 -> 254 | C13: =[1]May!C13-[1]April!C13 -> 45 | D13: =[1]May!D13-[1]April!D13 -> 73 | E13: =[1]May!E13-[1]April!E13 -> 54 | F13: =[1]May!F13-[1]April!F13 -> 426
A14: Clay | B14: =[1]May!B14-[1]April!B14 -> -19 | C14: =[1]May!C14-[1]April!C14 -> -16 | D14: =[1]May!D14-[1]April!D14 -> 53 | E14: =[1]May!E14-[1]April!E14 -> -109 | F14: =[1]May!F14-[1]April!F14 -> -91
A15: Collier | B15: =[1]May!B15-[1]April!B15 -> 381 | C15: =[1]May!C15-[1]April!C15 -> 88 | D15: =[1]May!D15-[1]April!D15 -> 104 | E15: =[1]May!E15-[1]April!E15 -> 87 | F15: =[1]May!F15-[1]April!F15 -> 660
A16: Columbia | B16: =[1]May!B16-[1]April!B16 -> -1336 | C16: =[1]May!C16-[1]April!C16 -> -975 | D16: =[1]May!D16-[1]April!D16 -> -88 | E16: =[1]May!E16-[1]April!E16 -> -1162 | F16: =[1]May!F16-[1]April!F16 -> -3561
... A71: Washington | B71: =[1]May!B71-[1]April!B71 -> 11 | C71: =[1]May!C71-[1]April!C71 -> 3 | D71: =[1]May!D71-[1]April!D71 -> 6 | E71: =[1]May!E71-[1]April!E71 -> 3 | F71: =[1]May!F71-[1]April!F71 -> 23
A72: TOTALS | B72: =SUM(B5:B71) -> -56440 | C72: =SUM(C5:C71) -> -118213 | D72: =SUM(D5:D71) -> 841 | E72: =SUM(E5:E71) -> -127079 | F72: =SUM(F5:F71) -> -300891

Sheet NetMayToJun
A1: Monthly Report - Net Activity by Party Affiliation - May to June
A2: Data comparison between 05/31/2025 - 06/30/2025
A3: ACTIVE REGISTERED VOTERS BY PARTY AFFILIATION BY COUNTY
A4: County | B4: Republican Party Of Florida | C4: Florida Democratic Party | D4: Minor Party | E4: No Party Affiliation | F4: Totals
A5: Alachua | B5: =[1]June!B5-[1]May!B5 -> 122 | C5: =[1]June!C5-[1]May!C5 -> 132 | D5: =[1]June!D5-[1]May!D5 -> 60 | E5: =[1]June!E5-[1]May!E5 -> 101 | F5: =[1]June!F5-[1]May!F5 -> 415
A6: Baker | B6: =[1]June!B6-[1]May!B6 -> -255 | C6: =[1]June!C6-[1]May!C6 -> -206 | D6: =[1]June!D6-[1]May!D6 -> -7 | E6: =[1]June!E6-[1]May!E6 -> -196 | F6: =[1]June!F6-[1]May!F6 -> -664
A7: Bay | B7: =[1]June!B7-[1]May!B7 -> -223 | C7: =[1]June!C7-[1]May!C7 -> -110 | D7: =[1]June!D7-[1]May!D7 -> 34 | E7: =[1]June!E7-[1]May!E7 -> -172 | F7: =[1]June!F7-[1]May!F7 -> -471
A8: Bradford | B8: =[1]June!B8-[1]May!B8 -> 22 | C8: =[1]June!C8-[1]May!C8 -> -2 | D8: =[1]June!D8-[1]May!D8 -> 4 | E8: =[1]June!E8-[1]May!E8 -> 3 | F8: =[1]June!F8-[1]May!F8 -> 27
A9: Brevard | B9: =[1]June!B9-[1]May!B9 -> 376 | C9: =[1]June!C9-[1]May!C9 -> 28 | D9: =[1]June!D9-[1]May!D9 -> 169 | E9: =[1]June!E9-[1]May!E9 -> 354 | F9: =[1]June!F9-[1]May!F9 -> 927
A10: Broward | B10: =[1]June!B10-[1]May!B10 -> 370 | C10: =[1]June!C10-[1]May!C10 -> 167 | D10: =[1]June!D10-[1]May!D10 -> 243 | E10: =[1]June!E10-[1]May!E10 -> 973 | F10: =[1]June!F10-[1]May!F10 -> 1753
A11: Calhoun | B11: =[1]June!B11-[1]May!B11 -> 4 | C11: =[1]June!C11-[1]May!C11 -> -6 | D11: =[1]June!D11-[1]May!D11 -> -1 | E11: =[1]June!E11-[1]May!E11 -> 7 | F11: =[1]June!F11-[1]May!F11 -> 4
A12: Charlotte | B12: =[1]June!B12-[1]May!B12 -> 422 | C12: =[1]June!C12-[1]May!C12 -> 47 | D12: =[1]June!D12-[1]May!D12 -> 95 | E12: =[1]June!E12-[1]May!E12 -> 123 | F12: =[1]June!F12-[1]May!F12 -> 687
A13: Citrus | B13: =[1]June!B13-[1]May!B13 -> 247 | C13: =[1]June!C13-[1]May!C13 -> 30 | D13: =[1]June!D13-[1]May!D13 -> 60 | E13: =[1]June!E13-[1]May!E13 -> 74 | F13: =[1]June!F13-[1]May!F13 -> 411
A14: Clay | B14: =[1]June!B14-[1]May!B14 -> -106 | C14: =[1]June!C14-[1]May!C14 -> -112 | D14: =[1]June!D14-[1]May!D14 -> 45 | E14: =[1]June!E14-[1]May!E14 -> -149 | F14: =[1]June!F14-[1]May!F14 -> -322
A15: Collier | B15: =[1]June!B15-[1]May!B15 -> 375 | C15: =[1]June!C15-[1]May!C15 -> 78 | D15: =[1]June!D15-[1]May!D15 -> 108 | E15: =[1]June!E15-[1]May!E15 -> 86 | F15: =[1]June!F15-[1]May!F15 -> 647
A16: Columbia | B16: =[1]June!B16-[1]May!B16 -> 71 | C16: =[1]June!C16-[1]May!C16 -> -12 | D16: =[1]June!D16-[1]May!D16 -> 21 | E16: =[1]June!E16-[1]May!E16 -> 31 | F16: =[1]June!F16-[1]May!F16 -> 111
... A71: Washington | B71: =[1]June!B71-[1]May!B71 -> 29 | C71: =[1]June!C71-[1]May!C71 -> -3 | D71: =[1]June!D71-[1]May!D71 -> 3 | E71: =[1]June!E71-[1]May!E71 -> 5 | F71: =[1]June!F71-[1]May!F71 -> 34
A72: TOTALS | B72: =SUM(B5:B71) -> -12517 | C72: =SUM(C5:C71) -> -18372 | D72: =SUM(D5:D71) -> 3864 | E72: =SUM(E5:E71) -> -18544 | F72: =SUM(F5:F71) -> -45569

Sheet NetJunToJul
A1: Monthly Report - Net Activity by Party Affiliation - June to July
A2: Data comparison between 06/30/2025 - 07/31/2025
A3: ACTIVE REGISTERED VOTERS BY PARTY AFFILIATION BY COUNTY
A4: County | B4: Republican Party Of Florida | C4: Florida Democratic Party | D4: Minor Party | E4: No Party Affiliation | F4: Totals
A5: Alachua | B5: =[1]July!B5-[1]June!B5 -> 122 | C5: =[1]July!C5-[1]June!C5 -> -6 | D5: =[1]July!D5-[1]June!D5 -> 67 | E5: =[1]July!E5-[1]June!E5 -> 104 | F5: =[1]July!F5-[1]June!F5 -> 287
A6: Baker | B6: =[1]July!B6-[1]June!B6 -> 0 | C6: =[1]July!C6-[1]June!C6 -> -65 | D6: =[1]July!D6-[1]June!D6 -> 9 | E6: =[1]July!E6-[1]June!E6 -> -32 | F6: =[1]July!F6-[1]June!F6 -> -88
A7: Bay | B7: =[1]July!B7-[1]June!B7 -> 97 | C7: =[1]July!C7-[1]June!C7 -> -3 | D7: =[1]July!D7-[1]June!D7 -> 73 | E7: =[1]July!E7-[1]June!E7 -> -36 | F7: =[1]July!F7-[1]June!F7 -> 131
A8: Bradford | B8: =[1]July!B8-[1]June!B8 -> 5 | C8: =[1]July!C8-[1]June!C8 -> -9 | D8: =[1]July!D8-[1]June!D8 -> 11 | E8: =[1]July!E8-[1]June!E8 -> -2 | F8: =[1]July!F8-[1]June!F8 -> 5
A9: Brevard | B9: =[1]July!B9-[1]June!B9 -> -7615 | C9: =[1]July!C9-[1]June!C9 -> -7525 | D9: =[1]July!D9-[1]June!D9 -> -670 | E9: =[1]July!E9-[1]June!E9 -> -11416 | F9: =[1]July!F9-[1]June!F9 -> -27226
A10: Broward | B10: =[1]July!B10-[1]June!B10 -> 1094 | C10: =[1]July!C10-[1]June!C10 -> 113 | D10: =[1]July!D10-[1]June!D10 -> 570 | E10: =[1]July!E10-[1]June!E10 -> 1420 | F10: =[1]July!F10-[1]June!F10 -> 3197
A11: Calhoun | B11: =[1]July!B11-[1]June!B11 -> 14 | C11: =[1]July!C11-[1]June!C11 -> -1 | D11: =[1]July!D11-[1]June!D11 -> 1 | E11: =[1]July!E11-[1]June!E11 -> -1 | F11: =[1]July!F11-[1]June!F11 -> 13
A12: Charlotte | B12: =[1]July!B12-[1]June!B12 -> 451 | C12: =[1]July!C12-[1]June!C12 -> 42 | D12: =[1]July!D12-[1]June!D12 -> 76 | E12: =[1]July!E12-[1]June!E12 -> 66 | F12: =[1]July!F12-[1]June!F12 -> 635
A13: Citrus | B13: =[1]July!B13-[1]June!B13 -> 168 | C13: =[1]July!C13-[1]June!C13 -> -37 | D13: =[1]July!D13-[1]June!D13 -> 33 | E13: =[1]July!E13-[1]June!E13 -> -48 | F13: =[1]July!F13-[1]June!F13 -> 116
A14: Clay | B14: =[1]July!B14-[1]June!B14 -> -3465 | C14: =[1]July!C14-[1]June!C14 -> -2411 | D14: =[1]July!D14-[1]June!D14 -> -210 | E14: =[1]July!E14-[1]June!E14 -> -3834 | F14: =[1]July!F14-[1]June!F14 -> -9920
A15: Collier | B15: =[1]July!B15-[1]June!B15 -> 380 | C15: =[1]July!C15-[1]June!C15 -> 61 | D15: =[1]July!D15-[1]June!D15 -> 82 | E15: =[1]July!E15-[1]June!E15 -> 97 | F15: =[1]July!F15-[1]June!F15 -> 620
A16: Columbia | B16: =[1]July!B16-[1]June!B16 -> 80 | C16: =[1]July!C16-[1]June!C16 -> 32 | D16: =[1]July!D16-[1]June!D16 -> 25 | E16: =[1]July!E16-[1]June!E16 -> 55 | F16: =[1]July!F16-[1]June!F16 -> 192
... A71: Washington | B71: =[1]July!B71-[1]June!B71 -> 57 | C71: =[1]July!C71-[1]June!C71 -> 2 | D71: =[1]July!D71-[1]June!D71 -> 5 | E71: =[1]July!E71-[1]June!E71 -> 12 | F71: =[1]July!F71-[1]June!F71 -> 76
A72: TOTALS | B72: =SUM(B5:B71) -> -9857 | C72: =SUM(C5:C71) -> -19360 | D72: =SUM(D5:D71) -> 4274 | E72: =SUM(E5:E71) -> -22246 | F72: =SUM(F5:F71) -> -47189

Sheet NetJulToAug
A1: Monthly Report - Net Activity by Party Affiliation - July to August
A2: Data comparison between 07/31/2025 - 08/31/2025
A3: ACTIVE REGISTERED VOTERS BY PARTY AFFILIATION BY COUNTY
A4: County | B4: Republican Party Of Florida | C4: Florida Democratic Party | D4: Minor Party | E4: No Party Affiliation | F4: Totals
A5: Alachua | B5: =[1]August!B5-[1]July!B5 -> 132 | C5: =[1]August!C5-[1]July!C5 -> 90 | D5: =[1]August!D5-[1]July!D5 -> 21 | E5: =[1]August!E5-[1]July!E5 -> 126 | F5: =[1]August!F5-[1]July!F5 -> 369
A6: Baker | B6: =[1]August!B6-[1]July!B6 -> -25 | C6: =[1]August!C6-[1]July!C6 -> -18 | D6: =[1]August!D6-[1]July!D6 -> -3 | E6: =[1]August!E6-[1]July!E6 -> -12 | F6: =[1]August!F6-[1]July!F6 -> -58
A7: Bay | B7: =[1]August!B7-[1]July!B7 -> 352 | C7: =[1]August!C7-[1]July!C7 -> 27 | D7: =[1]August!D7-[1]July!D7 -> 55 | E7: =[1]August!E7-[1]July!E7 -> 40 | F7: =[1]August!F7-[1]July!F7 -> 474
A8: Bradford | B8: =[1]August!B8-[1]July!B8 -> 40 | C8: =[1]August!C8-[1]July!C8 -> -9 | D8: =[1]August!D8-[1]July!D8 -> 9 | E8: =[1]August!E8-[1]July!E8 -> 6 | F8: =[1]August!F8-[1]July!F8 -> 46
A9: Brevard | B9: =[1]August!B9-[1]July!B9 -> 951 | C9: =[1]August!C9-[1]July!C9 -> 242 | D9: =[1]August!D9-[1]July!D9 -> 190 | E9: =[1]August!E9-[1]July!E9 -> 514 | F9: =[1]August!F9-[1]July!F9 -> 1897
A10: Broward | B10: =[1]August!B10-[1]July!B10 -> 251 | C10: =[1]August!C10-[1]July!C10 -> -467 | D10: =[1]August!D10-[1]July!D10 -> 209 | E10: =[1]August!E10-[1]July!E10 -> 507 | F10: =[1]August!F10-[1]July!F10 -> 500
A11: Calhoun | B11: =[1]August!B11-[1]July!B11 -> -2 | C11: =[1]August!C11-[1]July!C11 -> -11 | D11: =[1]August!D11-[1]July!D11 -> 3 | E11: =[1]August!E11-[1]July!E11 -> 7 | F11: =[1]August!F11-[1]July!F11 -> -3
A12: Charlotte | B12: =[1]August!B12-[1]July!B12 -> 420 | C12: =[1]August!C12-[1]July!C12 -> 15 | D12: =[1]August!D12-[1]July!D12 -> 75 | E12: =[1]August!E12-[1]July!E12 -> 47 | F12: =[1]August!F12-[1]July!F12 -> 557
A13: Citrus | B13: =[1]August!B13-[1]July!B13 -> 259 | C13: =[1]August!C13-[1]July!C13 -> -16 | D13: =[1]August!D13-[1]July!D13 -> 45 | E13: =[1]August!E13-[1]July!E13 -> 35 | F13: =[1]August!F13-[1]July!F13 -> 323
A14: Clay | B14: =[1]August!B14-[1]July!B14 -> 406 | C14: =[1]August!C14-[1]July!C14 -> 151 | D14: =[1]August!D14-[1]July!D14 -> 104 | E14: =[1]August!E14-[1]July!E14 -> 189 | F14: =[1]August!F14-[1]July!F14 -> 850
A15: Collier | B15: =[1]August!B15-[1]July!B15 -> 348 | C15: =[1]August!C15-[1]July!C15 -> 73 | D15: =[1]August!D15-[1]July!D15 -> 91 | E15: =[1]August!E15-[1]July!E15 -> 141 | F15: =[1]August!F15-[1]July!F15 -> 653
A16: Columbia | B16: =[1]August!B16-[1]July!B16 -> 61 | C16: =[1]August!C16-[1]July!C16 -> 20 | D16: =[1]August!D16-[1]July!D16 -> 17 | E16: =[1]August!E16-[1]July!E16 -> 23 | F16: =[1]August!F16-[1]July!F16 -> 121
... A71: Washington | B71: =[1]August!B71-[1]July!B71 -> 50 | C71: =[1]August!C71-[1]July!C71 -> -2 | D71: =[1]August!D71-[1]July!D71 -> 5 | E71: =[1]August!E71-[1]July!E71 -> 6 | F71: =[1]August!F71-[1]July!F71 -> 59
A72: TOTALS | B72: =SUM(B5:B71) -> -4126 | C72: =SUM(C5:C71) -> -33396 | D72: =SUM(D5:D71) -> 3393 | E72: =SUM(E5:E71) -> -28575 | F72: =SUM(F5:F71) -> -62704

Sheet NetAugToSep
A1: Monthly Report - Net Activity by Party Affiliation - August to September
A2: Data comparison between 08/31/2025 - 09/30/2025
A3: ACTIVE REGISTERED VOTERS BY PARTY AFFILIATION BY COUNTY
A4: County | B4: Republican Party Of Florida | C4: Florida Democratic Party | D4: Minor Party | E4: No Party Affiliation | F4: Totals
A5: Alachua | B5: =[1]September!B5-[1]August!B5 -> 103 | C5: =[1]September!C5-[1]August!C5 -> -164 | D5: =[1]September!D5-[1]August!D5 -> 81 | E5: =[1]September!E5-[1]August!E5 -> 116 | F5: =[1]September!F5-[1]August!F5 -> 136
A6: Baker | B6: =[1]September!B6-[1]August!B6 -> 28 | C6: =[1]September!C6-[1]August!C6 -> 1 | D6: =[1]September!D6-[1]August!D6 -> 9 | E6: =[1]September!E6-[1]August!E6 -> 4 | F6: =[1]September!F6-[1]August!F6 -> 42
A7: Bay | B7: =[1]September!B7-[1]August!B7 -> 307 | C7: =[1]September!C7-[1]August!C7 -> -34 | D7: =[1]September!D7-[1]August!D7 -> 97 | E7: =[1]September!E7-[1]August!E7 -> 70 | F7: =[1]September!F7-[1]August!F7 -> 440
A8: Bradford | B8: =[1]September!B8-[1]August!B8 -> -746 | C8: =[1]September!C8-[1]August!C8 -> -742 | D8: =[1]September!D8-[1]August!D8 -> -10 | E8: =[1]September!E8-[1]August!E8 -> -596 | F8: =[1]September!F8-[1]August!F8 -> -2094
A9: Brevard | B9: =[1]September!B9-[1]August!B9 -> 993 | C9: =[1]September!C9-[1]August!C9 -> -6 | D9: =[1]September!D9-[1]August!D9 -> 193 | E9: =[1]September!E9-[1]August!E9 -> 575 | F9: =[1]September!F9-[1]August!F9 -> 1755
A10: Broward | B10: =[1]September!B10-[1]August!B10 -> 1662 | C10: =[1]September!C10-[1]August!C10 -> 336 | D10: =[1]September!D10-[1]August!D10 -> 586 | E10: =[1]September!E10-[1]August!E10 -> 1906 | F10: =[1]September!F10-[1]August!F10 -> 4490
A11: Calhoun | B11: =[1]September!B11-[1]August!B11 -> 16 | C11: =[1]September!C11-[1]August!C11 -> -8 | D11: =[1]September!D11-[1]August!D11 -> 3 | E11: =[1]September!E11-[1]August!E11 -> -3 | F11: =[1]September!F11-[1]August!F11 -> 8
A12: Charlotte | B12: =[1]September!B12-[1]August!B12 -> 506 | C12: =[1]September!C12-[1]August!C12 -> 34 | D12: =[1]September!D12-[1]August!D12 -> 80 | E12: =[1]September!E12-[1]August!E12 -> 15 | F12: =[1]September!F12-[1]August!F12 -> 635
A13: Citrus | B13: =[1]September!B13-[1]August!B13 -> 83 | C13: =[1]September!C13-[1]August!C13 -> -92 | D13: =[1]September!D13-[1]August!D13 -> 77 | E13: =[1]September!E13-[1]August!E13 -> -79 | F13: =[1]September!F13-[1]August!F13 -> -11
A14: Clay | B14: =[1]September!B14-[1]August!B14 -> 305 | C14: =[1]September!C14-[1]August!C14 -> 57 | D14: =[1]September!D14-[1]August!D14 -> 72 | E14: =[1]September!E14-[1]August!E14 -> 102 | F14: =[1]September!F14-[1]August!F14 -> 536
A15: Collier | B15: =[1]September!B15-[1]August!B15 -> 468 | C15: =[1]September!C15-[1]August!C15 -> -13 | D15: =[1]September!D15-[1]August!D15 -> 117 | E15: =[1]September!E15-[1]August!E15 -> 184 | F15: =[1]September!F15-[1]August!F15 -> 756
A16: Columbia | B16: =[1]September!B16-[1]August!B16 -> 59 | C16: =[1]September!C16-[1]August!C16 -> -8 | D16: =[1]September!D16-[1]August!D16 -> 17 | E16: =[1]September!E16-[1]August!E16 -> 23 | F16: =[1]September!F16-[1]August!F16 -> 91
... A71: Washington | B71: =[1]September!B71-[1]August!B71 -> 47 | C71: =[1]September!C71-[1]August!C71 -> -7 | D71: =[1]September!D71-[1]August!D71 -> 9 | E71: =[1]September!E71-[1]August!E71 -> 4 | F71: =[1]September!F71-[1]August!F71 -> 53
A72: TOTALS | B72: =SUM(B5:B71) -> 9809 | C72: =SUM(C5:C71) -> -22159 | D72: =SUM(D5:D71) -> 5717 | E72: =SUM(E5:E71) -> -2553 | F72: =SUM(F5:F71) -> -9186

Sheet NetSepToOct
A1: Monthly Report - Net Activity by Party Affiliation - September to October
A2: Data comparison between 09/30/2025 - 10/31/2025
A3: ACTIVE REGISTERED VOTERS BY PARTY AFFILIATION BY COUNTY
A4: County | B4: Republican Party Of Florida | C4: Florida Democratic Party | D4: Minor Party | E4: No Party Affiliation | F4: Totals
A5: Alachua | B5: =[1]October!B5-[1]September!B5 -> 76 | C5: =[1]October!C5-[1]September!C5 -> 53 | D5: =[1]October!D5-[1]September!D5 -> 65 | E5: =[1]October!E5-[1]September!E5 -> 179 | F5: =SUM(B5:E5) -> 373
A6: Baker | B6: =[1]October!B6-[1]September!B6 -> -33 | C6: =[1]October!C6-[1]September!C6 -> -17 | D6: =[1]October!D6-[1]September!D6 -> -5 | E6: =[1]October!E6-[1]September!E6 -> -8 | F6: =SUM(B6:E6) -> -63
A7: Bay | B7: =[1]October!B7-[1]September!B7 -> -4712 | C7: =[1]October!C7-[1]September!C7 -> -2868 | D7: =[1]October!D7-[1]September!D7 -> -298 | E7: =[1]October!E7-[1]September!E7 -> -4618 | F7: =SUM(B7:E7) -> -12496
A8: Bradford | B8: =[1]October!B8-[1]September!B8 -> 11 | C8: =[1]October!C8-[1]September!C8 -> 0 | D8: =[1]October!D8-[1]September!D8 -> 10 | E8: =[1]October!E8-[1]September!E8 -> 18 | F8: =SUM(B8:E8) -> 39
A9: Brevard | B9: =[1]October!B9-[1]September!B9 -> 794 | C9: =[1]October!C9-[1]September!C9 -> 197 | D9: =[1]October!D9-[1]September!D9 -> 257 | E9: =[1]October!E9-[1]September!E9 -> 580 | F9: =SUM(B9:E9) -> 1828
A10: Broward | B10: =[1]October!B10-[1]September!B10 -> 754 | C10: =[1]October!C10-[1]September!C10 -> -451 | D10: =[1]October!D10-[1]September!D10 -> 424 | E10: =[1]October!E10-[1]September!E10 -> 468 | F10: =SUM(B10:E10) -> 1195
A11: Calhoun | B11: =[1]October!B11-[1]September!B11 -> 10 | C11: =[1]October!C11-[1]September!C11 -> -3 | D11: =[1]October!D11-[1]September!D11 -> 3 | E11: =[1]October!E11-[1]September!E11 -> 4 | F11: =SUM(B11:E11) -> 14
A12: Charlotte | B12: =[1]October!B12-[1]September!B12 -> 598 | C12: =[1]October!C12-[1]September!C12 -> 80 | D12: =[1]October!D12-[1]September!D12 -> 135 | E12: =[1]October!E12-[1]September!E12 -> 116 | F12: =SUM(B12:E12) -> 929
A13: Citrus | B13: =[1]October!B13-[1]September!B13 -> 373 | C13: =[1]October!C13-[1]September!C13 -> -21 | D13: =[1]October!D13-[1]September!D13 -> 84 | E13: =[1]October!E13-[1]September!E13 -> 43 | F13: =SUM(B13:E13) -> 479
A14: Clay | B14: =[1]October!B14-[1]September!B14 -> 40 | C14: =[1]October!C14-[1]September!C14 -> 17 | D14: =[1]October!D14-[1]September!D14 -> 80 | E14: =[1]October!E14-[1]September!E14 -> 95 | F14: =SUM(B14:E14) -> 232
A15: Collier | B15: =[1]October!B15-[1]September!B15 -> 284 | C15: =[1]October!C15-[1]September!C15 -> 17 | D15: =[1]October!D15-[1]September!D15 -> 90 | E15: =[1]October!E15-[1]September!E15 -> 97 | F15: =SUM(B15:E15) -> 488
A16: Columbia | B16: =[1]October!B16-[1]September!B16 -> 83 | C16: =[1]October!C16-[1]September!C16 -> 10 | D16: =[1]October!D16-[1]September!D16 -> 17 | E16: =[1]October!E16-[1]September!E16 -> 21 | F16: =SUM(B16:E16) -> 131
... A71: Washington | B71: =[1]October!B71-[1]September!B71 -> 28 | C71: =[1]October!C71-[1]September!C71 -> -1 | D71: =[1]October!D71-[1]September!D71 -> 11 | E71: =[1]October!E71-[1]September!E71 -> 4 | F71: =SUM(B71:E71) -> 42
A72: TOTALS | B72: =SUM(B5:B71) -> 3776 | C72: =SUM(C5:C71) -> -12881 | D72: =SUM(D5:D71) -> 5878 | E72: =SUM(E5:E71) -> -10347 | F72: =SUM(F5:F71) -> -13574

Sheet NetOctToNov
A1: Monthly Report - Net Activity by Party Affiliation - October to November
A2: Data comparison between 10/31/2025 - 11/30/2025
A3: ACTIVE REGISTERED VOTERS BY PARTY AFFILIATION BY COUNTY
A4: County | B4: Republican Party Of Florida | C4: Florida Democratic Party | D4: Minor Party | E4: No Party Affiliation | F4: Totals
A5: Alachua | B5: =[1]November!B5-[1]October!B5 -> 81 | C5: =[1]November!C5-[1]October!C5 -> 58 | D5: =[1]November!D5-[1]October!D5 -> 74 | E5: =[1]November!E5-[1]October!E5 -> 69 | F5: =SUM(B5:E5) -> 282
A6: Baker | B6: =[1]November!B6-[1]October!B6 -> 48 | C6: =[1]November!C6-[1]October!C6 -> 5 | D6: =[1]November!D6-[1]October!D6 -> 0 | E6: =[1]November!E6-[1]October!E6 -> 7 | F6: =SUM(B6:E6) -> 60
A7: Bay | B7: =[1]November!B7-[1]October!B7 -> 270 | C7: =[1]November!C7-[1]October!C7 -> 72 | D7: =[1]November!D7-[1]October!D7 -> 71 | E7: =[1]November!E7-[1]October!E7 -> 70 | F7: =SUM(B7:E7) -> 483
A8: Bradford | B8: =[1]November!B8-[1]October!B8 -> 12 | C8: =[1]November!C8-[1]October!C8 -> 16 | D8: =[1]November!D8-[1]October!D8 -> 17 | E8: =[1]November!E8-[1]October!E8 -> -1 | F8: =SUM(B8:E8) -> 44
A9: Brevard | B9: =[1]November!B9-[1]October!B9 -> 550 | C9: =[1]November!C9-[1]October!C9 -> 174 | D9: =[1]November!D9-[1]October!D9 -> 223 | E9: =[1]November!E9-[1]October!E9 -> 451 | F9: =SUM(B9:E9) -> 1398
A10: Broward | B10: =[1]November!B10-[1]October!B10 -> 463 | C10: =[1]November!C10-[1]October!C10 -> -26 | D10: =[1]November!D10-[1]October!D10 -> 212 | E10: =[1]November!E10-[1]October!E10 -> 577 | F10: =SUM(B10:E10) -> 1226
A11: Calhoun | B11: =[1]November!B11-[1]October!B11 -> 12 | C11: =[1]November!C11-[1]October!C11 -> -2 | D11: =[1]November!D11-[1]October!D11 -> 3 | E11: =[1]November!E11-[1]October!E11 -> 2 | F11: =SUM(B11:E11) -> 15
A12: Charlotte | B12: =[1]November!B12-[1]October!B12 -> 473 | C12: =[1]November!C12-[1]October!C12 -> 80 | D12: =[1]November!D12-[1]October!D12 -> 152 | E12: =[1]November!E12-[1]October!E12 -> 105 | F12: =SUM(B12:E12) -> 810
A13: Citrus | B13: =[1]November!B13-[1]October!B13 -> 331 | C13: =[1]November!C13-[1]October!C13 -> 29 | D13: =[1]November!D13-[1]October!D13 -> 104 | E13: =[1]November!E13-[1]October!E13 -> 16 | F13: =SUM(B13:E13) -> 480
A14: Clay | B14: =[1]November!B14-[1]October!B14 -> 218 | C14: =[1]November!C14-[1]October!C14 -> 71 | D14: =[1]November!D14-[1]October!D14 -> 69 | E14: =[1]November!E14-[1]October!E14 -> 63 | F14: =SUM(B14:E14) -> 421
A15: Collier | B15: =[1]November!B15-[1]October!B15 -> 119 | C15: =[1]November!C15-[1]October!C15 -> -35 | D15: =[1]November!D15-[1]October!D15 -> 91 | E15: =[1]November!E15-[1]October!E15 -> -15 | F15: =SUM(B15:E15) -> 160
A16: Columbia | B16: =[1]November!B16-[1]October!B16 -> 27 | C16: =[1]November!C16-[1]October!C16 -> 18 | D16: =[1]November!D16-[1]October!D16 -> 19 | E16: =[1]November!E16-[1]October!E16 -> 21 | F16: =SUM(B16:E16) -> 85
... A71: Washington | B71: =[1]November!B71-[1]October!B71 -> 53 | C71: =[1]November!C71-[1]October!C71 -> -3 | D71: =[1]November!D71-[1]October!D71 -> 4 | E71: =[1]November!E71-[1]October!E71 -> 1 | F71: =SUM(B71:E71) -> 55
A72: TOTALS | B72: =SUM(B5:B71) -> 13731 | C72: =SUM(C5:C71) -> 3894 | D72: =SUM(D5:D71) -> 5876 | E72: =SUM(E5:E71) -> 6953 | F72: =SUM(F5:F71) -> 30454

Sheet NetNovToDec
A1: Monthly Report - Net Activity by Party Affiliation - November to December
A2: Data comparison between 11/30/2025 - 12/31/2025
A3: ACTIVE REGISTERED VOTERS BY PARTY AFFILIATION BY COUNTY
A4: County | B4: Republican Party Of Florida | C4: Florida Democratic Party | D4: Minor Party | E4: No Party Affiliation | F4: Totals
A5: Alachua | B5: =[1]December!B5-[1]November!B5 -> -2424 | C5: =[1]December!C5-[1]November!C5 -> -5342 | D5: =[1]December!D5-[1]November!D5 -> -231 | E5: =[1]December!E5-[1]November!E5 -> -4643 | F5: =SUM(B5:E5) -> -12640
A6: Baker | B6: =[1]December!B6-[1]November!B6 -> 39 | C6: =[1]December!C6-[1]November!C6 -> 5 | D6: =[1]December!D6-[1]November!D6 -> 13 | E6: =[1]December!E6-[1]November!E6 -> 19 | F6: =SUM(B6:E6) -> 76
A7: Bay | B7: =[1]December!B7-[1]November!B7 -> 274 | C7: =[1]December!C7-[1]November!C7 -> 29 | D7: =[1]December!D7-[1]November!D7 -> 80 | E7: =[1]December!E7-[1]November!E7 -> 89 | F7: =SUM(B7:E7) -> 472
A8: Bradford | B8: =[1]December!B8-[1]November!B8 -> 35 | C8: =[1]December!C8-[1]November!C8 -> 1 | D8: =[1]December!D8-[1]November!D8 -> 4 | E8: =[1]December!E8-[1]November!E8 -> 6 | F8: =SUM(B8:E8) -> 46
A9: Brevard | B9: =[1]December!B9-[1]November!B9 -> 485 | C9: =[1]December!C9-[1]November!C9 -> 159 | D9: =[1]December!D9-[1]November!D9 -> 202 | E9: =[1]December!E9-[1]November!E9 -> 416 | F9: =SUM(B9:E9) -> 1262
A10: Broward | B10: =[1]December!B10-[1]November!B10 -> -20692 | C10: =[1]December!C10-[1]November!C10 -> -60181 | D10: =[1]December!D10-[1]November!D10 -> -2714 | E10: =[1]December!E10-[1]November!E10 -> -50722 | F10: =SUM(B10:E10) -> -134309
A11: Calhoun | B11: =[1]December!B11-[1]November!B11 -> 9 | C11: =[1]December!C11-[1]November!C11 -> -7 | D11: =[1]December!D11-[1]November!D11 -> 1 | E11: =[1]December!E11-[1]November!E11 -> 5 | F11: =SUM(B11:E11) -> 8
A12: Charlotte | B12: =[1]December!B12-[1]November!B12 -> 471 | C12: =[1]December!C12-[1]November!C12 -> 89 | D12: =[1]December!D12-[1]November!D12 -> 106 | E12: =[1]December!E12-[1]November!E12 -> 131 | F12: =SUM(B12:E12) -> 797
A13: Citrus | B13: =[1]December!B13-[1]November!B13 -> 242 | C13: =[1]December!C13-[1]November!C13 -> -11 | D13: =[1]December!D13-[1]November!D13 -> 95 | E13: =[1]December!E13-[1]November!E13 -> 10 | F13: =SUM(B13:E13) -> 336
A14: Clay | B14: =[1]December!B14-[1]November!B14 -> 191 | C14: =[1]December!C14-[1]November!C14 -> 130 | D14: =[1]December!D14-[1]November!D14 -> 85 | E14: =[1]December!E14-[1]November!E14 -> 89 | F14: =SUM(B14:E14) -> 495
A15: Collier | B15: =[1]December!B15-[1]November!B15 -> 662 | C15: =[1]December!C15-[1]November!C15 -> 148 | D15: =[1]December!D15-[1]November!D15 -> 122 | E15: =[1]December!E15-[1]November!E15 -> 200 | F15: =SUM(B15:E15) -> 1132
A16: Columbia | B16: =[1]December!B16-[1]November!B16 -> 26 | C16: =[1]December!C16-[1]November!C16 -> 4 | D16: =[1]December!D16-[1]November!D16 -> 22 | E16: =[1]December!E16-[1]November!E16 -> 8 | F16: =SUM(B16:E16) -> 60
... A71: Washington | B71: =[1]December!B71-[1]November!B71 -> 52 | C71: =[1]December!C71-[1]November!C71 -> 1 | D71: =[1]December!D71-[1]November!D71 -> 10 | E71: =[1]December!E71-[1]November!E71 -> 17 | F71: =SUM(B71:E71) -> 80
A72: TOTALS | B72: =SUM(B5:B71) -> -13479 | C72: =SUM(C5:C71) -> -64494 | D72: =SUM(D5:D71) -> 2116 | E72: =SUM(E5:E71) -> -52114 | F72: =SUM(F5:F71) -> -127971

Sheet Net-Year-to-Date Total
A1: Monthly Report - Net Activity by Party Affiliation - Year-to-Date Total
A2: Data comparison between 01/31/2025 - 12/31/2025
A3: ACTIVE REGISTERED VOTERS BY PARTY AFFILIATION BY COUNTY
A4: County | B4: Republican Party Of Florida | C4: Florida Democratic Party | D4: Minor Party | E4: No Party Affiliation | F4: Totals
A5: Alachua | B5: =NetJanToFeb!B5+NetFebToMar!B5+NetMarToApr!B5+NetAprToMay!B5+NetMayToJun!B5+NetJunToJul!B5+NetJulToAug!B5+NetAugToSep!B5+NetSepToOct!B5+NetOctToNov!B5+NetNovToDec!B5 -> -1859 | C5: =NetJanToFeb!C5+NetFebToMar!C5+NetMarToApr!C5+NetAprToMay!C5+NetMayToJun!C5+NetJunToJul!C5+NetJulToAug!C5+NetAugToSep!C5+NetSepToOct!C5+NetOctToNov!C5+NetNovToDec!C5 -> -6102 | D5: =NetJanToFeb!D5+NetFebToMar!D5+NetMarToApr!D5+NetAprToMay!D5+NetMayToJun!D5+NetJunToJul!D5+NetJulToAug!D5+NetAugToSep!D5+NetSepToOct!D5+NetOctToNov!D5+NetNovToDec!D5 -> 78 | E5: =NetJanToFeb!E5+NetFebToMar!E5+NetMarToApr!E5+NetAprToMay!E5+NetMayToJun!E5+NetJunToJul!E5+NetJulToAug!E5+NetAugToSep!E5+NetSepToOct!E5+NetOctToNov!E5+NetNovToDec!E5 -> -3939 | F5: =SUM(B5:E5) -> -11822
A6: Baker | B6: =NetJanToFeb!B6+NetFebToMar!B6+NetMarToApr!B6+NetAprToMay!B6+NetMayToJun!B6+NetJunToJul!B6+NetJulToAug!B6+NetAugToSep!B6+NetSepToOct!B6+NetOctToNov!B6+NetNovToDec!B6 -> -627 | C6: =NetJanToFeb!C6+NetFebToMar!C6+NetMarToApr!C6+NetAprToMay!C6+NetMayToJun!C6+NetJunToJul!C6+NetJulToAug!C6+NetAugToSep!C6+NetSepToOct!C6+NetOctToNov!C6+NetNovToDec!C6 -> -757 | D6: =NetJanToFeb!D6+NetFebToMar!D6+NetMarToApr!D6+NetAprToMay!D6+NetMayToJun!D6+NetJunToJul!D6+NetJulToAug!D6+NetAugToSep!D6+NetSepToOct!D6+NetOctToNov!D6+NetNovToDec!D6 -> -11 | E6: =NetJanToFeb!E6+NetFebToMar!E6+NetMarToApr!E6+NetAprToMay!E6+NetMayToJun!E6+NetJunToJul!E6+NetJulToAug!E6+NetAugToSep!E6+NetSepToOct!E6+NetOctToNov!E6+NetNovToDec!E6 -> -554 | F6: =SUM(B6:E6) -> -1949
A7: Bay | B7: =NetJanToFeb!B7+NetFebToMar!B7+NetMarToApr!B7+NetAprToMay!B7+NetMayToJun!B7+NetJunToJul!B7+NetJulToAug!B7+NetAugToSep!B7+NetSepToOct!B7+NetOctToNov!B7+NetNovToDec!B7 -> -2427 | C7: =NetJanToFeb!C7+NetFebToMar!C7+NetMarToApr!C7+NetAprToMay!C7+NetMayToJun!C7+NetJunToJul!C7+NetJulToAug!C7+NetAugToSep!C7+NetSepToOct!C7+NetOctToNov!C7+NetNovToDec!C7 -> -2752 | D7: =NetJanToFeb!D7+NetFebToMar!D7+NetMarToApr!D7+NetAprToMay!D7+NetMayToJun!D7+NetJunToJul!D7+NetJulToAug!D7+NetAugToSep!D7+NetSepToOct!D7+NetOctToNov!D7+NetNovToDec!D7 -> 205 | E7: =NetJanToFeb!E7+NetFebToMar!E7+NetMarToApr!E7+NetAprToMay!E7+NetMayToJun!E7+NetJunToJul!E7+NetJulToAug!E7+NetAugToSep!E7+NetSepToOct!E7+NetOctToNov!E7+NetNovToDec!E7 -> -4100 | F7: =SUM(B7:E7) -> -9074
A8: Bradford | B8: =NetJanToFeb!B8+NetFebToMar!B8+NetMarToApr!B8+NetAprToMay!B8+NetMayToJun!B8+NetJunToJul!B8+NetJulToAug!B8+NetAugToSep!B8+NetSepToOct!B8+NetOctToNov!B8+NetNovToDec!B8 -> -660 | C8: =NetJanToFeb!C8+NetFebToMar!C8+NetMarToApr!C8+NetAprToMay!C8+NetMayToJun!C8+NetJunToJul!C8+NetJulToAug!C8+NetAugToSep!C8+NetSepToOct!C8+NetOctToNov!C8+NetNovToDec!C8 -> -865 | D8: =NetJanToFeb!D8+NetFebToMar!D8+NetMarToApr!D8+NetAprToMay!D8+NetMayToJun!D8+NetJunToJul!D8+NetJulToAug!D8+NetAugToSep!D8+NetSepToOct!D8+NetOctToNov!D8+NetNovToDec!D8 -> 56 | E8: =NetJanToFeb!E8+NetFebToMar!E8+NetMarToApr!E8+NetAprToMay!E8+NetMayToJun!E8+NetJunToJul!E8+NetJulToAug!E8+NetAugToSep!E8+NetSepToOct!E8+NetOctToNov!E8+NetNovToDec!E8 -> -630 | F8: =SUM(B8:E8) -> -2099
